2022-04-26 11:36:01,057    INFO:     Started server process [20258]
2022-04-26 11:36:01,058    INFO:     Waiting for application startup.
2022-04-26 11:36:01,061    INFO:     Application startup complete.
2022-04-26 11:36:01,062    INFO:     Uvicorn running on http://localhost:20222 (Press CTRL+C to quit)
2022-04-26 11:41:42,629    INFO:     Shutting down
To git@github.com:PipelineBot01/TendersPlus.git
   b5ade5f..01b8e99  master -> master
2022-04-26 11:49:50,266    INFO:     Started server process [23997]
2022-04-26 11:49:50,267    INFO:     Waiting for application startup.
2022-04-26 11:49:50,268    INFO:     Application startup complete.
2022-04-26 11:49:50,269    INFO:     Uvicorn running on http://localhost:20222 (Press CTRL+C to quit)
From github.com:PipelineBot01/TendersPlus
   01b8e99..57626eb  master     -> origin/master
To git@github.com:PipelineBot01/TendersPlus.git
   57626eb..c61c50a  master -> master
2022-04-26 11:51:53,907    INFO:     Started server process [24539]
2022-04-26 11:51:53,908    INFO:     Waiting for application startup.
2022-04-26 11:51:53,909    INFO:     Application startup complete.
2022-04-26 11:51:53,910    INFO:     Uvicorn running on http://localhost:20222 (Press CTRL+C to quit)
To git@github.com:PipelineBot01/TendersPlus.git
   90d902e..1a5e235  master -> master
2022-04-26 13:43:37,200    INFO:     Started server process [20063]
2022-04-26 13:43:37,201    INFO:     Waiting for application startup.
2022-04-26 13:43:37,202    INFO:     Application startup complete.
2022-04-26 13:43:37,203    INFO:     Uvicorn running on http://localhost:20222 (Press CTRL+C to quit)
From github.com:PipelineBot01/TendersPlus
   160e363..9f6136c  master     -> origin/master
To git@github.com:PipelineBot01/TendersPlus.git
   9f6136c..c77cdf2  master -> master
2022-04-26 20:02:38,724    INFO:     Started server process [16084]
2022-04-26 20:02:38,725    INFO:     Waiting for application startup.
2022-04-26 20:02:38,727    INFO:     Application startup complete.
2022-04-26 20:02:38,728    INFO:     Uvicorn running on http://localhost:20222 (Press CTRL+C to quit)
2022-04-26 20:57:47,643    INFO:     Shutting down
From github.com:PipelineBot01/TendersPlus
   c77cdf2..7bfcc7f  master     -> origin/master
To git@github.com:PipelineBot01/TendersPlus.git
   7bfcc7f..a236b1d  master -> master
2022-04-26 20:58:20,765    INFO:     Started server process [29791]
2022-04-26 20:58:20,766    INFO:     Waiting for application startup.
2022-04-26 20:58:20,768    INFO:     Application startup complete.
2022-04-26 20:58:20,769    INFO:     Uvicorn running on http://localhost:20222 (Press CTRL+C to quit)
/home/TendersPlus/matcher/tenders/clean/data_clean.py:36: SettingWithCopyWarning: 
A value is trying to be set on a copy of a slice from a DataFrame.
Try using .loc[row_indexer,col_indexer] = value instead

See the caveats in the documentation: https://pandas.pydata.org/pandas-docs/stable/user_guide/indexing.html#returning-a-view-versus-a-copy
  input_df['_id'] = input_df['_id'].astype(str).copy()
/home/TendersPlus/matcher/tenders/clean/data_clean.py:37: SettingWithCopyWarning: 
A value is trying to be set on a copy of a slice from a DataFrame.
Try using .loc[row_indexer,col_indexer] = value instead

See the caveats in the documentation: https://pandas.pydata.org/pandas-docs/stable/user_guide/indexing.html#returning-a-view-versus-a-copy
  input_df['id'] = 'Grants' + input_df['_id']
Run time of job "update_researchers_pool (trigger: interval[1:00:00], next run at: 2022-04-27 05:58:20 CST)" was missed by 0:07:18.444760
From github.com:PipelineBot01/TendersPlus
   a236b1d..3b22f7f  master     -> origin/master
To git@github.com:PipelineBot01/TendersPlus.git
   3b22f7f..d457e50  master -> master
2022-04-27 11:46:17,312    INFO:     Started server process [21409]
2022-04-27 11:46:17,314    INFO:     Waiting for application startup.
2022-04-27 11:46:17,318    INFO:     Application startup complete.
2022-04-27 11:46:17,319    INFO:     Uvicorn running on http://localhost:20222 (Press CTRL+C to quit)
2022-04-27 11:51:22,729    INFO:     Shutting down
From github.com:PipelineBot01/TendersPlus
   d457e50..ce18357  master     -> origin/master
To git@github.com:PipelineBot01/TendersPlus.git
   ce18357..e53fad6  master -> master
2022-04-27 11:51:49,090    INFO:     Started server process [22887]
2022-04-27 11:51:49,091    INFO:     Waiting for application startup.
2022-04-27 11:51:49,093    INFO:     Application startup complete.
2022-04-27 11:51:49,094    INFO:     Uvicorn running on http://localhost:20222 (Press CTRL+C to quit)
2022-04-27 11:52:21,900    ERROR:    Exception in ASGI application
Traceback (most recent call last):
  File "/usr/local/lib/python3.6/site-packages/uvicorn/protocols/http/h11_impl.py", line 373, in run_asgi
    result = await app(self.scope, self.receive, self.send)
  File "/usr/local/lib/python3.6/site-packages/uvicorn/middleware/proxy_headers.py", line 75, in __call__
    return await self.app(scope, receive, send)
  File "/usr/local/lib/python3.6/site-packages/fastapi/applications.py", line 261, in __call__
    await super().__call__(scope, receive, send)
  File "/usr/local/lib/python3.6/site-packages/starlette/applications.py", line 112, in __call__
    await self.middleware_stack(scope, receive, send)
  File "/usr/local/lib/python3.6/site-packages/starlette/middleware/errors.py", line 181, in __call__
    raise exc
  File "/usr/local/lib/python3.6/site-packages/starlette/middleware/errors.py", line 159, in __call__
    await self.app(scope, receive, _send)
  File "/usr/local/lib/python3.6/site-packages/starlette/exceptions.py", line 82, in __call__
    raise exc
  File "/usr/local/lib/python3.6/site-packages/starlette/exceptions.py", line 71, in __call__
    await self.app(scope, receive, sender)
  File "/usr/local/lib/python3.6/site-packages/fastapi/middleware/asyncexitstack.py", line 21, in __call__
    raise e
  File "/usr/local/lib/python3.6/site-packages/fastapi/middleware/asyncexitstack.py", line 18, in __call__
    await self.app(scope, receive, send)
  File "/usr/local/lib/python3.6/site-packages/starlette/routing.py", line 656, in __call__
    await route.handle(scope, receive, send)
  File "/usr/local/lib/python3.6/site-packages/starlette/routing.py", line 259, in handle
    await self.app(scope, receive, send)
  File "/usr/local/lib/python3.6/site-packages/starlette/routing.py", line 61, in app
    response = await func(request)
  File "/usr/local/lib/python3.6/site-packages/fastapi/routing.py", line 228, in app
    dependant=dependant, values=values, is_coroutine=is_coroutine
  File "/usr/local/lib/python3.6/site-packages/fastapi/routing.py", line 160, in run_endpoint_function
    return await dependant.call(**values)
  File "main.py", line 33, in get_reco_tenders
    output = tender_process.run(data.__dict__['id'], tmp_output)
  File "/home/TendersPlus/matcher/auto_reco/postprocess.py", line 97, in run
    if user_id in self.__action_df['r_id'].unique():
  File "/usr/local/lib64/python3.6/site-packages/pandas/core/generic.py", line 5141, in __getattr__
    return object.__getattribute__(self, name)
AttributeError: 'DataFrame' object has no attribute 'unique'
2022-04-27 11:52:24,514    ERROR:    Exception in ASGI application
Traceback (most recent call last):
  File "/usr/local/lib/python3.6/site-packages/uvicorn/protocols/http/h11_impl.py", line 373, in run_asgi
    result = await app(self.scope, self.receive, self.send)
  File "/usr/local/lib/python3.6/site-packages/uvicorn/middleware/proxy_headers.py", line 75, in __call__
    return await self.app(scope, receive, send)
  File "/usr/local/lib/python3.6/site-packages/fastapi/applications.py", line 261, in __call__
    await super().__call__(scope, receive, send)
  File "/usr/local/lib/python3.6/site-packages/starlette/applications.py", line 112, in __call__
    await self.middleware_stack(scope, receive, send)
  File "/usr/local/lib/python3.6/site-packages/starlette/middleware/errors.py", line 181, in __call__
    raise exc
  File "/usr/local/lib/python3.6/site-packages/starlette/middleware/errors.py", line 159, in __call__
    await self.app(scope, receive, _send)
  File "/usr/local/lib/python3.6/site-packages/starlette/exceptions.py", line 82, in __call__
    raise exc
  File "/usr/local/lib/python3.6/site-packages/starlette/exceptions.py", line 71, in __call__
    await self.app(scope, receive, sender)
  File "/usr/local/lib/python3.6/site-packages/fastapi/middleware/asyncexitstack.py", line 21, in __call__
    raise e
  File "/usr/local/lib/python3.6/site-packages/fastapi/middleware/asyncexitstack.py", line 18, in __call__
    await self.app(scope, receive, send)
  File "/usr/local/lib/python3.6/site-packages/starlette/routing.py", line 656, in __call__
    await route.handle(scope, receive, send)
  File "/usr/local/lib/python3.6/site-packages/starlette/routing.py", line 259, in handle
    await self.app(scope, receive, send)
  File "/usr/local/lib/python3.6/site-packages/starlette/routing.py", line 61, in app
    response = await func(request)
  File "/usr/local/lib/python3.6/site-packages/fastapi/routing.py", line 228, in app
    dependant=dependant, values=values, is_coroutine=is_coroutine
  File "/usr/local/lib/python3.6/site-packages/fastapi/routing.py", line 160, in run_endpoint_function
    return await dependant.call(**values)
  File "main.py", line 33, in get_reco_tenders
    output = tender_process.run(data.__dict__['id'], tmp_output)
  File "/home/TendersPlus/matcher/auto_reco/postprocess.py", line 97, in run
    if user_id in self.__action_df['r_id'].unique():
  File "/usr/local/lib64/python3.6/site-packages/pandas/core/generic.py", line 5141, in __getattr__
    return object.__getattribute__(self, name)
AttributeError: 'DataFrame' object has no attribute 'unique'
From github.com:PipelineBot01/TendersPlus
   e53fad6..dd688e3  master     -> origin/master
To git@github.com:PipelineBot01/TendersPlus.git
   dd688e3..15f6f8d  master -> master
2022-04-27 12:02:53,170    INFO:     Started server process [25661]
2022-04-27 12:02:53,171    INFO:     Waiting for application startup.
2022-04-27 12:02:53,172    INFO:     Application startup complete.
2022-04-27 12:02:53,173    INFO:     Uvicorn running on http://localhost:20222 (Press CTRL+C to quit)
2022-04-27 12:02:56,782    INFO:     Shutting down
To git@github.com:PipelineBot01/TendersPlus.git
   15f6f8d..9f737f5  master -> master
2022-04-27 12:03:23,237    INFO:     Started server process [25865]
2022-04-27 12:03:23,237    INFO:     Waiting for application startup.
2022-04-27 12:03:23,238    INFO:     Application startup complete.
2022-04-27 12:03:23,239    INFO:     Uvicorn running on http://localhost:20222 (Press CTRL+C to quit)
2022-04-27 20:34:16,225    INFO:     Shutting down
From github.com:PipelineBot01/TendersPlus
   a721c84..f777dc0  master     -> origin/master
To git@github.com:PipelineBot01/TendersPlus.git
   f777dc0..3e67d59  master -> master
2022-04-27 20:34:52,065    INFO:     Started server process [21817]
2022-04-27 20:34:52,065    INFO:     Waiting for application startup.
2022-04-27 20:35:12,340    INFO:     Application startup complete.
2022-04-27 20:35:12,341    INFO:     Uvicorn running on http://localhost:20222 (Press CTRL+C to quit)
From github.com:PipelineBot01/TendersPlus
   3e67d59..45861d3  master     -> origin/master
To git@github.com:PipelineBot01/TendersPlus.git
   45861d3..aecdaeb  master -> master
2022-04-27 23:05:48,434    INFO:     Started server process [26711]
2022-04-27 23:05:48,434    INFO:     Waiting for application startup.
2022-04-27 23:06:08,947    INFO:     Application startup complete.
2022-04-27 23:06:08,948    INFO:     Uvicorn running on http://localhost:20222 (Press CTRL+C to quit)
/home/TendersPlus/matcher/tenders/clean/data_clean.py:36: SettingWithCopyWarning: 
A value is trying to be set on a copy of a slice from a DataFrame.
Try using .loc[row_indexer,col_indexer] = value instead

See the caveats in the documentation: https://pandas.pydata.org/pandas-docs/stable/user_guide/indexing.html#returning-a-view-versus-a-copy
  input_df['_id'] = input_df['_id'].astype(str).copy()
/home/TendersPlus/matcher/tenders/clean/data_clean.py:37: SettingWithCopyWarning: 
A value is trying to be set on a copy of a slice from a DataFrame.
Try using .loc[row_indexer,col_indexer] = value instead

See the caveats in the documentation: https://pandas.pydata.org/pandas-docs/stable/user_guide/indexing.html#returning-a-view-versus-a-copy
  input_df['id'] = 'Grants' + input_df['_id']
Run time of job "update_researchers_pool (trigger: interval[0:05:00], next run at: 2022-04-28 03:10:48 CST)" was missed by 0:07:14.240412
Run time of job "update_researchers_pool (trigger: interval[0:05:00], next run at: 2022-04-28 03:15:48 CST)" was missed by 0:02:14.241044
Run time of job "update_researchers_pool (trigger: interval[0:05:00], next run at: 2022-04-28 05:10:48 CST)" was missed by 0:03:27.241656
Job "update_researchers_pool (trigger: interval[0:05:00], next run at: 2022-04-28 09:50:48 CST)" raised an exception
Traceback (most recent call last):
  File "/usr/local/lib/python3.6/site-packages/apscheduler/executors/base_py3.py", line 30, in run_coroutine_job
    retval = await job.func(*job.args, **job.kwargs)
  File "/home/TendersPlus/matcher/scheduler/__init__.py", line 25, in update_researchers_pool
    ResearcherUpdater().update()
  File "/home/TendersPlus/matcher/researcher/update/researcher_updater.py", line 40, in __init__
    self.__new_reg_info = get_data()
  File "/home/TendersPlus/matcher/db/loadjson.py", line 11, in get_data
    return pd.DataFrame(json.loads(response.content)['data'])
  File "/usr/lib64/python3.6/json/__init__.py", line 354, in loads
    return _default_decoder.decode(s)
  File "/usr/lib64/python3.6/json/decoder.py", line 339, in decode
    obj, end = self.raw_decode(s, idx=_w(s, 0).end())
  File "/usr/lib64/python3.6/json/decoder.py", line 357, in raw_decode
    raise JSONDecodeError("Expecting value", s, err.value) from None
json.decoder.JSONDecodeError: Expecting value: line 1 column 1 (char 0)
/home/TendersPlus/matcher/deploy.sh: line 18: 26711 Killed                  python3 main.py
To git@github.com:PipelineBot01/TendersPlus.git
   4a94810..7d09af5  master -> master
2022-04-28 09:54:37,646    INFO:     Started server process [24604]
2022-04-28 09:54:37,646    INFO:     Waiting for application startup.
2022-04-28 09:54:58,617    INFO:     Application startup complete.
2022-04-28 09:54:58,618    INFO:     Uvicorn running on http://localhost:20222 (Press CTRL+C to quit)
From github.com:PipelineBot01/TendersPlus
   7d09af5..7ab8631  master     -> origin/master
To git@github.com:PipelineBot01/TendersPlus.git
   7ab8631..a9fe9bc  master -> master
2022-04-28 10:54:31,242    INFO:     Started server process [7002]
2022-04-28 10:54:31,242    INFO:     Waiting for application startup.
2022-04-28 10:54:51,288    INFO:     Application startup complete.
2022-04-28 10:54:51,289    INFO:     Uvicorn running on http://localhost:20222 (Press CTRL+C to quit)
2022-04-28 12:52:20,162    INFO:     Shutting down
From github.com:PipelineBot01/TendersPlus
   a9fe9bc..91fb609  master     -> origin/master
To git@github.com:PipelineBot01/TendersPlus.git
   91fb609..06cd521  master -> master
2022-04-28 12:53:10,703    INFO:     Started server process [3962]
2022-04-28 12:53:10,703    INFO:     Waiting for application startup.
2022-04-28 12:53:13,428    INFO:     Application startup complete.
2022-04-28 12:53:13,429    INFO:     Uvicorn running on http://localhost:20222 (Press CTRL+C to quit)
Killed by signal 15.
From github.com:PipelineBot01/TendersPlus
   06cd521..563ec13  master     -> origin/master
error: Your local changes to the following files would be overwritten by merge:
	matcher/researcher/assets/tag_division_map.csv
Please, commit your changes or stash them before you can merge.
Aborting
To git@github.com:PipelineBot01/TendersPlus.git
 ! [rejected]        master -> master (non-fast-forward)
error: failed to push some refs to 'git@github.com:PipelineBot01/TendersPlus.git'
hint: Updates were rejected because the tip of your current branch is behind
hint: its remote counterpart. Merge the remote changes (e.g. 'git pull')
hint: before pushing again.
hint: See the 'Note about fast-forwards' in 'git push --help' for details.
2022-04-28 14:44:04,775    INFO:     Started server process [31254]
2022-04-28 14:44:04,776    INFO:     Waiting for application startup.
2022-04-28 14:44:07,533    INFO:     Application startup complete.
2022-04-28 14:44:07,534    INFO:     Uvicorn running on http://localhost:20222 (Press CTRL+C to quit)
2022-04-28 14:50:05,173    INFO:     Shutting down
From github.com:PipelineBot01/TendersPlus
   563ec13..677ec87  master     -> origin/master
error: Your local changes to the following files would be overwritten by merge:
	matcher/researcher/assets/tag_division_map.csv
Please, commit your changes or stash them before you can merge.
Aborting
To git@github.com:PipelineBot01/TendersPlus.git
 ! [rejected]        master -> master (non-fast-forward)
error: failed to push some refs to 'git@github.com:PipelineBot01/TendersPlus.git'
hint: Updates were rejected because the tip of your current branch is behind
hint: its remote counterpart. Merge the remote changes (e.g. 'git pull')
hint: before pushing again.
hint: See the 'Note about fast-forwards' in 'git push --help' for details.
2022-04-28 14:50:57,914    INFO:     Started server process [537]
2022-04-28 14:50:57,914    INFO:     Waiting for application startup.
2022-04-28 14:51:00,645    INFO:     Application startup complete.
2022-04-28 14:51:00,646    INFO:     Uvicorn running on http://localhost:20222 (Press CTRL+C to quit)
error: Your local changes to the following files would be overwritten by merge:
	matcher/researcher/assets/tag_division_map.csv
Please, commit your changes or stash them before you can merge.
Aborting
To git@github.com:PipelineBot01/TendersPlus.git
 ! [rejected]        master -> master (non-fast-forward)
error: failed to push some refs to 'git@github.com:PipelineBot01/TendersPlus.git'
hint: Updates were rejected because the tip of your current branch is behind
hint: its remote counterpart. Merge the remote changes (e.g. 'git pull')
hint: before pushing again.
hint: See the 'Note about fast-forwards' in 'git push --help' for details.
2022-04-28 14:55:51,852    INFO:     Started server process [1778]
2022-04-28 14:55:51,853    INFO:     Waiting for application startup.
2022-04-28 14:55:54,583    INFO:     Application startup complete.
2022-04-28 14:55:54,584    INFO:     Uvicorn running on http://localhost:20222 (Press CTRL+C to quit)
error: Your local changes to the following files would be overwritten by merge:
	matcher/researcher/assets/tag_division_map.csv
Please, commit your changes or stash them before you can merge.
Aborting
To git@github.com:PipelineBot01/TendersPlus.git
 ! [rejected]        master -> master (non-fast-forward)
error: failed to push some refs to 'git@github.com:PipelineBot01/TendersPlus.git'
hint: Updates were rejected because the tip of your current branch is behind
hint: its remote counterpart. Merge the remote changes (e.g. 'git pull')
hint: before pushing again.
hint: See the 'Note about fast-forwards' in 'git push --help' for details.
2022-04-28 15:03:04,812    INFO:     Started server process [3726]
2022-04-28 15:03:04,812    INFO:     Waiting for application startup.
2022-04-28 15:03:07,552    INFO:     Application startup complete.
2022-04-28 15:03:07,553    INFO:     Uvicorn running on http://localhost:20222 (Press CTRL+C to quit)
To git@github.com:PipelineBot01/TendersPlus.git
   e218e50..2d6e0f2  master -> master
2022-04-28 16:40:29,328    INFO:     Started server process [27789]
2022-04-28 16:40:29,328    INFO:     Waiting for application startup.
2022-04-28 16:40:32,031    INFO:     Application startup complete.
2022-04-28 16:40:32,032    INFO:     Uvicorn running on http://localhost:20222 (Press CTRL+C to quit)
2022-04-28 17:21:49,264    ERROR:    Exception in ASGI application
Traceback (most recent call last):
  File "/usr/local/lib/python3.6/site-packages/uvicorn/protocols/http/h11_impl.py", line 373, in run_asgi
    result = await app(self.scope, self.receive, self.send)
  File "/usr/local/lib/python3.6/site-packages/uvicorn/middleware/proxy_headers.py", line 75, in __call__
    return await self.app(scope, receive, send)
  File "/usr/local/lib/python3.6/site-packages/fastapi/applications.py", line 261, in __call__
    await super().__call__(scope, receive, send)
  File "/usr/local/lib/python3.6/site-packages/starlette/applications.py", line 112, in __call__
    await self.middleware_stack(scope, receive, send)
  File "/usr/local/lib/python3.6/site-packages/starlette/middleware/errors.py", line 181, in __call__
    raise exc
  File "/usr/local/lib/python3.6/site-packages/starlette/middleware/errors.py", line 159, in __call__
    await self.app(scope, receive, _send)
  File "/usr/local/lib/python3.6/site-packages/starlette/exceptions.py", line 82, in __call__
    raise exc
  File "/usr/local/lib/python3.6/site-packages/starlette/exceptions.py", line 71, in __call__
    await self.app(scope, receive, sender)
  File "/usr/local/lib/python3.6/site-packages/fastapi/middleware/asyncexitstack.py", line 21, in __call__
    raise e
  File "/usr/local/lib/python3.6/site-packages/fastapi/middleware/asyncexitstack.py", line 18, in __call__
    await self.app(scope, receive, send)
  File "/usr/local/lib/python3.6/site-packages/starlette/routing.py", line 656, in __call__
    await route.handle(scope, receive, send)
  File "/usr/local/lib/python3.6/site-packages/starlette/routing.py", line 259, in handle
    await self.app(scope, receive, send)
  File "/usr/local/lib/python3.6/site-packages/starlette/routing.py", line 61, in app
    response = await func(request)
  File "/usr/local/lib/python3.6/site-packages/fastapi/routing.py", line 228, in app
    dependant=dependant, values=values, is_coroutine=is_coroutine
  File "/usr/local/lib/python3.6/site-packages/fastapi/routing.py", line 160, in run_endpoint_function
    return await dependant.call(**values)
  File "main.py", line 24, in get_sim_researchers
    output = researcher_matcher.match_by_profile(data.__dict__)
  File "/home/TendersPlus/matcher/researcher/matching/researcher_relation.py", line 263, in match_by_profile
    candidate_df = candidate_df[candidate_df['id'] != 'Reg_' + id] if remove_cur_id else candidate_df
TypeError: must be str, not NoneType
2022-04-28 17:21:58,531    ERROR:    Exception in ASGI application
Traceback (most recent call last):
  File "/usr/local/lib/python3.6/site-packages/uvicorn/protocols/http/h11_impl.py", line 373, in run_asgi
    result = await app(self.scope, self.receive, self.send)
  File "/usr/local/lib/python3.6/site-packages/uvicorn/middleware/proxy_headers.py", line 75, in __call__
    return await self.app(scope, receive, send)
  File "/usr/local/lib/python3.6/site-packages/fastapi/applications.py", line 261, in __call__
    await super().__call__(scope, receive, send)
  File "/usr/local/lib/python3.6/site-packages/starlette/applications.py", line 112, in __call__
    await self.middleware_stack(scope, receive, send)
  File "/usr/local/lib/python3.6/site-packages/starlette/middleware/errors.py", line 181, in __call__
    raise exc
  File "/usr/local/lib/python3.6/site-packages/starlette/middleware/errors.py", line 159, in __call__
    await self.app(scope, receive, _send)
  File "/usr/local/lib/python3.6/site-packages/starlette/exceptions.py", line 82, in __call__
    raise exc
  File "/usr/local/lib/python3.6/site-packages/starlette/exceptions.py", line 71, in __call__
    await self.app(scope, receive, sender)
  File "/usr/local/lib/python3.6/site-packages/fastapi/middleware/asyncexitstack.py", line 21, in __call__
    raise e
  File "/usr/local/lib/python3.6/site-packages/fastapi/middleware/asyncexitstack.py", line 18, in __call__
    await self.app(scope, receive, send)
  File "/usr/local/lib/python3.6/site-packages/starlette/routing.py", line 656, in __call__
    await route.handle(scope, receive, send)
  File "/usr/local/lib/python3.6/site-packages/starlette/routing.py", line 259, in handle
    await self.app(scope, receive, send)
  File "/usr/local/lib/python3.6/site-packages/starlette/routing.py", line 61, in app
    response = await func(request)
  File "/usr/local/lib/python3.6/site-packages/fastapi/routing.py", line 228, in app
    dependant=dependant, values=values, is_coroutine=is_coroutine
  File "/usr/local/lib/python3.6/site-packages/fastapi/routing.py", line 160, in run_endpoint_function
    return await dependant.call(**values)
  File "main.py", line 24, in get_sim_researchers
    output = researcher_matcher.match_by_profile(data.__dict__)
  File "/home/TendersPlus/matcher/researcher/matching/researcher_relation.py", line 263, in match_by_profile
    candidate_df = candidate_df[candidate_df['id'] != 'Reg_' + id] if remove_cur_id else candidate_df
TypeError: must be str, not NoneType
2022-04-28 17:22:11,392    ERROR:    Exception in ASGI application
Traceback (most recent call last):
  File "/usr/local/lib/python3.6/site-packages/uvicorn/protocols/http/h11_impl.py", line 373, in run_asgi
    result = await app(self.scope, self.receive, self.send)
  File "/usr/local/lib/python3.6/site-packages/uvicorn/middleware/proxy_headers.py", line 75, in __call__
    return await self.app(scope, receive, send)
  File "/usr/local/lib/python3.6/site-packages/fastapi/applications.py", line 261, in __call__
    await super().__call__(scope, receive, send)
  File "/usr/local/lib/python3.6/site-packages/starlette/applications.py", line 112, in __call__
    await self.middleware_stack(scope, receive, send)
  File "/usr/local/lib/python3.6/site-packages/starlette/middleware/errors.py", line 181, in __call__
    raise exc
  File "/usr/local/lib/python3.6/site-packages/starlette/middleware/errors.py", line 159, in __call__
    await self.app(scope, receive, _send)
  File "/usr/local/lib/python3.6/site-packages/starlette/exceptions.py", line 82, in __call__
    raise exc
  File "/usr/local/lib/python3.6/site-packages/starlette/exceptions.py", line 71, in __call__
    await self.app(scope, receive, sender)
  File "/usr/local/lib/python3.6/site-packages/fastapi/middleware/asyncexitstack.py", line 21, in __call__
    raise e
  File "/usr/local/lib/python3.6/site-packages/fastapi/middleware/asyncexitstack.py", line 18, in __call__
    await self.app(scope, receive, send)
  File "/usr/local/lib/python3.6/site-packages/starlette/routing.py", line 656, in __call__
    await route.handle(scope, receive, send)
  File "/usr/local/lib/python3.6/site-packages/starlette/routing.py", line 259, in handle
    await self.app(scope, receive, send)
  File "/usr/local/lib/python3.6/site-packages/starlette/routing.py", line 61, in app
    response = await func(request)
  File "/usr/local/lib/python3.6/site-packages/fastapi/routing.py", line 228, in app
    dependant=dependant, values=values, is_coroutine=is_coroutine
  File "/usr/local/lib/python3.6/site-packages/fastapi/routing.py", line 160, in run_endpoint_function
    return await dependant.call(**values)
  File "main.py", line 24, in get_sim_researchers
    output = researcher_matcher.match_by_profile(data.__dict__)
  File "/home/TendersPlus/matcher/researcher/matching/researcher_relation.py", line 263, in match_by_profile
    candidate_df = candidate_df[candidate_df['id'] != 'Reg_' + id] if remove_cur_id else candidate_df
TypeError: must be str, not NoneType
2022-04-28 17:22:40,876    ERROR:    Exception in ASGI application
Traceback (most recent call last):
  File "/usr/local/lib/python3.6/site-packages/uvicorn/protocols/http/h11_impl.py", line 373, in run_asgi
    result = await app(self.scope, self.receive, self.send)
  File "/usr/local/lib/python3.6/site-packages/uvicorn/middleware/proxy_headers.py", line 75, in __call__
    return await self.app(scope, receive, send)
  File "/usr/local/lib/python3.6/site-packages/fastapi/applications.py", line 261, in __call__
    await super().__call__(scope, receive, send)
  File "/usr/local/lib/python3.6/site-packages/starlette/applications.py", line 112, in __call__
    await self.middleware_stack(scope, receive, send)
  File "/usr/local/lib/python3.6/site-packages/starlette/middleware/errors.py", line 181, in __call__
    raise exc
  File "/usr/local/lib/python3.6/site-packages/starlette/middleware/errors.py", line 159, in __call__
    await self.app(scope, receive, _send)
  File "/usr/local/lib/python3.6/site-packages/starlette/exceptions.py", line 82, in __call__
    raise exc
  File "/usr/local/lib/python3.6/site-packages/starlette/exceptions.py", line 71, in __call__
    await self.app(scope, receive, sender)
  File "/usr/local/lib/python3.6/site-packages/fastapi/middleware/asyncexitstack.py", line 21, in __call__
    raise e
  File "/usr/local/lib/python3.6/site-packages/fastapi/middleware/asyncexitstack.py", line 18, in __call__
    await self.app(scope, receive, send)
  File "/usr/local/lib/python3.6/site-packages/starlette/routing.py", line 656, in __call__
    await route.handle(scope, receive, send)
  File "/usr/local/lib/python3.6/site-packages/starlette/routing.py", line 259, in handle
    await self.app(scope, receive, send)
  File "/usr/local/lib/python3.6/site-packages/starlette/routing.py", line 61, in app
    response = await func(request)
  File "/usr/local/lib/python3.6/site-packages/fastapi/routing.py", line 228, in app
    dependant=dependant, values=values, is_coroutine=is_coroutine
  File "/usr/local/lib/python3.6/site-packages/fastapi/routing.py", line 160, in run_endpoint_function
    return await dependant.call(**values)
  File "main.py", line 24, in get_sim_researchers
    output = researcher_matcher.match_by_profile(data.__dict__)
  File "/home/TendersPlus/matcher/researcher/matching/researcher_relation.py", line 263, in match_by_profile
    candidate_df = candidate_df[candidate_df['id'] != 'Reg_' + id] if remove_cur_id else candidate_df
TypeError: must be str, not NoneType
2022-04-28 17:23:59,415    ERROR:    Exception in ASGI application
Traceback (most recent call last):
  File "/usr/local/lib/python3.6/site-packages/uvicorn/protocols/http/h11_impl.py", line 373, in run_asgi
    result = await app(self.scope, self.receive, self.send)
  File "/usr/local/lib/python3.6/site-packages/uvicorn/middleware/proxy_headers.py", line 75, in __call__
    return await self.app(scope, receive, send)
  File "/usr/local/lib/python3.6/site-packages/fastapi/applications.py", line 261, in __call__
    await super().__call__(scope, receive, send)
  File "/usr/local/lib/python3.6/site-packages/starlette/applications.py", line 112, in __call__
    await self.middleware_stack(scope, receive, send)
  File "/usr/local/lib/python3.6/site-packages/starlette/middleware/errors.py", line 181, in __call__
    raise exc
  File "/usr/local/lib/python3.6/site-packages/starlette/middleware/errors.py", line 159, in __call__
    await self.app(scope, receive, _send)
  File "/usr/local/lib/python3.6/site-packages/starlette/exceptions.py", line 82, in __call__
    raise exc
  File "/usr/local/lib/python3.6/site-packages/starlette/exceptions.py", line 71, in __call__
    await self.app(scope, receive, sender)
  File "/usr/local/lib/python3.6/site-packages/fastapi/middleware/asyncexitstack.py", line 21, in __call__
    raise e
  File "/usr/local/lib/python3.6/site-packages/fastapi/middleware/asyncexitstack.py", line 18, in __call__
    await self.app(scope, receive, send)
  File "/usr/local/lib/python3.6/site-packages/starlette/routing.py", line 656, in __call__
    await route.handle(scope, receive, send)
  File "/usr/local/lib/python3.6/site-packages/starlette/routing.py", line 259, in handle
    await self.app(scope, receive, send)
  File "/usr/local/lib/python3.6/site-packages/starlette/routing.py", line 61, in app
    response = await func(request)
  File "/usr/local/lib/python3.6/site-packages/fastapi/routing.py", line 228, in app
    dependant=dependant, values=values, is_coroutine=is_coroutine
  File "/usr/local/lib/python3.6/site-packages/fastapi/routing.py", line 160, in run_endpoint_function
    return await dependant.call(**values)
  File "main.py", line 24, in get_sim_researchers
    output = researcher_matcher.match_by_profile(data.__dict__)
  File "/home/TendersPlus/matcher/researcher/matching/researcher_relation.py", line 263, in match_by_profile
    candidate_df = candidate_df[candidate_df['id'] != 'Reg_' + id] if remove_cur_id else candidate_df
TypeError: must be str, not NoneType
Job "update_researchers_pool (trigger: interval[0:10:00], next run at: 2022-04-28 21:40:29 CST)" raised an exception
Traceback (most recent call last):
  File "/usr/local/lib/python3.6/site-packages/apscheduler/executors/base_py3.py", line 30, in run_coroutine_job
    retval = await job.func(*job.args, **job.kwargs)
  File "/home/TendersPlus/matcher/scheduler/__init__.py", line 25, in update_researchers_pool
    ru.update()
  File "/home/TendersPlus/matcher/researcher/update/researcher_updater.py", line 80, in update
    self.__new_reg_info = get_data()
  File "/home/TendersPlus/matcher/db/loadjson.py", line 11, in get_data
    return pd.DataFrame(json.loads(response.content)['data'])
  File "/usr/lib64/python3.6/json/__init__.py", line 354, in loads
    return _default_decoder.decode(s)
  File "/usr/lib64/python3.6/json/decoder.py", line 339, in decode
    obj, end = self.raw_decode(s, idx=_w(s, 0).end())
  File "/usr/lib64/python3.6/json/decoder.py", line 357, in raw_decode
    raise JSONDecodeError("Expecting value", s, err.value) from None
json.decoder.JSONDecodeError: Expecting value: line 1 column 1 (char 0)
Job "update_researchers_pool (trigger: interval[0:10:00], next run at: 2022-04-28 21:50:29 CST)" raised an exception
Traceback (most recent call last):
  File "/usr/local/lib64/python3.6/site-packages/pandas/core/indexes/base.py", line 2898, in get_loc
    return self._engine.get_loc(casted_key)
  File "pandas/_libs/index.pyx", line 70, in pandas._libs.index.IndexEngine.get_loc
  File "pandas/_libs/index.pyx", line 101, in pandas._libs.index.IndexEngine.get_loc
  File "pandas/_libs/hashtable_class_helper.pxi", line 1675, in pandas._libs.hashtable.PyObjectHashTable.get_item
  File "pandas/_libs/hashtable_class_helper.pxi", line 1683, in pandas._libs.hashtable.PyObjectHashTable.get_item
KeyError: 'email'

The above exception was the direct cause of the following exception:

Traceback (most recent call last):
  File "/usr/local/lib/python3.6/site-packages/apscheduler/executors/base_py3.py", line 30, in run_coroutine_job
    retval = await job.func(*job.args, **job.kwargs)
  File "/home/TendersPlus/matcher/scheduler/__init__.py", line 25, in update_researchers_pool
    ru.update()
  File "/home/TendersPlus/matcher/researcher/update/researcher_updater.py", line 81, in update
    self.__new_tag_df, self.__new_div_df, self.__new_tag_div_map_df = get_user_profile(self.__new_reg_info)
  File "/home/TendersPlus/matcher/utils/feature_utils.py", line 53, in get_user_profile
    input_df[pk] = 'Reg_' + input_df['email']
  File "/usr/local/lib64/python3.6/site-packages/pandas/core/frame.py", line 2906, in __getitem__
    indexer = self.columns.get_loc(key)
  File "/usr/local/lib64/python3.6/site-packages/pandas/core/indexes/base.py", line 2900, in get_loc
    raise KeyError(key) from err
KeyError: 'email'
Job "update_researchers_pool (trigger: interval[0:10:00], next run at: 2022-04-28 22:00:29 CST)" raised an exception
Traceback (most recent call last):
  File "/usr/local/lib64/python3.6/site-packages/pandas/core/indexes/base.py", line 2898, in get_loc
    return self._engine.get_loc(casted_key)
  File "pandas/_libs/index.pyx", line 70, in pandas._libs.index.IndexEngine.get_loc
  File "pandas/_libs/index.pyx", line 101, in pandas._libs.index.IndexEngine.get_loc
  File "pandas/_libs/hashtable_class_helper.pxi", line 1675, in pandas._libs.hashtable.PyObjectHashTable.get_item
  File "pandas/_libs/hashtable_class_helper.pxi", line 1683, in pandas._libs.hashtable.PyObjectHashTable.get_item
KeyError: 'email'

The above exception was the direct cause of the following exception:

Traceback (most recent call last):
  File "/usr/local/lib/python3.6/site-packages/apscheduler/executors/base_py3.py", line 30, in run_coroutine_job
    retval = await job.func(*job.args, **job.kwargs)
  File "/home/TendersPlus/matcher/scheduler/__init__.py", line 25, in update_researchers_pool
    ru.update()
  File "/home/TendersPlus/matcher/researcher/update/researcher_updater.py", line 81, in update
    self.__new_tag_df, self.__new_div_df, self.__new_tag_div_map_df = get_user_profile(self.__new_reg_info)
  File "/home/TendersPlus/matcher/utils/feature_utils.py", line 53, in get_user_profile
    input_df[pk] = 'Reg_' + input_df['email']
  File "/usr/local/lib64/python3.6/site-packages/pandas/core/frame.py", line 2906, in __getitem__
    indexer = self.columns.get_loc(key)
  File "/usr/local/lib64/python3.6/site-packages/pandas/core/indexes/base.py", line 2900, in get_loc
    raise KeyError(key) from err
KeyError: 'email'
Job "update_researchers_pool (trigger: interval[0:10:00], next run at: 2022-04-28 22:10:29 CST)" raised an exception
Traceback (most recent call last):
  File "/usr/local/lib64/python3.6/site-packages/pandas/core/indexes/base.py", line 2898, in get_loc
    return self._engine.get_loc(casted_key)
  File "pandas/_libs/index.pyx", line 70, in pandas._libs.index.IndexEngine.get_loc
  File "pandas/_libs/index.pyx", line 101, in pandas._libs.index.IndexEngine.get_loc
  File "pandas/_libs/hashtable_class_helper.pxi", line 1675, in pandas._libs.hashtable.PyObjectHashTable.get_item
  File "pandas/_libs/hashtable_class_helper.pxi", line 1683, in pandas._libs.hashtable.PyObjectHashTable.get_item
KeyError: 'email'

The above exception was the direct cause of the following exception:

Traceback (most recent call last):
  File "/usr/local/lib/python3.6/site-packages/apscheduler/executors/base_py3.py", line 30, in run_coroutine_job
    retval = await job.func(*job.args, **job.kwargs)
  File "/home/TendersPlus/matcher/scheduler/__init__.py", line 25, in update_researchers_pool
    ru.update()
  File "/home/TendersPlus/matcher/researcher/update/researcher_updater.py", line 81, in update
    self.__new_tag_df, self.__new_div_df, self.__new_tag_div_map_df = get_user_profile(self.__new_reg_info)
  File "/home/TendersPlus/matcher/utils/feature_utils.py", line 53, in get_user_profile
    input_df[pk] = 'Reg_' + input_df['email']
  File "/usr/local/lib64/python3.6/site-packages/pandas/core/frame.py", line 2906, in __getitem__
    indexer = self.columns.get_loc(key)
  File "/usr/local/lib64/python3.6/site-packages/pandas/core/indexes/base.py", line 2900, in get_loc
    raise KeyError(key) from err
KeyError: 'email'
Job "update_researchers_pool (trigger: interval[0:10:00], next run at: 2022-04-28 22:20:29 CST)" raised an exception
Traceback (most recent call last):
  File "/usr/local/lib64/python3.6/site-packages/pandas/core/indexes/base.py", line 2898, in get_loc
    return self._engine.get_loc(casted_key)
  File "pandas/_libs/index.pyx", line 70, in pandas._libs.index.IndexEngine.get_loc
  File "pandas/_libs/index.pyx", line 101, in pandas._libs.index.IndexEngine.get_loc
  File "pandas/_libs/hashtable_class_helper.pxi", line 1675, in pandas._libs.hashtable.PyObjectHashTable.get_item
  File "pandas/_libs/hashtable_class_helper.pxi", line 1683, in pandas._libs.hashtable.PyObjectHashTable.get_item
KeyError: 'email'

The above exception was the direct cause of the following exception:

Traceback (most recent call last):
  File "/usr/local/lib/python3.6/site-packages/apscheduler/executors/base_py3.py", line 30, in run_coroutine_job
    retval = await job.func(*job.args, **job.kwargs)
  File "/home/TendersPlus/matcher/scheduler/__init__.py", line 25, in update_researchers_pool
    ru.update()
  File "/home/TendersPlus/matcher/researcher/update/researcher_updater.py", line 81, in update
    self.__new_tag_df, self.__new_div_df, self.__new_tag_div_map_df = get_user_profile(self.__new_reg_info)
  File "/home/TendersPlus/matcher/utils/feature_utils.py", line 53, in get_user_profile
    input_df[pk] = 'Reg_' + input_df['email']
  File "/usr/local/lib64/python3.6/site-packages/pandas/core/frame.py", line 2906, in __getitem__
    indexer = self.columns.get_loc(key)
  File "/usr/local/lib64/python3.6/site-packages/pandas/core/indexes/base.py", line 2900, in get_loc
    raise KeyError(key) from err
KeyError: 'email'
Job "update_researchers_pool (trigger: interval[0:10:00], next run at: 2022-04-28 22:30:29 CST)" raised an exception
Traceback (most recent call last):
  File "/usr/local/lib64/python3.6/site-packages/pandas/core/indexes/base.py", line 2898, in get_loc
    return self._engine.get_loc(casted_key)
  File "pandas/_libs/index.pyx", line 70, in pandas._libs.index.IndexEngine.get_loc
  File "pandas/_libs/index.pyx", line 101, in pandas._libs.index.IndexEngine.get_loc
  File "pandas/_libs/hashtable_class_helper.pxi", line 1675, in pandas._libs.hashtable.PyObjectHashTable.get_item
  File "pandas/_libs/hashtable_class_helper.pxi", line 1683, in pandas._libs.hashtable.PyObjectHashTable.get_item
KeyError: 'email'

The above exception was the direct cause of the following exception:

Traceback (most recent call last):
  File "/usr/local/lib/python3.6/site-packages/apscheduler/executors/base_py3.py", line 30, in run_coroutine_job
    retval = await job.func(*job.args, **job.kwargs)
  File "/home/TendersPlus/matcher/scheduler/__init__.py", line 25, in update_researchers_pool
    ru.update()
  File "/home/TendersPlus/matcher/researcher/update/researcher_updater.py", line 81, in update
    self.__new_tag_df, self.__new_div_df, self.__new_tag_div_map_df = get_user_profile(self.__new_reg_info)
  File "/home/TendersPlus/matcher/utils/feature_utils.py", line 53, in get_user_profile
    input_df[pk] = 'Reg_' + input_df['email']
  File "/usr/local/lib64/python3.6/site-packages/pandas/core/frame.py", line 2906, in __getitem__
    indexer = self.columns.get_loc(key)
  File "/usr/local/lib64/python3.6/site-packages/pandas/core/indexes/base.py", line 2900, in get_loc
    raise KeyError(key) from err
KeyError: 'email'
Job "update_researchers_pool (trigger: interval[0:10:00], next run at: 2022-04-28 22:40:29 CST)" raised an exception
Traceback (most recent call last):
  File "/usr/local/lib64/python3.6/site-packages/pandas/core/indexes/base.py", line 2898, in get_loc
    return self._engine.get_loc(casted_key)
  File "pandas/_libs/index.pyx", line 70, in pandas._libs.index.IndexEngine.get_loc
  File "pandas/_libs/index.pyx", line 101, in pandas._libs.index.IndexEngine.get_loc
  File "pandas/_libs/hashtable_class_helper.pxi", line 1675, in pandas._libs.hashtable.PyObjectHashTable.get_item
  File "pandas/_libs/hashtable_class_helper.pxi", line 1683, in pandas._libs.hashtable.PyObjectHashTable.get_item
KeyError: 'email'

The above exception was the direct cause of the following exception:

Traceback (most recent call last):
  File "/usr/local/lib/python3.6/site-packages/apscheduler/executors/base_py3.py", line 30, in run_coroutine_job
    retval = await job.func(*job.args, **job.kwargs)
  File "/home/TendersPlus/matcher/scheduler/__init__.py", line 25, in update_researchers_pool
    ru.update()
  File "/home/TendersPlus/matcher/researcher/update/researcher_updater.py", line 81, in update
    self.__new_tag_df, self.__new_div_df, self.__new_tag_div_map_df = get_user_profile(self.__new_reg_info)
  File "/home/TendersPlus/matcher/utils/feature_utils.py", line 53, in get_user_profile
    input_df[pk] = 'Reg_' + input_df['email']
  File "/usr/local/lib64/python3.6/site-packages/pandas/core/frame.py", line 2906, in __getitem__
    indexer = self.columns.get_loc(key)
  File "/usr/local/lib64/python3.6/site-packages/pandas/core/indexes/base.py", line 2900, in get_loc
    raise KeyError(key) from err
KeyError: 'email'
Job "update_researchers_pool (trigger: interval[0:10:00], next run at: 2022-04-28 22:50:29 CST)" raised an exception
Traceback (most recent call last):
  File "/usr/local/lib64/python3.6/site-packages/pandas/core/indexes/base.py", line 2898, in get_loc
    return self._engine.get_loc(casted_key)
  File "pandas/_libs/index.pyx", line 70, in pandas._libs.index.IndexEngine.get_loc
  File "pandas/_libs/index.pyx", line 101, in pandas._libs.index.IndexEngine.get_loc
  File "pandas/_libs/hashtable_class_helper.pxi", line 1675, in pandas._libs.hashtable.PyObjectHashTable.get_item
  File "pandas/_libs/hashtable_class_helper.pxi", line 1683, in pandas._libs.hashtable.PyObjectHashTable.get_item
KeyError: 'email'

The above exception was the direct cause of the following exception:

Traceback (most recent call last):
  File "/usr/local/lib/python3.6/site-packages/apscheduler/executors/base_py3.py", line 30, in run_coroutine_job
    retval = await job.func(*job.args, **job.kwargs)
  File "/home/TendersPlus/matcher/scheduler/__init__.py", line 25, in update_researchers_pool
    ru.update()
  File "/home/TendersPlus/matcher/researcher/update/researcher_updater.py", line 81, in update
    self.__new_tag_df, self.__new_div_df, self.__new_tag_div_map_df = get_user_profile(self.__new_reg_info)
  File "/home/TendersPlus/matcher/utils/feature_utils.py", line 53, in get_user_profile
    input_df[pk] = 'Reg_' + input_df['email']
  File "/usr/local/lib64/python3.6/site-packages/pandas/core/frame.py", line 2906, in __getitem__
    indexer = self.columns.get_loc(key)
  File "/usr/local/lib64/python3.6/site-packages/pandas/core/indexes/base.py", line 2900, in get_loc
    raise KeyError(key) from err
KeyError: 'email'
Job "update_researchers_pool (trigger: interval[0:10:00], next run at: 2022-04-28 23:00:29 CST)" raised an exception
Traceback (most recent call last):
  File "/usr/local/lib64/python3.6/site-packages/pandas/core/indexes/base.py", line 2898, in get_loc
    return self._engine.get_loc(casted_key)
  File "pandas/_libs/index.pyx", line 70, in pandas._libs.index.IndexEngine.get_loc
  File "pandas/_libs/index.pyx", line 101, in pandas._libs.index.IndexEngine.get_loc
  File "pandas/_libs/hashtable_class_helper.pxi", line 1675, in pandas._libs.hashtable.PyObjectHashTable.get_item
  File "pandas/_libs/hashtable_class_helper.pxi", line 1683, in pandas._libs.hashtable.PyObjectHashTable.get_item
KeyError: 'email'

The above exception was the direct cause of the following exception:

Traceback (most recent call last):
  File "/usr/local/lib/python3.6/site-packages/apscheduler/executors/base_py3.py", line 30, in run_coroutine_job
    retval = await job.func(*job.args, **job.kwargs)
  File "/home/TendersPlus/matcher/scheduler/__init__.py", line 25, in update_researchers_pool
    ru.update()
  File "/home/TendersPlus/matcher/researcher/update/researcher_updater.py", line 81, in update
    self.__new_tag_df, self.__new_div_df, self.__new_tag_div_map_df = get_user_profile(self.__new_reg_info)
  File "/home/TendersPlus/matcher/utils/feature_utils.py", line 53, in get_user_profile
    input_df[pk] = 'Reg_' + input_df['email']
  File "/usr/local/lib64/python3.6/site-packages/pandas/core/frame.py", line 2906, in __getitem__
    indexer = self.columns.get_loc(key)
  File "/usr/local/lib64/python3.6/site-packages/pandas/core/indexes/base.py", line 2900, in get_loc
    raise KeyError(key) from err
KeyError: 'email'
Job "update_researchers_pool (trigger: interval[0:10:00], next run at: 2022-04-28 23:10:29 CST)" raised an exception
Traceback (most recent call last):
  File "/usr/local/lib64/python3.6/site-packages/pandas/core/indexes/base.py", line 2898, in get_loc
    return self._engine.get_loc(casted_key)
  File "pandas/_libs/index.pyx", line 70, in pandas._libs.index.IndexEngine.get_loc
  File "pandas/_libs/index.pyx", line 101, in pandas._libs.index.IndexEngine.get_loc
  File "pandas/_libs/hashtable_class_helper.pxi", line 1675, in pandas._libs.hashtable.PyObjectHashTable.get_item
  File "pandas/_libs/hashtable_class_helper.pxi", line 1683, in pandas._libs.hashtable.PyObjectHashTable.get_item
KeyError: 'email'

The above exception was the direct cause of the following exception:

Traceback (most recent call last):
  File "/usr/local/lib/python3.6/site-packages/apscheduler/executors/base_py3.py", line 30, in run_coroutine_job
    retval = await job.func(*job.args, **job.kwargs)
  File "/home/TendersPlus/matcher/scheduler/__init__.py", line 25, in update_researchers_pool
    ru.update()
  File "/home/TendersPlus/matcher/researcher/update/researcher_updater.py", line 81, in update
    self.__new_tag_df, self.__new_div_df, self.__new_tag_div_map_df = get_user_profile(self.__new_reg_info)
  File "/home/TendersPlus/matcher/utils/feature_utils.py", line 53, in get_user_profile
    input_df[pk] = 'Reg_' + input_df['email']
  File "/usr/local/lib64/python3.6/site-packages/pandas/core/frame.py", line 2906, in __getitem__
    indexer = self.columns.get_loc(key)
  File "/usr/local/lib64/python3.6/site-packages/pandas/core/indexes/base.py", line 2900, in get_loc
    raise KeyError(key) from err
KeyError: 'email'
Job "update_researchers_pool (trigger: interval[0:10:00], next run at: 2022-04-28 23:20:29 CST)" raised an exception
Traceback (most recent call last):
  File "/usr/local/lib64/python3.6/site-packages/pandas/core/indexes/base.py", line 2898, in get_loc
    return self._engine.get_loc(casted_key)
  File "pandas/_libs/index.pyx", line 70, in pandas._libs.index.IndexEngine.get_loc
  File "pandas/_libs/index.pyx", line 101, in pandas._libs.index.IndexEngine.get_loc
  File "pandas/_libs/hashtable_class_helper.pxi", line 1675, in pandas._libs.hashtable.PyObjectHashTable.get_item
  File "pandas/_libs/hashtable_class_helper.pxi", line 1683, in pandas._libs.hashtable.PyObjectHashTable.get_item
KeyError: 'email'

The above exception was the direct cause of the following exception:

Traceback (most recent call last):
  File "/usr/local/lib/python3.6/site-packages/apscheduler/executors/base_py3.py", line 30, in run_coroutine_job
    retval = await job.func(*job.args, **job.kwargs)
  File "/home/TendersPlus/matcher/scheduler/__init__.py", line 25, in update_researchers_pool
    ru.update()
  File "/home/TendersPlus/matcher/researcher/update/researcher_updater.py", line 81, in update
    self.__new_tag_df, self.__new_div_df, self.__new_tag_div_map_df = get_user_profile(self.__new_reg_info)
  File "/home/TendersPlus/matcher/utils/feature_utils.py", line 53, in get_user_profile
    input_df[pk] = 'Reg_' + input_df['email']
  File "/usr/local/lib64/python3.6/site-packages/pandas/core/frame.py", line 2906, in __getitem__
    indexer = self.columns.get_loc(key)
  File "/usr/local/lib64/python3.6/site-packages/pandas/core/indexes/base.py", line 2900, in get_loc
    raise KeyError(key) from err
KeyError: 'email'
Job "update_researchers_pool (trigger: interval[0:10:00], next run at: 2022-04-28 23:30:29 CST)" raised an exception
Traceback (most recent call last):
  File "/usr/local/lib64/python3.6/site-packages/pandas/core/indexes/base.py", line 2898, in get_loc
    return self._engine.get_loc(casted_key)
  File "pandas/_libs/index.pyx", line 70, in pandas._libs.index.IndexEngine.get_loc
  File "pandas/_libs/index.pyx", line 101, in pandas._libs.index.IndexEngine.get_loc
  File "pandas/_libs/hashtable_class_helper.pxi", line 1675, in pandas._libs.hashtable.PyObjectHashTable.get_item
  File "pandas/_libs/hashtable_class_helper.pxi", line 1683, in pandas._libs.hashtable.PyObjectHashTable.get_item
KeyError: 'email'

The above exception was the direct cause of the following exception:

Traceback (most recent call last):
  File "/usr/local/lib/python3.6/site-packages/apscheduler/executors/base_py3.py", line 30, in run_coroutine_job
    retval = await job.func(*job.args, **job.kwargs)
  File "/home/TendersPlus/matcher/scheduler/__init__.py", line 25, in update_researchers_pool
    ru.update()
  File "/home/TendersPlus/matcher/researcher/update/researcher_updater.py", line 81, in update
    self.__new_tag_df, self.__new_div_df, self.__new_tag_div_map_df = get_user_profile(self.__new_reg_info)
  File "/home/TendersPlus/matcher/utils/feature_utils.py", line 53, in get_user_profile
    input_df[pk] = 'Reg_' + input_df['email']
  File "/usr/local/lib64/python3.6/site-packages/pandas/core/frame.py", line 2906, in __getitem__
    indexer = self.columns.get_loc(key)
  File "/usr/local/lib64/python3.6/site-packages/pandas/core/indexes/base.py", line 2900, in get_loc
    raise KeyError(key) from err
KeyError: 'email'
Job "update_researchers_pool (trigger: interval[0:10:00], next run at: 2022-04-28 23:40:29 CST)" raised an exception
Traceback (most recent call last):
  File "/usr/local/lib64/python3.6/site-packages/pandas/core/indexes/base.py", line 2898, in get_loc
    return self._engine.get_loc(casted_key)
  File "pandas/_libs/index.pyx", line 70, in pandas._libs.index.IndexEngine.get_loc
  File "pandas/_libs/index.pyx", line 101, in pandas._libs.index.IndexEngine.get_loc
  File "pandas/_libs/hashtable_class_helper.pxi", line 1675, in pandas._libs.hashtable.PyObjectHashTable.get_item
  File "pandas/_libs/hashtable_class_helper.pxi", line 1683, in pandas._libs.hashtable.PyObjectHashTable.get_item
KeyError: 'email'

The above exception was the direct cause of the following exception:

Traceback (most recent call last):
  File "/usr/local/lib/python3.6/site-packages/apscheduler/executors/base_py3.py", line 30, in run_coroutine_job
    retval = await job.func(*job.args, **job.kwargs)
  File "/home/TendersPlus/matcher/scheduler/__init__.py", line 25, in update_researchers_pool
    ru.update()
  File "/home/TendersPlus/matcher/researcher/update/researcher_updater.py", line 81, in update
    self.__new_tag_df, self.__new_div_df, self.__new_tag_div_map_df = get_user_profile(self.__new_reg_info)
  File "/home/TendersPlus/matcher/utils/feature_utils.py", line 53, in get_user_profile
    input_df[pk] = 'Reg_' + input_df['email']
  File "/usr/local/lib64/python3.6/site-packages/pandas/core/frame.py", line 2906, in __getitem__
    indexer = self.columns.get_loc(key)
  File "/usr/local/lib64/python3.6/site-packages/pandas/core/indexes/base.py", line 2900, in get_loc
    raise KeyError(key) from err
KeyError: 'email'
Job "update_researchers_pool (trigger: interval[0:10:00], next run at: 2022-04-28 23:50:29 CST)" raised an exception
Traceback (most recent call last):
  File "/usr/local/lib64/python3.6/site-packages/pandas/core/indexes/base.py", line 2898, in get_loc
    return self._engine.get_loc(casted_key)
  File "pandas/_libs/index.pyx", line 70, in pandas._libs.index.IndexEngine.get_loc
  File "pandas/_libs/index.pyx", line 101, in pandas._libs.index.IndexEngine.get_loc
  File "pandas/_libs/hashtable_class_helper.pxi", line 1675, in pandas._libs.hashtable.PyObjectHashTable.get_item
  File "pandas/_libs/hashtable_class_helper.pxi", line 1683, in pandas._libs.hashtable.PyObjectHashTable.get_item
KeyError: 'email'

The above exception was the direct cause of the following exception:

Traceback (most recent call last):
  File "/usr/local/lib/python3.6/site-packages/apscheduler/executors/base_py3.py", line 30, in run_coroutine_job
    retval = await job.func(*job.args, **job.kwargs)
  File "/home/TendersPlus/matcher/scheduler/__init__.py", line 25, in update_researchers_pool
    ru.update()
  File "/home/TendersPlus/matcher/researcher/update/researcher_updater.py", line 81, in update
    self.__new_tag_df, self.__new_div_df, self.__new_tag_div_map_df = get_user_profile(self.__new_reg_info)
  File "/home/TendersPlus/matcher/utils/feature_utils.py", line 53, in get_user_profile
    input_df[pk] = 'Reg_' + input_df['email']
  File "/usr/local/lib64/python3.6/site-packages/pandas/core/frame.py", line 2906, in __getitem__
    indexer = self.columns.get_loc(key)
  File "/usr/local/lib64/python3.6/site-packages/pandas/core/indexes/base.py", line 2900, in get_loc
    raise KeyError(key) from err
KeyError: 'email'
Job "update_researchers_pool (trigger: interval[0:10:00], next run at: 2022-04-29 00:00:29 CST)" raised an exception
Traceback (most recent call last):
  File "/usr/local/lib64/python3.6/site-packages/pandas/core/indexes/base.py", line 2898, in get_loc
    return self._engine.get_loc(casted_key)
  File "pandas/_libs/index.pyx", line 70, in pandas._libs.index.IndexEngine.get_loc
  File "pandas/_libs/index.pyx", line 101, in pandas._libs.index.IndexEngine.get_loc
  File "pandas/_libs/hashtable_class_helper.pxi", line 1675, in pandas._libs.hashtable.PyObjectHashTable.get_item
  File "pandas/_libs/hashtable_class_helper.pxi", line 1683, in pandas._libs.hashtable.PyObjectHashTable.get_item
KeyError: 'email'

The above exception was the direct cause of the following exception:

Traceback (most recent call last):
  File "/usr/local/lib/python3.6/site-packages/apscheduler/executors/base_py3.py", line 30, in run_coroutine_job
    retval = await job.func(*job.args, **job.kwargs)
  File "/home/TendersPlus/matcher/scheduler/__init__.py", line 25, in update_researchers_pool
    ru.update()
  File "/home/TendersPlus/matcher/researcher/update/researcher_updater.py", line 81, in update
    self.__new_tag_df, self.__new_div_df, self.__new_tag_div_map_df = get_user_profile(self.__new_reg_info)
  File "/home/TendersPlus/matcher/utils/feature_utils.py", line 53, in get_user_profile
    input_df[pk] = 'Reg_' + input_df['email']
  File "/usr/local/lib64/python3.6/site-packages/pandas/core/frame.py", line 2906, in __getitem__
    indexer = self.columns.get_loc(key)
  File "/usr/local/lib64/python3.6/site-packages/pandas/core/indexes/base.py", line 2900, in get_loc
    raise KeyError(key) from err
KeyError: 'email'
Job "update_researchers_pool (trigger: interval[0:10:00], next run at: 2022-04-29 00:10:29 CST)" raised an exception
Traceback (most recent call last):
  File "/usr/local/lib64/python3.6/site-packages/pandas/core/indexes/base.py", line 2898, in get_loc
    return self._engine.get_loc(casted_key)
  File "pandas/_libs/index.pyx", line 70, in pandas._libs.index.IndexEngine.get_loc
  File "pandas/_libs/index.pyx", line 101, in pandas._libs.index.IndexEngine.get_loc
  File "pandas/_libs/hashtable_class_helper.pxi", line 1675, in pandas._libs.hashtable.PyObjectHashTable.get_item
  File "pandas/_libs/hashtable_class_helper.pxi", line 1683, in pandas._libs.hashtable.PyObjectHashTable.get_item
KeyError: 'email'

The above exception was the direct cause of the following exception:

Traceback (most recent call last):
  File "/usr/local/lib/python3.6/site-packages/apscheduler/executors/base_py3.py", line 30, in run_coroutine_job
    retval = await job.func(*job.args, **job.kwargs)
  File "/home/TendersPlus/matcher/scheduler/__init__.py", line 25, in update_researchers_pool
    ru.update()
  File "/home/TendersPlus/matcher/researcher/update/researcher_updater.py", line 81, in update
    self.__new_tag_df, self.__new_div_df, self.__new_tag_div_map_df = get_user_profile(self.__new_reg_info)
  File "/home/TendersPlus/matcher/utils/feature_utils.py", line 53, in get_user_profile
    input_df[pk] = 'Reg_' + input_df['email']
  File "/usr/local/lib64/python3.6/site-packages/pandas/core/frame.py", line 2906, in __getitem__
    indexer = self.columns.get_loc(key)
  File "/usr/local/lib64/python3.6/site-packages/pandas/core/indexes/base.py", line 2900, in get_loc
    raise KeyError(key) from err
KeyError: 'email'
Job "update_researchers_pool (trigger: interval[0:10:00], next run at: 2022-04-29 00:20:29 CST)" raised an exception
Traceback (most recent call last):
  File "/usr/local/lib64/python3.6/site-packages/pandas/core/indexes/base.py", line 2898, in get_loc
    return self._engine.get_loc(casted_key)
  File "pandas/_libs/index.pyx", line 70, in pandas._libs.index.IndexEngine.get_loc
  File "pandas/_libs/index.pyx", line 101, in pandas._libs.index.IndexEngine.get_loc
  File "pandas/_libs/hashtable_class_helper.pxi", line 1675, in pandas._libs.hashtable.PyObjectHashTable.get_item
  File "pandas/_libs/hashtable_class_helper.pxi", line 1683, in pandas._libs.hashtable.PyObjectHashTable.get_item
KeyError: 'email'

The above exception was the direct cause of the following exception:

Traceback (most recent call last):
  File "/usr/local/lib/python3.6/site-packages/apscheduler/executors/base_py3.py", line 30, in run_coroutine_job
    retval = await job.func(*job.args, **job.kwargs)
  File "/home/TendersPlus/matcher/scheduler/__init__.py", line 25, in update_researchers_pool
    ru.update()
  File "/home/TendersPlus/matcher/researcher/update/researcher_updater.py", line 81, in update
    self.__new_tag_df, self.__new_div_df, self.__new_tag_div_map_df = get_user_profile(self.__new_reg_info)
  File "/home/TendersPlus/matcher/utils/feature_utils.py", line 53, in get_user_profile
    input_df[pk] = 'Reg_' + input_df['email']
  File "/usr/local/lib64/python3.6/site-packages/pandas/core/frame.py", line 2906, in __getitem__
    indexer = self.columns.get_loc(key)
  File "/usr/local/lib64/python3.6/site-packages/pandas/core/indexes/base.py", line 2900, in get_loc
    raise KeyError(key) from err
KeyError: 'email'
Job "update_researchers_pool (trigger: interval[0:10:00], next run at: 2022-04-29 00:30:29 CST)" raised an exception
Traceback (most recent call last):
  File "/usr/local/lib64/python3.6/site-packages/pandas/core/indexes/base.py", line 2898, in get_loc
    return self._engine.get_loc(casted_key)
  File "pandas/_libs/index.pyx", line 70, in pandas._libs.index.IndexEngine.get_loc
  File "pandas/_libs/index.pyx", line 101, in pandas._libs.index.IndexEngine.get_loc
  File "pandas/_libs/hashtable_class_helper.pxi", line 1675, in pandas._libs.hashtable.PyObjectHashTable.get_item
  File "pandas/_libs/hashtable_class_helper.pxi", line 1683, in pandas._libs.hashtable.PyObjectHashTable.get_item
KeyError: 'email'

The above exception was the direct cause of the following exception:

Traceback (most recent call last):
  File "/usr/local/lib/python3.6/site-packages/apscheduler/executors/base_py3.py", line 30, in run_coroutine_job
    retval = await job.func(*job.args, **job.kwargs)
  File "/home/TendersPlus/matcher/scheduler/__init__.py", line 25, in update_researchers_pool
    ru.update()
  File "/home/TendersPlus/matcher/researcher/update/researcher_updater.py", line 81, in update
    self.__new_tag_df, self.__new_div_df, self.__new_tag_div_map_df = get_user_profile(self.__new_reg_info)
  File "/home/TendersPlus/matcher/utils/feature_utils.py", line 53, in get_user_profile
    input_df[pk] = 'Reg_' + input_df['email']
  File "/usr/local/lib64/python3.6/site-packages/pandas/core/frame.py", line 2906, in __getitem__
    indexer = self.columns.get_loc(key)
  File "/usr/local/lib64/python3.6/site-packages/pandas/core/indexes/base.py", line 2900, in get_loc
    raise KeyError(key) from err
KeyError: 'email'
Job "update_researchers_pool (trigger: interval[0:10:00], next run at: 2022-04-29 00:40:29 CST)" raised an exception
Traceback (most recent call last):
  File "/usr/local/lib64/python3.6/site-packages/pandas/core/indexes/base.py", line 2898, in get_loc
    return self._engine.get_loc(casted_key)
  File "pandas/_libs/index.pyx", line 70, in pandas._libs.index.IndexEngine.get_loc
  File "pandas/_libs/index.pyx", line 101, in pandas._libs.index.IndexEngine.get_loc
  File "pandas/_libs/hashtable_class_helper.pxi", line 1675, in pandas._libs.hashtable.PyObjectHashTable.get_item
  File "pandas/_libs/hashtable_class_helper.pxi", line 1683, in pandas._libs.hashtable.PyObjectHashTable.get_item
KeyError: 'email'

The above exception was the direct cause of the following exception:

Traceback (most recent call last):
  File "/usr/local/lib/python3.6/site-packages/apscheduler/executors/base_py3.py", line 30, in run_coroutine_job
    retval = await job.func(*job.args, **job.kwargs)
  File "/home/TendersPlus/matcher/scheduler/__init__.py", line 25, in update_researchers_pool
    ru.update()
  File "/home/TendersPlus/matcher/researcher/update/researcher_updater.py", line 81, in update
    self.__new_tag_df, self.__new_div_df, self.__new_tag_div_map_df = get_user_profile(self.__new_reg_info)
  File "/home/TendersPlus/matcher/utils/feature_utils.py", line 53, in get_user_profile
    input_df[pk] = 'Reg_' + input_df['email']
  File "/usr/local/lib64/python3.6/site-packages/pandas/core/frame.py", line 2906, in __getitem__
    indexer = self.columns.get_loc(key)
  File "/usr/local/lib64/python3.6/site-packages/pandas/core/indexes/base.py", line 2900, in get_loc
    raise KeyError(key) from err
KeyError: 'email'
Job "update_researchers_pool (trigger: interval[0:10:00], next run at: 2022-04-29 00:50:29 CST)" raised an exception
Traceback (most recent call last):
  File "/usr/local/lib64/python3.6/site-packages/pandas/core/indexes/base.py", line 2898, in get_loc
    return self._engine.get_loc(casted_key)
  File "pandas/_libs/index.pyx", line 70, in pandas._libs.index.IndexEngine.get_loc
  File "pandas/_libs/index.pyx", line 101, in pandas._libs.index.IndexEngine.get_loc
  File "pandas/_libs/hashtable_class_helper.pxi", line 1675, in pandas._libs.hashtable.PyObjectHashTable.get_item
  File "pandas/_libs/hashtable_class_helper.pxi", line 1683, in pandas._libs.hashtable.PyObjectHashTable.get_item
KeyError: 'email'

The above exception was the direct cause of the following exception:

Traceback (most recent call last):
  File "/usr/local/lib/python3.6/site-packages/apscheduler/executors/base_py3.py", line 30, in run_coroutine_job
    retval = await job.func(*job.args, **job.kwargs)
  File "/home/TendersPlus/matcher/scheduler/__init__.py", line 25, in update_researchers_pool
    ru.update()
  File "/home/TendersPlus/matcher/researcher/update/researcher_updater.py", line 81, in update
    self.__new_tag_df, self.__new_div_df, self.__new_tag_div_map_df = get_user_profile(self.__new_reg_info)
  File "/home/TendersPlus/matcher/utils/feature_utils.py", line 53, in get_user_profile
    input_df[pk] = 'Reg_' + input_df['email']
  File "/usr/local/lib64/python3.6/site-packages/pandas/core/frame.py", line 2906, in __getitem__
    indexer = self.columns.get_loc(key)
  File "/usr/local/lib64/python3.6/site-packages/pandas/core/indexes/base.py", line 2900, in get_loc
    raise KeyError(key) from err
KeyError: 'email'
Job "update_researchers_pool (trigger: interval[0:10:00], next run at: 2022-04-29 01:00:29 CST)" raised an exception
Traceback (most recent call last):
  File "/usr/local/lib64/python3.6/site-packages/pandas/core/indexes/base.py", line 2898, in get_loc
    return self._engine.get_loc(casted_key)
  File "pandas/_libs/index.pyx", line 70, in pandas._libs.index.IndexEngine.get_loc
  File "pandas/_libs/index.pyx", line 101, in pandas._libs.index.IndexEngine.get_loc
  File "pandas/_libs/hashtable_class_helper.pxi", line 1675, in pandas._libs.hashtable.PyObjectHashTable.get_item
  File "pandas/_libs/hashtable_class_helper.pxi", line 1683, in pandas._libs.hashtable.PyObjectHashTable.get_item
KeyError: 'email'

The above exception was the direct cause of the following exception:

Traceback (most recent call last):
  File "/usr/local/lib/python3.6/site-packages/apscheduler/executors/base_py3.py", line 30, in run_coroutine_job
    retval = await job.func(*job.args, **job.kwargs)
  File "/home/TendersPlus/matcher/scheduler/__init__.py", line 25, in update_researchers_pool
    ru.update()
  File "/home/TendersPlus/matcher/researcher/update/researcher_updater.py", line 81, in update
    self.__new_tag_df, self.__new_div_df, self.__new_tag_div_map_df = get_user_profile(self.__new_reg_info)
  File "/home/TendersPlus/matcher/utils/feature_utils.py", line 53, in get_user_profile
    input_df[pk] = 'Reg_' + input_df['email']
  File "/usr/local/lib64/python3.6/site-packages/pandas/core/frame.py", line 2906, in __getitem__
    indexer = self.columns.get_loc(key)
  File "/usr/local/lib64/python3.6/site-packages/pandas/core/indexes/base.py", line 2900, in get_loc
    raise KeyError(key) from err
KeyError: 'email'
Job "update_researchers_pool (trigger: interval[0:10:00], next run at: 2022-04-29 01:10:29 CST)" raised an exception
Traceback (most recent call last):
  File "/usr/local/lib64/python3.6/site-packages/pandas/core/indexes/base.py", line 2898, in get_loc
    return self._engine.get_loc(casted_key)
  File "pandas/_libs/index.pyx", line 70, in pandas._libs.index.IndexEngine.get_loc
  File "pandas/_libs/index.pyx", line 101, in pandas._libs.index.IndexEngine.get_loc
  File "pandas/_libs/hashtable_class_helper.pxi", line 1675, in pandas._libs.hashtable.PyObjectHashTable.get_item
  File "pandas/_libs/hashtable_class_helper.pxi", line 1683, in pandas._libs.hashtable.PyObjectHashTable.get_item
KeyError: 'email'

The above exception was the direct cause of the following exception:

Traceback (most recent call last):
  File "/usr/local/lib/python3.6/site-packages/apscheduler/executors/base_py3.py", line 30, in run_coroutine_job
    retval = await job.func(*job.args, **job.kwargs)
  File "/home/TendersPlus/matcher/scheduler/__init__.py", line 25, in update_researchers_pool
    ru.update()
  File "/home/TendersPlus/matcher/researcher/update/researcher_updater.py", line 81, in update
    self.__new_tag_df, self.__new_div_df, self.__new_tag_div_map_df = get_user_profile(self.__new_reg_info)
  File "/home/TendersPlus/matcher/utils/feature_utils.py", line 53, in get_user_profile
    input_df[pk] = 'Reg_' + input_df['email']
  File "/usr/local/lib64/python3.6/site-packages/pandas/core/frame.py", line 2906, in __getitem__
    indexer = self.columns.get_loc(key)
  File "/usr/local/lib64/python3.6/site-packages/pandas/core/indexes/base.py", line 2900, in get_loc
    raise KeyError(key) from err
KeyError: 'email'
Job "update_researchers_pool (trigger: interval[0:10:00], next run at: 2022-04-29 01:20:29 CST)" raised an exception
Traceback (most recent call last):
  File "/usr/local/lib64/python3.6/site-packages/pandas/core/indexes/base.py", line 2898, in get_loc
    return self._engine.get_loc(casted_key)
  File "pandas/_libs/index.pyx", line 70, in pandas._libs.index.IndexEngine.get_loc
  File "pandas/_libs/index.pyx", line 101, in pandas._libs.index.IndexEngine.get_loc
  File "pandas/_libs/hashtable_class_helper.pxi", line 1675, in pandas._libs.hashtable.PyObjectHashTable.get_item
  File "pandas/_libs/hashtable_class_helper.pxi", line 1683, in pandas._libs.hashtable.PyObjectHashTable.get_item
KeyError: 'email'

The above exception was the direct cause of the following exception:

Traceback (most recent call last):
  File "/usr/local/lib/python3.6/site-packages/apscheduler/executors/base_py3.py", line 30, in run_coroutine_job
    retval = await job.func(*job.args, **job.kwargs)
  File "/home/TendersPlus/matcher/scheduler/__init__.py", line 25, in update_researchers_pool
    ru.update()
  File "/home/TendersPlus/matcher/researcher/update/researcher_updater.py", line 81, in update
    self.__new_tag_df, self.__new_div_df, self.__new_tag_div_map_df = get_user_profile(self.__new_reg_info)
  File "/home/TendersPlus/matcher/utils/feature_utils.py", line 53, in get_user_profile
    input_df[pk] = 'Reg_' + input_df['email']
  File "/usr/local/lib64/python3.6/site-packages/pandas/core/frame.py", line 2906, in __getitem__
    indexer = self.columns.get_loc(key)
  File "/usr/local/lib64/python3.6/site-packages/pandas/core/indexes/base.py", line 2900, in get_loc
    raise KeyError(key) from err
KeyError: 'email'
Job "update_researchers_pool (trigger: interval[0:10:00], next run at: 2022-04-29 01:30:29 CST)" raised an exception
Traceback (most recent call last):
  File "/usr/local/lib64/python3.6/site-packages/pandas/core/indexes/base.py", line 2898, in get_loc
    return self._engine.get_loc(casted_key)
  File "pandas/_libs/index.pyx", line 70, in pandas._libs.index.IndexEngine.get_loc
  File "pandas/_libs/index.pyx", line 101, in pandas._libs.index.IndexEngine.get_loc
  File "pandas/_libs/hashtable_class_helper.pxi", line 1675, in pandas._libs.hashtable.PyObjectHashTable.get_item
  File "pandas/_libs/hashtable_class_helper.pxi", line 1683, in pandas._libs.hashtable.PyObjectHashTable.get_item
KeyError: 'email'

The above exception was the direct cause of the following exception:

Traceback (most recent call last):
  File "/usr/local/lib/python3.6/site-packages/apscheduler/executors/base_py3.py", line 30, in run_coroutine_job
    retval = await job.func(*job.args, **job.kwargs)
  File "/home/TendersPlus/matcher/scheduler/__init__.py", line 25, in update_researchers_pool
    ru.update()
  File "/home/TendersPlus/matcher/researcher/update/researcher_updater.py", line 81, in update
    self.__new_tag_df, self.__new_div_df, self.__new_tag_div_map_df = get_user_profile(self.__new_reg_info)
  File "/home/TendersPlus/matcher/utils/feature_utils.py", line 53, in get_user_profile
    input_df[pk] = 'Reg_' + input_df['email']
  File "/usr/local/lib64/python3.6/site-packages/pandas/core/frame.py", line 2906, in __getitem__
    indexer = self.columns.get_loc(key)
  File "/usr/local/lib64/python3.6/site-packages/pandas/core/indexes/base.py", line 2900, in get_loc
    raise KeyError(key) from err
KeyError: 'email'
Job "update_researchers_pool (trigger: interval[0:10:00], next run at: 2022-04-29 01:40:29 CST)" raised an exception
Traceback (most recent call last):
  File "/usr/local/lib64/python3.6/site-packages/pandas/core/indexes/base.py", line 2898, in get_loc
    return self._engine.get_loc(casted_key)
  File "pandas/_libs/index.pyx", line 70, in pandas._libs.index.IndexEngine.get_loc
  File "pandas/_libs/index.pyx", line 101, in pandas._libs.index.IndexEngine.get_loc
  File "pandas/_libs/hashtable_class_helper.pxi", line 1675, in pandas._libs.hashtable.PyObjectHashTable.get_item
  File "pandas/_libs/hashtable_class_helper.pxi", line 1683, in pandas._libs.hashtable.PyObjectHashTable.get_item
KeyError: 'email'

The above exception was the direct cause of the following exception:

Traceback (most recent call last):
  File "/usr/local/lib/python3.6/site-packages/apscheduler/executors/base_py3.py", line 30, in run_coroutine_job
    retval = await job.func(*job.args, **job.kwargs)
  File "/home/TendersPlus/matcher/scheduler/__init__.py", line 25, in update_researchers_pool
    ru.update()
  File "/home/TendersPlus/matcher/researcher/update/researcher_updater.py", line 81, in update
    self.__new_tag_df, self.__new_div_df, self.__new_tag_div_map_df = get_user_profile(self.__new_reg_info)
  File "/home/TendersPlus/matcher/utils/feature_utils.py", line 53, in get_user_profile
    input_df[pk] = 'Reg_' + input_df['email']
  File "/usr/local/lib64/python3.6/site-packages/pandas/core/frame.py", line 2906, in __getitem__
    indexer = self.columns.get_loc(key)
  File "/usr/local/lib64/python3.6/site-packages/pandas/core/indexes/base.py", line 2900, in get_loc
    raise KeyError(key) from err
KeyError: 'email'
Job "update_researchers_pool (trigger: interval[0:10:00], next run at: 2022-04-29 01:50:29 CST)" raised an exception
Traceback (most recent call last):
  File "/usr/local/lib64/python3.6/site-packages/pandas/core/indexes/base.py", line 2898, in get_loc
    return self._engine.get_loc(casted_key)
  File "pandas/_libs/index.pyx", line 70, in pandas._libs.index.IndexEngine.get_loc
  File "pandas/_libs/index.pyx", line 101, in pandas._libs.index.IndexEngine.get_loc
  File "pandas/_libs/hashtable_class_helper.pxi", line 1675, in pandas._libs.hashtable.PyObjectHashTable.get_item
  File "pandas/_libs/hashtable_class_helper.pxi", line 1683, in pandas._libs.hashtable.PyObjectHashTable.get_item
KeyError: 'email'

The above exception was the direct cause of the following exception:

Traceback (most recent call last):
  File "/usr/local/lib/python3.6/site-packages/apscheduler/executors/base_py3.py", line 30, in run_coroutine_job
    retval = await job.func(*job.args, **job.kwargs)
  File "/home/TendersPlus/matcher/scheduler/__init__.py", line 25, in update_researchers_pool
    ru.update()
  File "/home/TendersPlus/matcher/researcher/update/researcher_updater.py", line 81, in update
    self.__new_tag_df, self.__new_div_df, self.__new_tag_div_map_df = get_user_profile(self.__new_reg_info)
  File "/home/TendersPlus/matcher/utils/feature_utils.py", line 53, in get_user_profile
    input_df[pk] = 'Reg_' + input_df['email']
  File "/usr/local/lib64/python3.6/site-packages/pandas/core/frame.py", line 2906, in __getitem__
    indexer = self.columns.get_loc(key)
  File "/usr/local/lib64/python3.6/site-packages/pandas/core/indexes/base.py", line 2900, in get_loc
    raise KeyError(key) from err
KeyError: 'email'
Job "update_researchers_pool (trigger: interval[0:10:00], next run at: 2022-04-29 02:00:29 CST)" raised an exception
Traceback (most recent call last):
  File "/usr/local/lib64/python3.6/site-packages/pandas/core/indexes/base.py", line 2898, in get_loc
    return self._engine.get_loc(casted_key)
  File "pandas/_libs/index.pyx", line 70, in pandas._libs.index.IndexEngine.get_loc
  File "pandas/_libs/index.pyx", line 101, in pandas._libs.index.IndexEngine.get_loc
  File "pandas/_libs/hashtable_class_helper.pxi", line 1675, in pandas._libs.hashtable.PyObjectHashTable.get_item
  File "pandas/_libs/hashtable_class_helper.pxi", line 1683, in pandas._libs.hashtable.PyObjectHashTable.get_item
KeyError: 'email'

The above exception was the direct cause of the following exception:

Traceback (most recent call last):
  File "/usr/local/lib/python3.6/site-packages/apscheduler/executors/base_py3.py", line 30, in run_coroutine_job
    retval = await job.func(*job.args, **job.kwargs)
  File "/home/TendersPlus/matcher/scheduler/__init__.py", line 25, in update_researchers_pool
    ru.update()
  File "/home/TendersPlus/matcher/researcher/update/researcher_updater.py", line 81, in update
    self.__new_tag_df, self.__new_div_df, self.__new_tag_div_map_df = get_user_profile(self.__new_reg_info)
  File "/home/TendersPlus/matcher/utils/feature_utils.py", line 53, in get_user_profile
    input_df[pk] = 'Reg_' + input_df['email']
  File "/usr/local/lib64/python3.6/site-packages/pandas/core/frame.py", line 2906, in __getitem__
    indexer = self.columns.get_loc(key)
  File "/usr/local/lib64/python3.6/site-packages/pandas/core/indexes/base.py", line 2900, in get_loc
    raise KeyError(key) from err
KeyError: 'email'
Job "update_researchers_pool (trigger: interval[0:10:00], next run at: 2022-04-29 02:10:29 CST)" raised an exception
Traceback (most recent call last):
  File "/usr/local/lib64/python3.6/site-packages/pandas/core/indexes/base.py", line 2898, in get_loc
    return self._engine.get_loc(casted_key)
  File "pandas/_libs/index.pyx", line 70, in pandas._libs.index.IndexEngine.get_loc
  File "pandas/_libs/index.pyx", line 101, in pandas._libs.index.IndexEngine.get_loc
  File "pandas/_libs/hashtable_class_helper.pxi", line 1675, in pandas._libs.hashtable.PyObjectHashTable.get_item
  File "pandas/_libs/hashtable_class_helper.pxi", line 1683, in pandas._libs.hashtable.PyObjectHashTable.get_item
KeyError: 'email'

The above exception was the direct cause of the following exception:

Traceback (most recent call last):
  File "/usr/local/lib/python3.6/site-packages/apscheduler/executors/base_py3.py", line 30, in run_coroutine_job
    retval = await job.func(*job.args, **job.kwargs)
  File "/home/TendersPlus/matcher/scheduler/__init__.py", line 25, in update_researchers_pool
    ru.update()
  File "/home/TendersPlus/matcher/researcher/update/researcher_updater.py", line 81, in update
    self.__new_tag_df, self.__new_div_df, self.__new_tag_div_map_df = get_user_profile(self.__new_reg_info)
  File "/home/TendersPlus/matcher/utils/feature_utils.py", line 53, in get_user_profile
    input_df[pk] = 'Reg_' + input_df['email']
  File "/usr/local/lib64/python3.6/site-packages/pandas/core/frame.py", line 2906, in __getitem__
    indexer = self.columns.get_loc(key)
  File "/usr/local/lib64/python3.6/site-packages/pandas/core/indexes/base.py", line 2900, in get_loc
    raise KeyError(key) from err
KeyError: 'email'
Job "update_researchers_pool (trigger: interval[0:10:00], next run at: 2022-04-29 02:20:29 CST)" raised an exception
Traceback (most recent call last):
  File "/usr/local/lib64/python3.6/site-packages/pandas/core/indexes/base.py", line 2898, in get_loc
    return self._engine.get_loc(casted_key)
  File "pandas/_libs/index.pyx", line 70, in pandas._libs.index.IndexEngine.get_loc
  File "pandas/_libs/index.pyx", line 101, in pandas._libs.index.IndexEngine.get_loc
  File "pandas/_libs/hashtable_class_helper.pxi", line 1675, in pandas._libs.hashtable.PyObjectHashTable.get_item
  File "pandas/_libs/hashtable_class_helper.pxi", line 1683, in pandas._libs.hashtable.PyObjectHashTable.get_item
KeyError: 'email'

The above exception was the direct cause of the following exception:

Traceback (most recent call last):
  File "/usr/local/lib/python3.6/site-packages/apscheduler/executors/base_py3.py", line 30, in run_coroutine_job
    retval = await job.func(*job.args, **job.kwargs)
  File "/home/TendersPlus/matcher/scheduler/__init__.py", line 25, in update_researchers_pool
    ru.update()
  File "/home/TendersPlus/matcher/researcher/update/researcher_updater.py", line 81, in update
    self.__new_tag_df, self.__new_div_df, self.__new_tag_div_map_df = get_user_profile(self.__new_reg_info)
  File "/home/TendersPlus/matcher/utils/feature_utils.py", line 53, in get_user_profile
    input_df[pk] = 'Reg_' + input_df['email']
  File "/usr/local/lib64/python3.6/site-packages/pandas/core/frame.py", line 2906, in __getitem__
    indexer = self.columns.get_loc(key)
  File "/usr/local/lib64/python3.6/site-packages/pandas/core/indexes/base.py", line 2900, in get_loc
    raise KeyError(key) from err
KeyError: 'email'
Job "update_researchers_pool (trigger: interval[0:10:00], next run at: 2022-04-29 02:30:29 CST)" raised an exception
Traceback (most recent call last):
  File "/usr/local/lib64/python3.6/site-packages/pandas/core/indexes/base.py", line 2898, in get_loc
    return self._engine.get_loc(casted_key)
  File "pandas/_libs/index.pyx", line 70, in pandas._libs.index.IndexEngine.get_loc
  File "pandas/_libs/index.pyx", line 101, in pandas._libs.index.IndexEngine.get_loc
  File "pandas/_libs/hashtable_class_helper.pxi", line 1675, in pandas._libs.hashtable.PyObjectHashTable.get_item
  File "pandas/_libs/hashtable_class_helper.pxi", line 1683, in pandas._libs.hashtable.PyObjectHashTable.get_item
KeyError: 'email'

The above exception was the direct cause of the following exception:

Traceback (most recent call last):
  File "/usr/local/lib/python3.6/site-packages/apscheduler/executors/base_py3.py", line 30, in run_coroutine_job
    retval = await job.func(*job.args, **job.kwargs)
  File "/home/TendersPlus/matcher/scheduler/__init__.py", line 25, in update_researchers_pool
    ru.update()
  File "/home/TendersPlus/matcher/researcher/update/researcher_updater.py", line 81, in update
    self.__new_tag_df, self.__new_div_df, self.__new_tag_div_map_df = get_user_profile(self.__new_reg_info)
  File "/home/TendersPlus/matcher/utils/feature_utils.py", line 53, in get_user_profile
    input_df[pk] = 'Reg_' + input_df['email']
  File "/usr/local/lib64/python3.6/site-packages/pandas/core/frame.py", line 2906, in __getitem__
    indexer = self.columns.get_loc(key)
  File "/usr/local/lib64/python3.6/site-packages/pandas/core/indexes/base.py", line 2900, in get_loc
    raise KeyError(key) from err
KeyError: 'email'
Job "update_researchers_pool (trigger: interval[0:10:00], next run at: 2022-04-29 02:40:29 CST)" raised an exception
Traceback (most recent call last):
  File "/usr/local/lib64/python3.6/site-packages/pandas/core/indexes/base.py", line 2898, in get_loc
    return self._engine.get_loc(casted_key)
  File "pandas/_libs/index.pyx", line 70, in pandas._libs.index.IndexEngine.get_loc
  File "pandas/_libs/index.pyx", line 101, in pandas._libs.index.IndexEngine.get_loc
  File "pandas/_libs/hashtable_class_helper.pxi", line 1675, in pandas._libs.hashtable.PyObjectHashTable.get_item
  File "pandas/_libs/hashtable_class_helper.pxi", line 1683, in pandas._libs.hashtable.PyObjectHashTable.get_item
KeyError: 'email'

The above exception was the direct cause of the following exception:

Traceback (most recent call last):
  File "/usr/local/lib/python3.6/site-packages/apscheduler/executors/base_py3.py", line 30, in run_coroutine_job
    retval = await job.func(*job.args, **job.kwargs)
  File "/home/TendersPlus/matcher/scheduler/__init__.py", line 25, in update_researchers_pool
    ru.update()
  File "/home/TendersPlus/matcher/researcher/update/researcher_updater.py", line 81, in update
    self.__new_tag_df, self.__new_div_df, self.__new_tag_div_map_df = get_user_profile(self.__new_reg_info)
  File "/home/TendersPlus/matcher/utils/feature_utils.py", line 53, in get_user_profile
    input_df[pk] = 'Reg_' + input_df['email']
  File "/usr/local/lib64/python3.6/site-packages/pandas/core/frame.py", line 2906, in __getitem__
    indexer = self.columns.get_loc(key)
  File "/usr/local/lib64/python3.6/site-packages/pandas/core/indexes/base.py", line 2900, in get_loc
    raise KeyError(key) from err
KeyError: 'email'
Job "update_researchers_pool (trigger: interval[0:10:00], next run at: 2022-04-29 02:50:29 CST)" raised an exception
Traceback (most recent call last):
  File "/usr/local/lib64/python3.6/site-packages/pandas/core/indexes/base.py", line 2898, in get_loc
    return self._engine.get_loc(casted_key)
  File "pandas/_libs/index.pyx", line 70, in pandas._libs.index.IndexEngine.get_loc
  File "pandas/_libs/index.pyx", line 101, in pandas._libs.index.IndexEngine.get_loc
  File "pandas/_libs/hashtable_class_helper.pxi", line 1675, in pandas._libs.hashtable.PyObjectHashTable.get_item
  File "pandas/_libs/hashtable_class_helper.pxi", line 1683, in pandas._libs.hashtable.PyObjectHashTable.get_item
KeyError: 'email'

The above exception was the direct cause of the following exception:

Traceback (most recent call last):
  File "/usr/local/lib/python3.6/site-packages/apscheduler/executors/base_py3.py", line 30, in run_coroutine_job
    retval = await job.func(*job.args, **job.kwargs)
  File "/home/TendersPlus/matcher/scheduler/__init__.py", line 25, in update_researchers_pool
    ru.update()
  File "/home/TendersPlus/matcher/researcher/update/researcher_updater.py", line 81, in update
    self.__new_tag_df, self.__new_div_df, self.__new_tag_div_map_df = get_user_profile(self.__new_reg_info)
  File "/home/TendersPlus/matcher/utils/feature_utils.py", line 53, in get_user_profile
    input_df[pk] = 'Reg_' + input_df['email']
  File "/usr/local/lib64/python3.6/site-packages/pandas/core/frame.py", line 2906, in __getitem__
    indexer = self.columns.get_loc(key)
  File "/usr/local/lib64/python3.6/site-packages/pandas/core/indexes/base.py", line 2900, in get_loc
    raise KeyError(key) from err
KeyError: 'email'
Job "update_researchers_pool (trigger: interval[0:10:00], next run at: 2022-04-29 03:00:29 CST)" raised an exception
Traceback (most recent call last):
  File "/usr/local/lib64/python3.6/site-packages/pandas/core/indexes/base.py", line 2898, in get_loc
    return self._engine.get_loc(casted_key)
  File "pandas/_libs/index.pyx", line 70, in pandas._libs.index.IndexEngine.get_loc
  File "pandas/_libs/index.pyx", line 101, in pandas._libs.index.IndexEngine.get_loc
  File "pandas/_libs/hashtable_class_helper.pxi", line 1675, in pandas._libs.hashtable.PyObjectHashTable.get_item
  File "pandas/_libs/hashtable_class_helper.pxi", line 1683, in pandas._libs.hashtable.PyObjectHashTable.get_item
KeyError: 'email'

The above exception was the direct cause of the following exception:

Traceback (most recent call last):
  File "/usr/local/lib/python3.6/site-packages/apscheduler/executors/base_py3.py", line 30, in run_coroutine_job
    retval = await job.func(*job.args, **job.kwargs)
  File "/home/TendersPlus/matcher/scheduler/__init__.py", line 25, in update_researchers_pool
    ru.update()
  File "/home/TendersPlus/matcher/researcher/update/researcher_updater.py", line 81, in update
    self.__new_tag_df, self.__new_div_df, self.__new_tag_div_map_df = get_user_profile(self.__new_reg_info)
  File "/home/TendersPlus/matcher/utils/feature_utils.py", line 53, in get_user_profile
    input_df[pk] = 'Reg_' + input_df['email']
  File "/usr/local/lib64/python3.6/site-packages/pandas/core/frame.py", line 2906, in __getitem__
    indexer = self.columns.get_loc(key)
  File "/usr/local/lib64/python3.6/site-packages/pandas/core/indexes/base.py", line 2900, in get_loc
    raise KeyError(key) from err
KeyError: 'email'
Job "update_researchers_pool (trigger: interval[0:10:00], next run at: 2022-04-29 03:10:29 CST)" raised an exception
Traceback (most recent call last):
  File "/usr/local/lib64/python3.6/site-packages/pandas/core/indexes/base.py", line 2898, in get_loc
    return self._engine.get_loc(casted_key)
  File "pandas/_libs/index.pyx", line 70, in pandas._libs.index.IndexEngine.get_loc
  File "pandas/_libs/index.pyx", line 101, in pandas._libs.index.IndexEngine.get_loc
  File "pandas/_libs/hashtable_class_helper.pxi", line 1675, in pandas._libs.hashtable.PyObjectHashTable.get_item
  File "pandas/_libs/hashtable_class_helper.pxi", line 1683, in pandas._libs.hashtable.PyObjectHashTable.get_item
KeyError: 'email'

The above exception was the direct cause of the following exception:

Traceback (most recent call last):
  File "/usr/local/lib/python3.6/site-packages/apscheduler/executors/base_py3.py", line 30, in run_coroutine_job
    retval = await job.func(*job.args, **job.kwargs)
  File "/home/TendersPlus/matcher/scheduler/__init__.py", line 25, in update_researchers_pool
    ru.update()
  File "/home/TendersPlus/matcher/researcher/update/researcher_updater.py", line 81, in update
    self.__new_tag_df, self.__new_div_df, self.__new_tag_div_map_df = get_user_profile(self.__new_reg_info)
  File "/home/TendersPlus/matcher/utils/feature_utils.py", line 53, in get_user_profile
    input_df[pk] = 'Reg_' + input_df['email']
  File "/usr/local/lib64/python3.6/site-packages/pandas/core/frame.py", line 2906, in __getitem__
    indexer = self.columns.get_loc(key)
  File "/usr/local/lib64/python3.6/site-packages/pandas/core/indexes/base.py", line 2900, in get_loc
    raise KeyError(key) from err
KeyError: 'email'
Job "update_researchers_pool (trigger: interval[0:10:00], next run at: 2022-04-29 03:20:29 CST)" raised an exception
Traceback (most recent call last):
  File "/usr/local/lib64/python3.6/site-packages/pandas/core/indexes/base.py", line 2898, in get_loc
    return self._engine.get_loc(casted_key)
  File "pandas/_libs/index.pyx", line 70, in pandas._libs.index.IndexEngine.get_loc
  File "pandas/_libs/index.pyx", line 101, in pandas._libs.index.IndexEngine.get_loc
  File "pandas/_libs/hashtable_class_helper.pxi", line 1675, in pandas._libs.hashtable.PyObjectHashTable.get_item
  File "pandas/_libs/hashtable_class_helper.pxi", line 1683, in pandas._libs.hashtable.PyObjectHashTable.get_item
KeyError: 'email'

The above exception was the direct cause of the following exception:

Traceback (most recent call last):
  File "/usr/local/lib/python3.6/site-packages/apscheduler/executors/base_py3.py", line 30, in run_coroutine_job
    retval = await job.func(*job.args, **job.kwargs)
  File "/home/TendersPlus/matcher/scheduler/__init__.py", line 25, in update_researchers_pool
    ru.update()
  File "/home/TendersPlus/matcher/researcher/update/researcher_updater.py", line 81, in update
    self.__new_tag_df, self.__new_div_df, self.__new_tag_div_map_df = get_user_profile(self.__new_reg_info)
  File "/home/TendersPlus/matcher/utils/feature_utils.py", line 53, in get_user_profile
    input_df[pk] = 'Reg_' + input_df['email']
  File "/usr/local/lib64/python3.6/site-packages/pandas/core/frame.py", line 2906, in __getitem__
    indexer = self.columns.get_loc(key)
  File "/usr/local/lib64/python3.6/site-packages/pandas/core/indexes/base.py", line 2900, in get_loc
    raise KeyError(key) from err
KeyError: 'email'
Job "update_researchers_pool (trigger: interval[0:10:00], next run at: 2022-04-29 03:30:29 CST)" raised an exception
Traceback (most recent call last):
  File "/usr/local/lib64/python3.6/site-packages/pandas/core/indexes/base.py", line 2898, in get_loc
    return self._engine.get_loc(casted_key)
  File "pandas/_libs/index.pyx", line 70, in pandas._libs.index.IndexEngine.get_loc
  File "pandas/_libs/index.pyx", line 101, in pandas._libs.index.IndexEngine.get_loc
  File "pandas/_libs/hashtable_class_helper.pxi", line 1675, in pandas._libs.hashtable.PyObjectHashTable.get_item
  File "pandas/_libs/hashtable_class_helper.pxi", line 1683, in pandas._libs.hashtable.PyObjectHashTable.get_item
KeyError: 'email'

The above exception was the direct cause of the following exception:

Traceback (most recent call last):
  File "/usr/local/lib/python3.6/site-packages/apscheduler/executors/base_py3.py", line 30, in run_coroutine_job
    retval = await job.func(*job.args, **job.kwargs)
  File "/home/TendersPlus/matcher/scheduler/__init__.py", line 25, in update_researchers_pool
    ru.update()
  File "/home/TendersPlus/matcher/researcher/update/researcher_updater.py", line 81, in update
    self.__new_tag_df, self.__new_div_df, self.__new_tag_div_map_df = get_user_profile(self.__new_reg_info)
  File "/home/TendersPlus/matcher/utils/feature_utils.py", line 53, in get_user_profile
    input_df[pk] = 'Reg_' + input_df['email']
  File "/usr/local/lib64/python3.6/site-packages/pandas/core/frame.py", line 2906, in __getitem__
    indexer = self.columns.get_loc(key)
  File "/usr/local/lib64/python3.6/site-packages/pandas/core/indexes/base.py", line 2900, in get_loc
    raise KeyError(key) from err
KeyError: 'email'
Job "update_researchers_pool (trigger: interval[0:10:00], next run at: 2022-04-29 03:40:29 CST)" raised an exception
Traceback (most recent call last):
  File "/usr/local/lib64/python3.6/site-packages/pandas/core/indexes/base.py", line 2898, in get_loc
    return self._engine.get_loc(casted_key)
  File "pandas/_libs/index.pyx", line 70, in pandas._libs.index.IndexEngine.get_loc
  File "pandas/_libs/index.pyx", line 101, in pandas._libs.index.IndexEngine.get_loc
  File "pandas/_libs/hashtable_class_helper.pxi", line 1675, in pandas._libs.hashtable.PyObjectHashTable.get_item
  File "pandas/_libs/hashtable_class_helper.pxi", line 1683, in pandas._libs.hashtable.PyObjectHashTable.get_item
KeyError: 'email'

The above exception was the direct cause of the following exception:

Traceback (most recent call last):
  File "/usr/local/lib/python3.6/site-packages/apscheduler/executors/base_py3.py", line 30, in run_coroutine_job
    retval = await job.func(*job.args, **job.kwargs)
  File "/home/TendersPlus/matcher/scheduler/__init__.py", line 25, in update_researchers_pool
    ru.update()
  File "/home/TendersPlus/matcher/researcher/update/researcher_updater.py", line 81, in update
    self.__new_tag_df, self.__new_div_df, self.__new_tag_div_map_df = get_user_profile(self.__new_reg_info)
  File "/home/TendersPlus/matcher/utils/feature_utils.py", line 53, in get_user_profile
    input_df[pk] = 'Reg_' + input_df['email']
  File "/usr/local/lib64/python3.6/site-packages/pandas/core/frame.py", line 2906, in __getitem__
    indexer = self.columns.get_loc(key)
  File "/usr/local/lib64/python3.6/site-packages/pandas/core/indexes/base.py", line 2900, in get_loc
    raise KeyError(key) from err
KeyError: 'email'
Job "update_researchers_pool (trigger: interval[0:10:00], next run at: 2022-04-29 03:50:29 CST)" raised an exception
Traceback (most recent call last):
  File "/usr/local/lib64/python3.6/site-packages/pandas/core/indexes/base.py", line 2898, in get_loc
    return self._engine.get_loc(casted_key)
  File "pandas/_libs/index.pyx", line 70, in pandas._libs.index.IndexEngine.get_loc
  File "pandas/_libs/index.pyx", line 101, in pandas._libs.index.IndexEngine.get_loc
  File "pandas/_libs/hashtable_class_helper.pxi", line 1675, in pandas._libs.hashtable.PyObjectHashTable.get_item
  File "pandas/_libs/hashtable_class_helper.pxi", line 1683, in pandas._libs.hashtable.PyObjectHashTable.get_item
KeyError: 'email'

The above exception was the direct cause of the following exception:

Traceback (most recent call last):
  File "/usr/local/lib/python3.6/site-packages/apscheduler/executors/base_py3.py", line 30, in run_coroutine_job
    retval = await job.func(*job.args, **job.kwargs)
  File "/home/TendersPlus/matcher/scheduler/__init__.py", line 25, in update_researchers_pool
    ru.update()
  File "/home/TendersPlus/matcher/researcher/update/researcher_updater.py", line 81, in update
    self.__new_tag_df, self.__new_div_df, self.__new_tag_div_map_df = get_user_profile(self.__new_reg_info)
  File "/home/TendersPlus/matcher/utils/feature_utils.py", line 53, in get_user_profile
    input_df[pk] = 'Reg_' + input_df['email']
  File "/usr/local/lib64/python3.6/site-packages/pandas/core/frame.py", line 2906, in __getitem__
    indexer = self.columns.get_loc(key)
  File "/usr/local/lib64/python3.6/site-packages/pandas/core/indexes/base.py", line 2900, in get_loc
    raise KeyError(key) from err
KeyError: 'email'
Job "update_researchers_pool (trigger: interval[0:10:00], next run at: 2022-04-29 04:00:29 CST)" raised an exception
Traceback (most recent call last):
  File "/usr/local/lib64/python3.6/site-packages/pandas/core/indexes/base.py", line 2898, in get_loc
    return self._engine.get_loc(casted_key)
  File "pandas/_libs/index.pyx", line 70, in pandas._libs.index.IndexEngine.get_loc
  File "pandas/_libs/index.pyx", line 101, in pandas._libs.index.IndexEngine.get_loc
  File "pandas/_libs/hashtable_class_helper.pxi", line 1675, in pandas._libs.hashtable.PyObjectHashTable.get_item
  File "pandas/_libs/hashtable_class_helper.pxi", line 1683, in pandas._libs.hashtable.PyObjectHashTable.get_item
KeyError: 'email'

The above exception was the direct cause of the following exception:

Traceback (most recent call last):
  File "/usr/local/lib/python3.6/site-packages/apscheduler/executors/base_py3.py", line 30, in run_coroutine_job
    retval = await job.func(*job.args, **job.kwargs)
  File "/home/TendersPlus/matcher/scheduler/__init__.py", line 25, in update_researchers_pool
    ru.update()
  File "/home/TendersPlus/matcher/researcher/update/researcher_updater.py", line 81, in update
    self.__new_tag_df, self.__new_div_df, self.__new_tag_div_map_df = get_user_profile(self.__new_reg_info)
  File "/home/TendersPlus/matcher/utils/feature_utils.py", line 53, in get_user_profile
    input_df[pk] = 'Reg_' + input_df['email']
  File "/usr/local/lib64/python3.6/site-packages/pandas/core/frame.py", line 2906, in __getitem__
    indexer = self.columns.get_loc(key)
  File "/usr/local/lib64/python3.6/site-packages/pandas/core/indexes/base.py", line 2900, in get_loc
    raise KeyError(key) from err
KeyError: 'email'
Job "update_researchers_pool (trigger: interval[0:10:00], next run at: 2022-04-29 04:10:29 CST)" raised an exception
Traceback (most recent call last):
  File "/usr/local/lib64/python3.6/site-packages/pandas/core/indexes/base.py", line 2898, in get_loc
    return self._engine.get_loc(casted_key)
  File "pandas/_libs/index.pyx", line 70, in pandas._libs.index.IndexEngine.get_loc
  File "pandas/_libs/index.pyx", line 101, in pandas._libs.index.IndexEngine.get_loc
  File "pandas/_libs/hashtable_class_helper.pxi", line 1675, in pandas._libs.hashtable.PyObjectHashTable.get_item
  File "pandas/_libs/hashtable_class_helper.pxi", line 1683, in pandas._libs.hashtable.PyObjectHashTable.get_item
KeyError: 'email'

The above exception was the direct cause of the following exception:

Traceback (most recent call last):
  File "/usr/local/lib/python3.6/site-packages/apscheduler/executors/base_py3.py", line 30, in run_coroutine_job
    retval = await job.func(*job.args, **job.kwargs)
  File "/home/TendersPlus/matcher/scheduler/__init__.py", line 25, in update_researchers_pool
    ru.update()
  File "/home/TendersPlus/matcher/researcher/update/researcher_updater.py", line 81, in update
    self.__new_tag_df, self.__new_div_df, self.__new_tag_div_map_df = get_user_profile(self.__new_reg_info)
  File "/home/TendersPlus/matcher/utils/feature_utils.py", line 53, in get_user_profile
    input_df[pk] = 'Reg_' + input_df['email']
  File "/usr/local/lib64/python3.6/site-packages/pandas/core/frame.py", line 2906, in __getitem__
    indexer = self.columns.get_loc(key)
  File "/usr/local/lib64/python3.6/site-packages/pandas/core/indexes/base.py", line 2900, in get_loc
    raise KeyError(key) from err
KeyError: 'email'
Job "update_researchers_pool (trigger: interval[0:10:00], next run at: 2022-04-29 04:20:29 CST)" raised an exception
Traceback (most recent call last):
  File "/usr/local/lib64/python3.6/site-packages/pandas/core/indexes/base.py", line 2898, in get_loc
    return self._engine.get_loc(casted_key)
  File "pandas/_libs/index.pyx", line 70, in pandas._libs.index.IndexEngine.get_loc
  File "pandas/_libs/index.pyx", line 101, in pandas._libs.index.IndexEngine.get_loc
  File "pandas/_libs/hashtable_class_helper.pxi", line 1675, in pandas._libs.hashtable.PyObjectHashTable.get_item
  File "pandas/_libs/hashtable_class_helper.pxi", line 1683, in pandas._libs.hashtable.PyObjectHashTable.get_item
KeyError: 'email'

The above exception was the direct cause of the following exception:

Traceback (most recent call last):
  File "/usr/local/lib/python3.6/site-packages/apscheduler/executors/base_py3.py", line 30, in run_coroutine_job
    retval = await job.func(*job.args, **job.kwargs)
  File "/home/TendersPlus/matcher/scheduler/__init__.py", line 25, in update_researchers_pool
    ru.update()
  File "/home/TendersPlus/matcher/researcher/update/researcher_updater.py", line 81, in update
    self.__new_tag_df, self.__new_div_df, self.__new_tag_div_map_df = get_user_profile(self.__new_reg_info)
  File "/home/TendersPlus/matcher/utils/feature_utils.py", line 53, in get_user_profile
    input_df[pk] = 'Reg_' + input_df['email']
  File "/usr/local/lib64/python3.6/site-packages/pandas/core/frame.py", line 2906, in __getitem__
    indexer = self.columns.get_loc(key)
  File "/usr/local/lib64/python3.6/site-packages/pandas/core/indexes/base.py", line 2900, in get_loc
    raise KeyError(key) from err
KeyError: 'email'
Job "update_researchers_pool (trigger: interval[0:10:00], next run at: 2022-04-29 04:30:29 CST)" raised an exception
Traceback (most recent call last):
  File "/usr/local/lib64/python3.6/site-packages/pandas/core/indexes/base.py", line 2898, in get_loc
    return self._engine.get_loc(casted_key)
  File "pandas/_libs/index.pyx", line 70, in pandas._libs.index.IndexEngine.get_loc
  File "pandas/_libs/index.pyx", line 101, in pandas._libs.index.IndexEngine.get_loc
  File "pandas/_libs/hashtable_class_helper.pxi", line 1675, in pandas._libs.hashtable.PyObjectHashTable.get_item
  File "pandas/_libs/hashtable_class_helper.pxi", line 1683, in pandas._libs.hashtable.PyObjectHashTable.get_item
KeyError: 'email'

The above exception was the direct cause of the following exception:

Traceback (most recent call last):
  File "/usr/local/lib/python3.6/site-packages/apscheduler/executors/base_py3.py", line 30, in run_coroutine_job
    retval = await job.func(*job.args, **job.kwargs)
  File "/home/TendersPlus/matcher/scheduler/__init__.py", line 25, in update_researchers_pool
    ru.update()
  File "/home/TendersPlus/matcher/researcher/update/researcher_updater.py", line 81, in update
    self.__new_tag_df, self.__new_div_df, self.__new_tag_div_map_df = get_user_profile(self.__new_reg_info)
  File "/home/TendersPlus/matcher/utils/feature_utils.py", line 53, in get_user_profile
    input_df[pk] = 'Reg_' + input_df['email']
  File "/usr/local/lib64/python3.6/site-packages/pandas/core/frame.py", line 2906, in __getitem__
    indexer = self.columns.get_loc(key)
  File "/usr/local/lib64/python3.6/site-packages/pandas/core/indexes/base.py", line 2900, in get_loc
    raise KeyError(key) from err
KeyError: 'email'
Job "update_researchers_pool (trigger: interval[0:10:00], next run at: 2022-04-29 04:40:29 CST)" raised an exception
Traceback (most recent call last):
  File "/usr/local/lib64/python3.6/site-packages/pandas/core/indexes/base.py", line 2898, in get_loc
    return self._engine.get_loc(casted_key)
  File "pandas/_libs/index.pyx", line 70, in pandas._libs.index.IndexEngine.get_loc
  File "pandas/_libs/index.pyx", line 101, in pandas._libs.index.IndexEngine.get_loc
  File "pandas/_libs/hashtable_class_helper.pxi", line 1675, in pandas._libs.hashtable.PyObjectHashTable.get_item
  File "pandas/_libs/hashtable_class_helper.pxi", line 1683, in pandas._libs.hashtable.PyObjectHashTable.get_item
KeyError: 'email'

The above exception was the direct cause of the following exception:

Traceback (most recent call last):
  File "/usr/local/lib/python3.6/site-packages/apscheduler/executors/base_py3.py", line 30, in run_coroutine_job
    retval = await job.func(*job.args, **job.kwargs)
  File "/home/TendersPlus/matcher/scheduler/__init__.py", line 25, in update_researchers_pool
    ru.update()
  File "/home/TendersPlus/matcher/researcher/update/researcher_updater.py", line 81, in update
    self.__new_tag_df, self.__new_div_df, self.__new_tag_div_map_df = get_user_profile(self.__new_reg_info)
  File "/home/TendersPlus/matcher/utils/feature_utils.py", line 53, in get_user_profile
    input_df[pk] = 'Reg_' + input_df['email']
  File "/usr/local/lib64/python3.6/site-packages/pandas/core/frame.py", line 2906, in __getitem__
    indexer = self.columns.get_loc(key)
  File "/usr/local/lib64/python3.6/site-packages/pandas/core/indexes/base.py", line 2900, in get_loc
    raise KeyError(key) from err
KeyError: 'email'
Run time of job "update_researchers_pool (trigger: interval[0:10:00], next run at: 2022-04-29 04:50:29 CST)" was missed by 0:03:14.993536
Job "update_researchers_pool (trigger: interval[0:10:00], next run at: 2022-04-29 05:00:29 CST)" raised an exception
Traceback (most recent call last):
  File "/usr/local/lib64/python3.6/site-packages/pandas/core/indexes/base.py", line 2898, in get_loc
    return self._engine.get_loc(casted_key)
  File "pandas/_libs/index.pyx", line 70, in pandas._libs.index.IndexEngine.get_loc
  File "pandas/_libs/index.pyx", line 101, in pandas._libs.index.IndexEngine.get_loc
  File "pandas/_libs/hashtable_class_helper.pxi", line 1675, in pandas._libs.hashtable.PyObjectHashTable.get_item
  File "pandas/_libs/hashtable_class_helper.pxi", line 1683, in pandas._libs.hashtable.PyObjectHashTable.get_item
KeyError: 'email'

The above exception was the direct cause of the following exception:

Traceback (most recent call last):
  File "/usr/local/lib/python3.6/site-packages/apscheduler/executors/base_py3.py", line 30, in run_coroutine_job
    retval = await job.func(*job.args, **job.kwargs)
  File "/home/TendersPlus/matcher/scheduler/__init__.py", line 25, in update_researchers_pool
    ru.update()
  File "/home/TendersPlus/matcher/researcher/update/researcher_updater.py", line 81, in update
    self.__new_tag_df, self.__new_div_df, self.__new_tag_div_map_df = get_user_profile(self.__new_reg_info)
  File "/home/TendersPlus/matcher/utils/feature_utils.py", line 53, in get_user_profile
    input_df[pk] = 'Reg_' + input_df['email']
  File "/usr/local/lib64/python3.6/site-packages/pandas/core/frame.py", line 2906, in __getitem__
    indexer = self.columns.get_loc(key)
  File "/usr/local/lib64/python3.6/site-packages/pandas/core/indexes/base.py", line 2900, in get_loc
    raise KeyError(key) from err
KeyError: 'email'
Job "update_researchers_pool (trigger: interval[0:10:00], next run at: 2022-04-29 05:10:29 CST)" raised an exception
Traceback (most recent call last):
  File "/usr/local/lib64/python3.6/site-packages/pandas/core/indexes/base.py", line 2898, in get_loc
    return self._engine.get_loc(casted_key)
  File "pandas/_libs/index.pyx", line 70, in pandas._libs.index.IndexEngine.get_loc
  File "pandas/_libs/index.pyx", line 101, in pandas._libs.index.IndexEngine.get_loc
  File "pandas/_libs/hashtable_class_helper.pxi", line 1675, in pandas._libs.hashtable.PyObjectHashTable.get_item
  File "pandas/_libs/hashtable_class_helper.pxi", line 1683, in pandas._libs.hashtable.PyObjectHashTable.get_item
KeyError: 'email'

The above exception was the direct cause of the following exception:

Traceback (most recent call last):
  File "/usr/local/lib/python3.6/site-packages/apscheduler/executors/base_py3.py", line 30, in run_coroutine_job
    retval = await job.func(*job.args, **job.kwargs)
  File "/home/TendersPlus/matcher/scheduler/__init__.py", line 25, in update_researchers_pool
    ru.update()
  File "/home/TendersPlus/matcher/researcher/update/researcher_updater.py", line 81, in update
    self.__new_tag_df, self.__new_div_df, self.__new_tag_div_map_df = get_user_profile(self.__new_reg_info)
  File "/home/TendersPlus/matcher/utils/feature_utils.py", line 53, in get_user_profile
    input_df[pk] = 'Reg_' + input_df['email']
  File "/usr/local/lib64/python3.6/site-packages/pandas/core/frame.py", line 2906, in __getitem__
    indexer = self.columns.get_loc(key)
  File "/usr/local/lib64/python3.6/site-packages/pandas/core/indexes/base.py", line 2900, in get_loc
    raise KeyError(key) from err
KeyError: 'email'
Job "update_researchers_pool (trigger: interval[0:10:00], next run at: 2022-04-29 05:20:29 CST)" raised an exception
Traceback (most recent call last):
  File "/usr/local/lib64/python3.6/site-packages/pandas/core/indexes/base.py", line 2898, in get_loc
    return self._engine.get_loc(casted_key)
  File "pandas/_libs/index.pyx", line 70, in pandas._libs.index.IndexEngine.get_loc
  File "pandas/_libs/index.pyx", line 101, in pandas._libs.index.IndexEngine.get_loc
  File "pandas/_libs/hashtable_class_helper.pxi", line 1675, in pandas._libs.hashtable.PyObjectHashTable.get_item
  File "pandas/_libs/hashtable_class_helper.pxi", line 1683, in pandas._libs.hashtable.PyObjectHashTable.get_item
KeyError: 'email'

The above exception was the direct cause of the following exception:

Traceback (most recent call last):
  File "/usr/local/lib/python3.6/site-packages/apscheduler/executors/base_py3.py", line 30, in run_coroutine_job
    retval = await job.func(*job.args, **job.kwargs)
  File "/home/TendersPlus/matcher/scheduler/__init__.py", line 25, in update_researchers_pool
    ru.update()
  File "/home/TendersPlus/matcher/researcher/update/researcher_updater.py", line 81, in update
    self.__new_tag_df, self.__new_div_df, self.__new_tag_div_map_df = get_user_profile(self.__new_reg_info)
  File "/home/TendersPlus/matcher/utils/feature_utils.py", line 53, in get_user_profile
    input_df[pk] = 'Reg_' + input_df['email']
  File "/usr/local/lib64/python3.6/site-packages/pandas/core/frame.py", line 2906, in __getitem__
    indexer = self.columns.get_loc(key)
  File "/usr/local/lib64/python3.6/site-packages/pandas/core/indexes/base.py", line 2900, in get_loc
    raise KeyError(key) from err
KeyError: 'email'
Job "update_researchers_pool (trigger: interval[0:10:00], next run at: 2022-04-29 05:30:29 CST)" raised an exception
Traceback (most recent call last):
  File "/usr/local/lib64/python3.6/site-packages/pandas/core/indexes/base.py", line 2898, in get_loc
    return self._engine.get_loc(casted_key)
  File "pandas/_libs/index.pyx", line 70, in pandas._libs.index.IndexEngine.get_loc
  File "pandas/_libs/index.pyx", line 101, in pandas._libs.index.IndexEngine.get_loc
  File "pandas/_libs/hashtable_class_helper.pxi", line 1675, in pandas._libs.hashtable.PyObjectHashTable.get_item
  File "pandas/_libs/hashtable_class_helper.pxi", line 1683, in pandas._libs.hashtable.PyObjectHashTable.get_item
KeyError: 'email'

The above exception was the direct cause of the following exception:

Traceback (most recent call last):
  File "/usr/local/lib/python3.6/site-packages/apscheduler/executors/base_py3.py", line 30, in run_coroutine_job
    retval = await job.func(*job.args, **job.kwargs)
  File "/home/TendersPlus/matcher/scheduler/__init__.py", line 25, in update_researchers_pool
    ru.update()
  File "/home/TendersPlus/matcher/researcher/update/researcher_updater.py", line 81, in update
    self.__new_tag_df, self.__new_div_df, self.__new_tag_div_map_df = get_user_profile(self.__new_reg_info)
  File "/home/TendersPlus/matcher/utils/feature_utils.py", line 53, in get_user_profile
    input_df[pk] = 'Reg_' + input_df['email']
  File "/usr/local/lib64/python3.6/site-packages/pandas/core/frame.py", line 2906, in __getitem__
    indexer = self.columns.get_loc(key)
  File "/usr/local/lib64/python3.6/site-packages/pandas/core/indexes/base.py", line 2900, in get_loc
    raise KeyError(key) from err
KeyError: 'email'
Job "update_researchers_pool (trigger: interval[0:10:00], next run at: 2022-04-29 05:40:29 CST)" raised an exception
Traceback (most recent call last):
  File "/usr/local/lib64/python3.6/site-packages/pandas/core/indexes/base.py", line 2898, in get_loc
    return self._engine.get_loc(casted_key)
  File "pandas/_libs/index.pyx", line 70, in pandas._libs.index.IndexEngine.get_loc
  File "pandas/_libs/index.pyx", line 101, in pandas._libs.index.IndexEngine.get_loc
  File "pandas/_libs/hashtable_class_helper.pxi", line 1675, in pandas._libs.hashtable.PyObjectHashTable.get_item
  File "pandas/_libs/hashtable_class_helper.pxi", line 1683, in pandas._libs.hashtable.PyObjectHashTable.get_item
KeyError: 'email'

The above exception was the direct cause of the following exception:

Traceback (most recent call last):
  File "/usr/local/lib/python3.6/site-packages/apscheduler/executors/base_py3.py", line 30, in run_coroutine_job
    retval = await job.func(*job.args, **job.kwargs)
  File "/home/TendersPlus/matcher/scheduler/__init__.py", line 25, in update_researchers_pool
    ru.update()
  File "/home/TendersPlus/matcher/researcher/update/researcher_updater.py", line 81, in update
    self.__new_tag_df, self.__new_div_df, self.__new_tag_div_map_df = get_user_profile(self.__new_reg_info)
  File "/home/TendersPlus/matcher/utils/feature_utils.py", line 53, in get_user_profile
    input_df[pk] = 'Reg_' + input_df['email']
  File "/usr/local/lib64/python3.6/site-packages/pandas/core/frame.py", line 2906, in __getitem__
    indexer = self.columns.get_loc(key)
  File "/usr/local/lib64/python3.6/site-packages/pandas/core/indexes/base.py", line 2900, in get_loc
    raise KeyError(key) from err
KeyError: 'email'
Job "update_researchers_pool (trigger: interval[0:10:00], next run at: 2022-04-29 05:50:29 CST)" raised an exception
Traceback (most recent call last):
  File "/usr/local/lib64/python3.6/site-packages/pandas/core/indexes/base.py", line 2898, in get_loc
    return self._engine.get_loc(casted_key)
  File "pandas/_libs/index.pyx", line 70, in pandas._libs.index.IndexEngine.get_loc
  File "pandas/_libs/index.pyx", line 101, in pandas._libs.index.IndexEngine.get_loc
  File "pandas/_libs/hashtable_class_helper.pxi", line 1675, in pandas._libs.hashtable.PyObjectHashTable.get_item
  File "pandas/_libs/hashtable_class_helper.pxi", line 1683, in pandas._libs.hashtable.PyObjectHashTable.get_item
KeyError: 'email'

The above exception was the direct cause of the following exception:

Traceback (most recent call last):
  File "/usr/local/lib/python3.6/site-packages/apscheduler/executors/base_py3.py", line 30, in run_coroutine_job
    retval = await job.func(*job.args, **job.kwargs)
  File "/home/TendersPlus/matcher/scheduler/__init__.py", line 25, in update_researchers_pool
    ru.update()
  File "/home/TendersPlus/matcher/researcher/update/researcher_updater.py", line 81, in update
    self.__new_tag_df, self.__new_div_df, self.__new_tag_div_map_df = get_user_profile(self.__new_reg_info)
  File "/home/TendersPlus/matcher/utils/feature_utils.py", line 53, in get_user_profile
    input_df[pk] = 'Reg_' + input_df['email']
  File "/usr/local/lib64/python3.6/site-packages/pandas/core/frame.py", line 2906, in __getitem__
    indexer = self.columns.get_loc(key)
  File "/usr/local/lib64/python3.6/site-packages/pandas/core/indexes/base.py", line 2900, in get_loc
    raise KeyError(key) from err
KeyError: 'email'
Job "update_researchers_pool (trigger: interval[0:10:00], next run at: 2022-04-29 06:00:29 CST)" raised an exception
Traceback (most recent call last):
  File "/usr/local/lib64/python3.6/site-packages/pandas/core/indexes/base.py", line 2898, in get_loc
    return self._engine.get_loc(casted_key)
  File "pandas/_libs/index.pyx", line 70, in pandas._libs.index.IndexEngine.get_loc
  File "pandas/_libs/index.pyx", line 101, in pandas._libs.index.IndexEngine.get_loc
  File "pandas/_libs/hashtable_class_helper.pxi", line 1675, in pandas._libs.hashtable.PyObjectHashTable.get_item
  File "pandas/_libs/hashtable_class_helper.pxi", line 1683, in pandas._libs.hashtable.PyObjectHashTable.get_item
KeyError: 'email'

The above exception was the direct cause of the following exception:

Traceback (most recent call last):
  File "/usr/local/lib/python3.6/site-packages/apscheduler/executors/base_py3.py", line 30, in run_coroutine_job
    retval = await job.func(*job.args, **job.kwargs)
  File "/home/TendersPlus/matcher/scheduler/__init__.py", line 25, in update_researchers_pool
    ru.update()
  File "/home/TendersPlus/matcher/researcher/update/researcher_updater.py", line 81, in update
    self.__new_tag_df, self.__new_div_df, self.__new_tag_div_map_df = get_user_profile(self.__new_reg_info)
  File "/home/TendersPlus/matcher/utils/feature_utils.py", line 53, in get_user_profile
    input_df[pk] = 'Reg_' + input_df['email']
  File "/usr/local/lib64/python3.6/site-packages/pandas/core/frame.py", line 2906, in __getitem__
    indexer = self.columns.get_loc(key)
  File "/usr/local/lib64/python3.6/site-packages/pandas/core/indexes/base.py", line 2900, in get_loc
    raise KeyError(key) from err
KeyError: 'email'
Job "update_researchers_pool (trigger: interval[0:10:00], next run at: 2022-04-29 06:10:29 CST)" raised an exception
Traceback (most recent call last):
  File "/usr/local/lib64/python3.6/site-packages/pandas/core/indexes/base.py", line 2898, in get_loc
    return self._engine.get_loc(casted_key)
  File "pandas/_libs/index.pyx", line 70, in pandas._libs.index.IndexEngine.get_loc
  File "pandas/_libs/index.pyx", line 101, in pandas._libs.index.IndexEngine.get_loc
  File "pandas/_libs/hashtable_class_helper.pxi", line 1675, in pandas._libs.hashtable.PyObjectHashTable.get_item
  File "pandas/_libs/hashtable_class_helper.pxi", line 1683, in pandas._libs.hashtable.PyObjectHashTable.get_item
KeyError: 'email'

The above exception was the direct cause of the following exception:

Traceback (most recent call last):
  File "/usr/local/lib/python3.6/site-packages/apscheduler/executors/base_py3.py", line 30, in run_coroutine_job
    retval = await job.func(*job.args, **job.kwargs)
  File "/home/TendersPlus/matcher/scheduler/__init__.py", line 25, in update_researchers_pool
    ru.update()
  File "/home/TendersPlus/matcher/researcher/update/researcher_updater.py", line 81, in update
    self.__new_tag_df, self.__new_div_df, self.__new_tag_div_map_df = get_user_profile(self.__new_reg_info)
  File "/home/TendersPlus/matcher/utils/feature_utils.py", line 53, in get_user_profile
    input_df[pk] = 'Reg_' + input_df['email']
  File "/usr/local/lib64/python3.6/site-packages/pandas/core/frame.py", line 2906, in __getitem__
    indexer = self.columns.get_loc(key)
  File "/usr/local/lib64/python3.6/site-packages/pandas/core/indexes/base.py", line 2900, in get_loc
    raise KeyError(key) from err
KeyError: 'email'
Job "update_researchers_pool (trigger: interval[0:10:00], next run at: 2022-04-29 06:20:29 CST)" raised an exception
Traceback (most recent call last):
  File "/usr/local/lib64/python3.6/site-packages/pandas/core/indexes/base.py", line 2898, in get_loc
    return self._engine.get_loc(casted_key)
  File "pandas/_libs/index.pyx", line 70, in pandas._libs.index.IndexEngine.get_loc
  File "pandas/_libs/index.pyx", line 101, in pandas._libs.index.IndexEngine.get_loc
  File "pandas/_libs/hashtable_class_helper.pxi", line 1675, in pandas._libs.hashtable.PyObjectHashTable.get_item
  File "pandas/_libs/hashtable_class_helper.pxi", line 1683, in pandas._libs.hashtable.PyObjectHashTable.get_item
KeyError: 'email'

The above exception was the direct cause of the following exception:

Traceback (most recent call last):
  File "/usr/local/lib/python3.6/site-packages/apscheduler/executors/base_py3.py", line 30, in run_coroutine_job
    retval = await job.func(*job.args, **job.kwargs)
  File "/home/TendersPlus/matcher/scheduler/__init__.py", line 25, in update_researchers_pool
    ru.update()
  File "/home/TendersPlus/matcher/researcher/update/researcher_updater.py", line 81, in update
    self.__new_tag_df, self.__new_div_df, self.__new_tag_div_map_df = get_user_profile(self.__new_reg_info)
  File "/home/TendersPlus/matcher/utils/feature_utils.py", line 53, in get_user_profile
    input_df[pk] = 'Reg_' + input_df['email']
  File "/usr/local/lib64/python3.6/site-packages/pandas/core/frame.py", line 2906, in __getitem__
    indexer = self.columns.get_loc(key)
  File "/usr/local/lib64/python3.6/site-packages/pandas/core/indexes/base.py", line 2900, in get_loc
    raise KeyError(key) from err
KeyError: 'email'
Job "update_researchers_pool (trigger: interval[0:10:00], next run at: 2022-04-29 06:30:29 CST)" raised an exception
Traceback (most recent call last):
  File "/usr/local/lib64/python3.6/site-packages/pandas/core/indexes/base.py", line 2898, in get_loc
    return self._engine.get_loc(casted_key)
  File "pandas/_libs/index.pyx", line 70, in pandas._libs.index.IndexEngine.get_loc
  File "pandas/_libs/index.pyx", line 101, in pandas._libs.index.IndexEngine.get_loc
  File "pandas/_libs/hashtable_class_helper.pxi", line 1675, in pandas._libs.hashtable.PyObjectHashTable.get_item
  File "pandas/_libs/hashtable_class_helper.pxi", line 1683, in pandas._libs.hashtable.PyObjectHashTable.get_item
KeyError: 'email'

The above exception was the direct cause of the following exception:

Traceback (most recent call last):
  File "/usr/local/lib/python3.6/site-packages/apscheduler/executors/base_py3.py", line 30, in run_coroutine_job
    retval = await job.func(*job.args, **job.kwargs)
  File "/home/TendersPlus/matcher/scheduler/__init__.py", line 25, in update_researchers_pool
    ru.update()
  File "/home/TendersPlus/matcher/researcher/update/researcher_updater.py", line 81, in update
    self.__new_tag_df, self.__new_div_df, self.__new_tag_div_map_df = get_user_profile(self.__new_reg_info)
  File "/home/TendersPlus/matcher/utils/feature_utils.py", line 53, in get_user_profile
    input_df[pk] = 'Reg_' + input_df['email']
  File "/usr/local/lib64/python3.6/site-packages/pandas/core/frame.py", line 2906, in __getitem__
    indexer = self.columns.get_loc(key)
  File "/usr/local/lib64/python3.6/site-packages/pandas/core/indexes/base.py", line 2900, in get_loc
    raise KeyError(key) from err
KeyError: 'email'
Job "update_researchers_pool (trigger: interval[0:10:00], next run at: 2022-04-29 06:40:29 CST)" raised an exception
Traceback (most recent call last):
  File "/usr/local/lib64/python3.6/site-packages/pandas/core/indexes/base.py", line 2898, in get_loc
    return self._engine.get_loc(casted_key)
  File "pandas/_libs/index.pyx", line 70, in pandas._libs.index.IndexEngine.get_loc
  File "pandas/_libs/index.pyx", line 101, in pandas._libs.index.IndexEngine.get_loc
  File "pandas/_libs/hashtable_class_helper.pxi", line 1675, in pandas._libs.hashtable.PyObjectHashTable.get_item
  File "pandas/_libs/hashtable_class_helper.pxi", line 1683, in pandas._libs.hashtable.PyObjectHashTable.get_item
KeyError: 'email'

The above exception was the direct cause of the following exception:

Traceback (most recent call last):
  File "/usr/local/lib/python3.6/site-packages/apscheduler/executors/base_py3.py", line 30, in run_coroutine_job
    retval = await job.func(*job.args, **job.kwargs)
  File "/home/TendersPlus/matcher/scheduler/__init__.py", line 25, in update_researchers_pool
    ru.update()
  File "/home/TendersPlus/matcher/researcher/update/researcher_updater.py", line 81, in update
    self.__new_tag_df, self.__new_div_df, self.__new_tag_div_map_df = get_user_profile(self.__new_reg_info)
  File "/home/TendersPlus/matcher/utils/feature_utils.py", line 53, in get_user_profile
    input_df[pk] = 'Reg_' + input_df['email']
  File "/usr/local/lib64/python3.6/site-packages/pandas/core/frame.py", line 2906, in __getitem__
    indexer = self.columns.get_loc(key)
  File "/usr/local/lib64/python3.6/site-packages/pandas/core/indexes/base.py", line 2900, in get_loc
    raise KeyError(key) from err
KeyError: 'email'
Job "update_researchers_pool (trigger: interval[0:10:00], next run at: 2022-04-29 06:50:29 CST)" raised an exception
Traceback (most recent call last):
  File "/usr/local/lib64/python3.6/site-packages/pandas/core/indexes/base.py", line 2898, in get_loc
    return self._engine.get_loc(casted_key)
  File "pandas/_libs/index.pyx", line 70, in pandas._libs.index.IndexEngine.get_loc
  File "pandas/_libs/index.pyx", line 101, in pandas._libs.index.IndexEngine.get_loc
  File "pandas/_libs/hashtable_class_helper.pxi", line 1675, in pandas._libs.hashtable.PyObjectHashTable.get_item
  File "pandas/_libs/hashtable_class_helper.pxi", line 1683, in pandas._libs.hashtable.PyObjectHashTable.get_item
KeyError: 'email'

The above exception was the direct cause of the following exception:

Traceback (most recent call last):
  File "/usr/local/lib/python3.6/site-packages/apscheduler/executors/base_py3.py", line 30, in run_coroutine_job
    retval = await job.func(*job.args, **job.kwargs)
  File "/home/TendersPlus/matcher/scheduler/__init__.py", line 25, in update_researchers_pool
    ru.update()
  File "/home/TendersPlus/matcher/researcher/update/researcher_updater.py", line 81, in update
    self.__new_tag_df, self.__new_div_df, self.__new_tag_div_map_df = get_user_profile(self.__new_reg_info)
  File "/home/TendersPlus/matcher/utils/feature_utils.py", line 53, in get_user_profile
    input_df[pk] = 'Reg_' + input_df['email']
  File "/usr/local/lib64/python3.6/site-packages/pandas/core/frame.py", line 2906, in __getitem__
    indexer = self.columns.get_loc(key)
  File "/usr/local/lib64/python3.6/site-packages/pandas/core/indexes/base.py", line 2900, in get_loc
    raise KeyError(key) from err
KeyError: 'email'
Job "update_researchers_pool (trigger: interval[0:10:00], next run at: 2022-04-29 07:00:29 CST)" raised an exception
Traceback (most recent call last):
  File "/usr/local/lib64/python3.6/site-packages/pandas/core/indexes/base.py", line 2898, in get_loc
    return self._engine.get_loc(casted_key)
  File "pandas/_libs/index.pyx", line 70, in pandas._libs.index.IndexEngine.get_loc
  File "pandas/_libs/index.pyx", line 101, in pandas._libs.index.IndexEngine.get_loc
  File "pandas/_libs/hashtable_class_helper.pxi", line 1675, in pandas._libs.hashtable.PyObjectHashTable.get_item
  File "pandas/_libs/hashtable_class_helper.pxi", line 1683, in pandas._libs.hashtable.PyObjectHashTable.get_item
KeyError: 'email'

The above exception was the direct cause of the following exception:

Traceback (most recent call last):
  File "/usr/local/lib/python3.6/site-packages/apscheduler/executors/base_py3.py", line 30, in run_coroutine_job
    retval = await job.func(*job.args, **job.kwargs)
  File "/home/TendersPlus/matcher/scheduler/__init__.py", line 25, in update_researchers_pool
    ru.update()
  File "/home/TendersPlus/matcher/researcher/update/researcher_updater.py", line 81, in update
    self.__new_tag_df, self.__new_div_df, self.__new_tag_div_map_df = get_user_profile(self.__new_reg_info)
  File "/home/TendersPlus/matcher/utils/feature_utils.py", line 53, in get_user_profile
    input_df[pk] = 'Reg_' + input_df['email']
  File "/usr/local/lib64/python3.6/site-packages/pandas/core/frame.py", line 2906, in __getitem__
    indexer = self.columns.get_loc(key)
  File "/usr/local/lib64/python3.6/site-packages/pandas/core/indexes/base.py", line 2900, in get_loc
    raise KeyError(key) from err
KeyError: 'email'
Job "update_researchers_pool (trigger: interval[0:10:00], next run at: 2022-04-29 07:10:29 CST)" raised an exception
Traceback (most recent call last):
  File "/usr/local/lib64/python3.6/site-packages/pandas/core/indexes/base.py", line 2898, in get_loc
    return self._engine.get_loc(casted_key)
  File "pandas/_libs/index.pyx", line 70, in pandas._libs.index.IndexEngine.get_loc
  File "pandas/_libs/index.pyx", line 101, in pandas._libs.index.IndexEngine.get_loc
  File "pandas/_libs/hashtable_class_helper.pxi", line 1675, in pandas._libs.hashtable.PyObjectHashTable.get_item
  File "pandas/_libs/hashtable_class_helper.pxi", line 1683, in pandas._libs.hashtable.PyObjectHashTable.get_item
KeyError: 'email'

The above exception was the direct cause of the following exception:

Traceback (most recent call last):
  File "/usr/local/lib/python3.6/site-packages/apscheduler/executors/base_py3.py", line 30, in run_coroutine_job
    retval = await job.func(*job.args, **job.kwargs)
  File "/home/TendersPlus/matcher/scheduler/__init__.py", line 25, in update_researchers_pool
    ru.update()
  File "/home/TendersPlus/matcher/researcher/update/researcher_updater.py", line 81, in update
    self.__new_tag_df, self.__new_div_df, self.__new_tag_div_map_df = get_user_profile(self.__new_reg_info)
  File "/home/TendersPlus/matcher/utils/feature_utils.py", line 53, in get_user_profile
    input_df[pk] = 'Reg_' + input_df['email']
  File "/usr/local/lib64/python3.6/site-packages/pandas/core/frame.py", line 2906, in __getitem__
    indexer = self.columns.get_loc(key)
  File "/usr/local/lib64/python3.6/site-packages/pandas/core/indexes/base.py", line 2900, in get_loc
    raise KeyError(key) from err
KeyError: 'email'
Job "update_researchers_pool (trigger: interval[0:10:00], next run at: 2022-04-29 07:20:29 CST)" raised an exception
Traceback (most recent call last):
  File "/usr/local/lib64/python3.6/site-packages/pandas/core/indexes/base.py", line 2898, in get_loc
    return self._engine.get_loc(casted_key)
  File "pandas/_libs/index.pyx", line 70, in pandas._libs.index.IndexEngine.get_loc
  File "pandas/_libs/index.pyx", line 101, in pandas._libs.index.IndexEngine.get_loc
  File "pandas/_libs/hashtable_class_helper.pxi", line 1675, in pandas._libs.hashtable.PyObjectHashTable.get_item
  File "pandas/_libs/hashtable_class_helper.pxi", line 1683, in pandas._libs.hashtable.PyObjectHashTable.get_item
KeyError: 'email'

The above exception was the direct cause of the following exception:

Traceback (most recent call last):
  File "/usr/local/lib/python3.6/site-packages/apscheduler/executors/base_py3.py", line 30, in run_coroutine_job
    retval = await job.func(*job.args, **job.kwargs)
  File "/home/TendersPlus/matcher/scheduler/__init__.py", line 25, in update_researchers_pool
    ru.update()
  File "/home/TendersPlus/matcher/researcher/update/researcher_updater.py", line 81, in update
    self.__new_tag_df, self.__new_div_df, self.__new_tag_div_map_df = get_user_profile(self.__new_reg_info)
  File "/home/TendersPlus/matcher/utils/feature_utils.py", line 53, in get_user_profile
    input_df[pk] = 'Reg_' + input_df['email']
  File "/usr/local/lib64/python3.6/site-packages/pandas/core/frame.py", line 2906, in __getitem__
    indexer = self.columns.get_loc(key)
  File "/usr/local/lib64/python3.6/site-packages/pandas/core/indexes/base.py", line 2900, in get_loc
    raise KeyError(key) from err
KeyError: 'email'
Job "update_researchers_pool (trigger: interval[0:10:00], next run at: 2022-04-29 07:30:29 CST)" raised an exception
Traceback (most recent call last):
  File "/usr/local/lib64/python3.6/site-packages/pandas/core/indexes/base.py", line 2898, in get_loc
    return self._engine.get_loc(casted_key)
  File "pandas/_libs/index.pyx", line 70, in pandas._libs.index.IndexEngine.get_loc
  File "pandas/_libs/index.pyx", line 101, in pandas._libs.index.IndexEngine.get_loc
  File "pandas/_libs/hashtable_class_helper.pxi", line 1675, in pandas._libs.hashtable.PyObjectHashTable.get_item
  File "pandas/_libs/hashtable_class_helper.pxi", line 1683, in pandas._libs.hashtable.PyObjectHashTable.get_item
KeyError: 'email'

The above exception was the direct cause of the following exception:

Traceback (most recent call last):
  File "/usr/local/lib/python3.6/site-packages/apscheduler/executors/base_py3.py", line 30, in run_coroutine_job
    retval = await job.func(*job.args, **job.kwargs)
  File "/home/TendersPlus/matcher/scheduler/__init__.py", line 25, in update_researchers_pool
    ru.update()
  File "/home/TendersPlus/matcher/researcher/update/researcher_updater.py", line 81, in update
    self.__new_tag_df, self.__new_div_df, self.__new_tag_div_map_df = get_user_profile(self.__new_reg_info)
  File "/home/TendersPlus/matcher/utils/feature_utils.py", line 53, in get_user_profile
    input_df[pk] = 'Reg_' + input_df['email']
  File "/usr/local/lib64/python3.6/site-packages/pandas/core/frame.py", line 2906, in __getitem__
    indexer = self.columns.get_loc(key)
  File "/usr/local/lib64/python3.6/site-packages/pandas/core/indexes/base.py", line 2900, in get_loc
    raise KeyError(key) from err
KeyError: 'email'
Job "update_researchers_pool (trigger: interval[0:10:00], next run at: 2022-04-29 07:40:29 CST)" raised an exception
Traceback (most recent call last):
  File "/usr/local/lib64/python3.6/site-packages/pandas/core/indexes/base.py", line 2898, in get_loc
    return self._engine.get_loc(casted_key)
  File "pandas/_libs/index.pyx", line 70, in pandas._libs.index.IndexEngine.get_loc
  File "pandas/_libs/index.pyx", line 101, in pandas._libs.index.IndexEngine.get_loc
  File "pandas/_libs/hashtable_class_helper.pxi", line 1675, in pandas._libs.hashtable.PyObjectHashTable.get_item
  File "pandas/_libs/hashtable_class_helper.pxi", line 1683, in pandas._libs.hashtable.PyObjectHashTable.get_item
KeyError: 'email'

The above exception was the direct cause of the following exception:

Traceback (most recent call last):
  File "/usr/local/lib/python3.6/site-packages/apscheduler/executors/base_py3.py", line 30, in run_coroutine_job
    retval = await job.func(*job.args, **job.kwargs)
  File "/home/TendersPlus/matcher/scheduler/__init__.py", line 25, in update_researchers_pool
    ru.update()
  File "/home/TendersPlus/matcher/researcher/update/researcher_updater.py", line 81, in update
    self.__new_tag_df, self.__new_div_df, self.__new_tag_div_map_df = get_user_profile(self.__new_reg_info)
  File "/home/TendersPlus/matcher/utils/feature_utils.py", line 53, in get_user_profile
    input_df[pk] = 'Reg_' + input_df['email']
  File "/usr/local/lib64/python3.6/site-packages/pandas/core/frame.py", line 2906, in __getitem__
    indexer = self.columns.get_loc(key)
  File "/usr/local/lib64/python3.6/site-packages/pandas/core/indexes/base.py", line 2900, in get_loc
    raise KeyError(key) from err
KeyError: 'email'
Job "update_researchers_pool (trigger: interval[0:10:00], next run at: 2022-04-29 07:50:29 CST)" raised an exception
Traceback (most recent call last):
  File "/usr/local/lib64/python3.6/site-packages/pandas/core/indexes/base.py", line 2898, in get_loc
    return self._engine.get_loc(casted_key)
  File "pandas/_libs/index.pyx", line 70, in pandas._libs.index.IndexEngine.get_loc
  File "pandas/_libs/index.pyx", line 101, in pandas._libs.index.IndexEngine.get_loc
  File "pandas/_libs/hashtable_class_helper.pxi", line 1675, in pandas._libs.hashtable.PyObjectHashTable.get_item
  File "pandas/_libs/hashtable_class_helper.pxi", line 1683, in pandas._libs.hashtable.PyObjectHashTable.get_item
KeyError: 'email'

The above exception was the direct cause of the following exception:

Traceback (most recent call last):
  File "/usr/local/lib/python3.6/site-packages/apscheduler/executors/base_py3.py", line 30, in run_coroutine_job
    retval = await job.func(*job.args, **job.kwargs)
  File "/home/TendersPlus/matcher/scheduler/__init__.py", line 25, in update_researchers_pool
    ru.update()
  File "/home/TendersPlus/matcher/researcher/update/researcher_updater.py", line 81, in update
    self.__new_tag_df, self.__new_div_df, self.__new_tag_div_map_df = get_user_profile(self.__new_reg_info)
  File "/home/TendersPlus/matcher/utils/feature_utils.py", line 53, in get_user_profile
    input_df[pk] = 'Reg_' + input_df['email']
  File "/usr/local/lib64/python3.6/site-packages/pandas/core/frame.py", line 2906, in __getitem__
    indexer = self.columns.get_loc(key)
  File "/usr/local/lib64/python3.6/site-packages/pandas/core/indexes/base.py", line 2900, in get_loc
    raise KeyError(key) from err
KeyError: 'email'
Job "update_researchers_pool (trigger: interval[0:10:00], next run at: 2022-04-29 08:00:29 CST)" raised an exception
Traceback (most recent call last):
  File "/usr/local/lib64/python3.6/site-packages/pandas/core/indexes/base.py", line 2898, in get_loc
    return self._engine.get_loc(casted_key)
  File "pandas/_libs/index.pyx", line 70, in pandas._libs.index.IndexEngine.get_loc
  File "pandas/_libs/index.pyx", line 101, in pandas._libs.index.IndexEngine.get_loc
  File "pandas/_libs/hashtable_class_helper.pxi", line 1675, in pandas._libs.hashtable.PyObjectHashTable.get_item
  File "pandas/_libs/hashtable_class_helper.pxi", line 1683, in pandas._libs.hashtable.PyObjectHashTable.get_item
KeyError: 'email'

The above exception was the direct cause of the following exception:

Traceback (most recent call last):
  File "/usr/local/lib/python3.6/site-packages/apscheduler/executors/base_py3.py", line 30, in run_coroutine_job
    retval = await job.func(*job.args, **job.kwargs)
  File "/home/TendersPlus/matcher/scheduler/__init__.py", line 25, in update_researchers_pool
    ru.update()
  File "/home/TendersPlus/matcher/researcher/update/researcher_updater.py", line 81, in update
    self.__new_tag_df, self.__new_div_df, self.__new_tag_div_map_df = get_user_profile(self.__new_reg_info)
  File "/home/TendersPlus/matcher/utils/feature_utils.py", line 53, in get_user_profile
    input_df[pk] = 'Reg_' + input_df['email']
  File "/usr/local/lib64/python3.6/site-packages/pandas/core/frame.py", line 2906, in __getitem__
    indexer = self.columns.get_loc(key)
  File "/usr/local/lib64/python3.6/site-packages/pandas/core/indexes/base.py", line 2900, in get_loc
    raise KeyError(key) from err
KeyError: 'email'
Job "update_researchers_pool (trigger: interval[0:10:00], next run at: 2022-04-29 08:10:29 CST)" raised an exception
Traceback (most recent call last):
  File "/usr/local/lib64/python3.6/site-packages/pandas/core/indexes/base.py", line 2898, in get_loc
    return self._engine.get_loc(casted_key)
  File "pandas/_libs/index.pyx", line 70, in pandas._libs.index.IndexEngine.get_loc
  File "pandas/_libs/index.pyx", line 101, in pandas._libs.index.IndexEngine.get_loc
  File "pandas/_libs/hashtable_class_helper.pxi", line 1675, in pandas._libs.hashtable.PyObjectHashTable.get_item
  File "pandas/_libs/hashtable_class_helper.pxi", line 1683, in pandas._libs.hashtable.PyObjectHashTable.get_item
KeyError: 'email'

The above exception was the direct cause of the following exception:

Traceback (most recent call last):
  File "/usr/local/lib/python3.6/site-packages/apscheduler/executors/base_py3.py", line 30, in run_coroutine_job
    retval = await job.func(*job.args, **job.kwargs)
  File "/home/TendersPlus/matcher/scheduler/__init__.py", line 25, in update_researchers_pool
    ru.update()
  File "/home/TendersPlus/matcher/researcher/update/researcher_updater.py", line 81, in update
    self.__new_tag_df, self.__new_div_df, self.__new_tag_div_map_df = get_user_profile(self.__new_reg_info)
  File "/home/TendersPlus/matcher/utils/feature_utils.py", line 53, in get_user_profile
    input_df[pk] = 'Reg_' + input_df['email']
  File "/usr/local/lib64/python3.6/site-packages/pandas/core/frame.py", line 2906, in __getitem__
    indexer = self.columns.get_loc(key)
  File "/usr/local/lib64/python3.6/site-packages/pandas/core/indexes/base.py", line 2900, in get_loc
    raise KeyError(key) from err
KeyError: 'email'
Job "update_researchers_pool (trigger: interval[0:10:00], next run at: 2022-04-29 08:20:29 CST)" raised an exception
Traceback (most recent call last):
  File "/usr/local/lib64/python3.6/site-packages/pandas/core/indexes/base.py", line 2898, in get_loc
    return self._engine.get_loc(casted_key)
  File "pandas/_libs/index.pyx", line 70, in pandas._libs.index.IndexEngine.get_loc
  File "pandas/_libs/index.pyx", line 101, in pandas._libs.index.IndexEngine.get_loc
  File "pandas/_libs/hashtable_class_helper.pxi", line 1675, in pandas._libs.hashtable.PyObjectHashTable.get_item
  File "pandas/_libs/hashtable_class_helper.pxi", line 1683, in pandas._libs.hashtable.PyObjectHashTable.get_item
KeyError: 'email'

The above exception was the direct cause of the following exception:

Traceback (most recent call last):
  File "/usr/local/lib/python3.6/site-packages/apscheduler/executors/base_py3.py", line 30, in run_coroutine_job
    retval = await job.func(*job.args, **job.kwargs)
  File "/home/TendersPlus/matcher/scheduler/__init__.py", line 25, in update_researchers_pool
    ru.update()
  File "/home/TendersPlus/matcher/researcher/update/researcher_updater.py", line 81, in update
    self.__new_tag_df, self.__new_div_df, self.__new_tag_div_map_df = get_user_profile(self.__new_reg_info)
  File "/home/TendersPlus/matcher/utils/feature_utils.py", line 53, in get_user_profile
    input_df[pk] = 'Reg_' + input_df['email']
  File "/usr/local/lib64/python3.6/site-packages/pandas/core/frame.py", line 2906, in __getitem__
    indexer = self.columns.get_loc(key)
  File "/usr/local/lib64/python3.6/site-packages/pandas/core/indexes/base.py", line 2900, in get_loc
    raise KeyError(key) from err
KeyError: 'email'
Job "update_researchers_pool (trigger: interval[0:10:00], next run at: 2022-04-29 08:30:29 CST)" raised an exception
Traceback (most recent call last):
  File "/usr/local/lib64/python3.6/site-packages/pandas/core/indexes/base.py", line 2898, in get_loc
    return self._engine.get_loc(casted_key)
  File "pandas/_libs/index.pyx", line 70, in pandas._libs.index.IndexEngine.get_loc
  File "pandas/_libs/index.pyx", line 101, in pandas._libs.index.IndexEngine.get_loc
  File "pandas/_libs/hashtable_class_helper.pxi", line 1675, in pandas._libs.hashtable.PyObjectHashTable.get_item
  File "pandas/_libs/hashtable_class_helper.pxi", line 1683, in pandas._libs.hashtable.PyObjectHashTable.get_item
KeyError: 'email'

The above exception was the direct cause of the following exception:

Traceback (most recent call last):
  File "/usr/local/lib/python3.6/site-packages/apscheduler/executors/base_py3.py", line 30, in run_coroutine_job
    retval = await job.func(*job.args, **job.kwargs)
  File "/home/TendersPlus/matcher/scheduler/__init__.py", line 25, in update_researchers_pool
    ru.update()
  File "/home/TendersPlus/matcher/researcher/update/researcher_updater.py", line 81, in update
    self.__new_tag_df, self.__new_div_df, self.__new_tag_div_map_df = get_user_profile(self.__new_reg_info)
  File "/home/TendersPlus/matcher/utils/feature_utils.py", line 53, in get_user_profile
    input_df[pk] = 'Reg_' + input_df['email']
  File "/usr/local/lib64/python3.6/site-packages/pandas/core/frame.py", line 2906, in __getitem__
    indexer = self.columns.get_loc(key)
  File "/usr/local/lib64/python3.6/site-packages/pandas/core/indexes/base.py", line 2900, in get_loc
    raise KeyError(key) from err
KeyError: 'email'
Job "update_researchers_pool (trigger: interval[0:10:00], next run at: 2022-04-29 08:40:29 CST)" raised an exception
Traceback (most recent call last):
  File "/usr/local/lib64/python3.6/site-packages/pandas/core/indexes/base.py", line 2898, in get_loc
    return self._engine.get_loc(casted_key)
  File "pandas/_libs/index.pyx", line 70, in pandas._libs.index.IndexEngine.get_loc
  File "pandas/_libs/index.pyx", line 101, in pandas._libs.index.IndexEngine.get_loc
  File "pandas/_libs/hashtable_class_helper.pxi", line 1675, in pandas._libs.hashtable.PyObjectHashTable.get_item
  File "pandas/_libs/hashtable_class_helper.pxi", line 1683, in pandas._libs.hashtable.PyObjectHashTable.get_item
KeyError: 'email'

The above exception was the direct cause of the following exception:

Traceback (most recent call last):
  File "/usr/local/lib/python3.6/site-packages/apscheduler/executors/base_py3.py", line 30, in run_coroutine_job
    retval = await job.func(*job.args, **job.kwargs)
  File "/home/TendersPlus/matcher/scheduler/__init__.py", line 25, in update_researchers_pool
    ru.update()
  File "/home/TendersPlus/matcher/researcher/update/researcher_updater.py", line 81, in update
    self.__new_tag_df, self.__new_div_df, self.__new_tag_div_map_df = get_user_profile(self.__new_reg_info)
  File "/home/TendersPlus/matcher/utils/feature_utils.py", line 53, in get_user_profile
    input_df[pk] = 'Reg_' + input_df['email']
  File "/usr/local/lib64/python3.6/site-packages/pandas/core/frame.py", line 2906, in __getitem__
    indexer = self.columns.get_loc(key)
  File "/usr/local/lib64/python3.6/site-packages/pandas/core/indexes/base.py", line 2900, in get_loc
    raise KeyError(key) from err
KeyError: 'email'
Job "update_researchers_pool (trigger: interval[0:10:00], next run at: 2022-04-29 08:50:29 CST)" raised an exception
Traceback (most recent call last):
  File "/usr/local/lib64/python3.6/site-packages/pandas/core/indexes/base.py", line 2898, in get_loc
    return self._engine.get_loc(casted_key)
  File "pandas/_libs/index.pyx", line 70, in pandas._libs.index.IndexEngine.get_loc
  File "pandas/_libs/index.pyx", line 101, in pandas._libs.index.IndexEngine.get_loc
  File "pandas/_libs/hashtable_class_helper.pxi", line 1675, in pandas._libs.hashtable.PyObjectHashTable.get_item
  File "pandas/_libs/hashtable_class_helper.pxi", line 1683, in pandas._libs.hashtable.PyObjectHashTable.get_item
KeyError: 'email'

The above exception was the direct cause of the following exception:

Traceback (most recent call last):
  File "/usr/local/lib/python3.6/site-packages/apscheduler/executors/base_py3.py", line 30, in run_coroutine_job
    retval = await job.func(*job.args, **job.kwargs)
  File "/home/TendersPlus/matcher/scheduler/__init__.py", line 25, in update_researchers_pool
    ru.update()
  File "/home/TendersPlus/matcher/researcher/update/researcher_updater.py", line 81, in update
    self.__new_tag_df, self.__new_div_df, self.__new_tag_div_map_df = get_user_profile(self.__new_reg_info)
  File "/home/TendersPlus/matcher/utils/feature_utils.py", line 53, in get_user_profile
    input_df[pk] = 'Reg_' + input_df['email']
  File "/usr/local/lib64/python3.6/site-packages/pandas/core/frame.py", line 2906, in __getitem__
    indexer = self.columns.get_loc(key)
  File "/usr/local/lib64/python3.6/site-packages/pandas/core/indexes/base.py", line 2900, in get_loc
    raise KeyError(key) from err
KeyError: 'email'
Job "update_researchers_pool (trigger: interval[0:10:00], next run at: 2022-04-29 09:00:29 CST)" raised an exception
Traceback (most recent call last):
  File "/usr/local/lib64/python3.6/site-packages/pandas/core/indexes/base.py", line 2898, in get_loc
    return self._engine.get_loc(casted_key)
  File "pandas/_libs/index.pyx", line 70, in pandas._libs.index.IndexEngine.get_loc
  File "pandas/_libs/index.pyx", line 101, in pandas._libs.index.IndexEngine.get_loc
  File "pandas/_libs/hashtable_class_helper.pxi", line 1675, in pandas._libs.hashtable.PyObjectHashTable.get_item
  File "pandas/_libs/hashtable_class_helper.pxi", line 1683, in pandas._libs.hashtable.PyObjectHashTable.get_item
KeyError: 'email'

The above exception was the direct cause of the following exception:

Traceback (most recent call last):
  File "/usr/local/lib/python3.6/site-packages/apscheduler/executors/base_py3.py", line 30, in run_coroutine_job
    retval = await job.func(*job.args, **job.kwargs)
  File "/home/TendersPlus/matcher/scheduler/__init__.py", line 25, in update_researchers_pool
    ru.update()
  File "/home/TendersPlus/matcher/researcher/update/researcher_updater.py", line 81, in update
    self.__new_tag_df, self.__new_div_df, self.__new_tag_div_map_df = get_user_profile(self.__new_reg_info)
  File "/home/TendersPlus/matcher/utils/feature_utils.py", line 53, in get_user_profile
    input_df[pk] = 'Reg_' + input_df['email']
  File "/usr/local/lib64/python3.6/site-packages/pandas/core/frame.py", line 2906, in __getitem__
    indexer = self.columns.get_loc(key)
  File "/usr/local/lib64/python3.6/site-packages/pandas/core/indexes/base.py", line 2900, in get_loc
    raise KeyError(key) from err
KeyError: 'email'
Job "update_researchers_pool (trigger: interval[0:10:00], next run at: 2022-04-29 09:10:29 CST)" raised an exception
Traceback (most recent call last):
  File "/usr/local/lib64/python3.6/site-packages/pandas/core/indexes/base.py", line 2898, in get_loc
    return self._engine.get_loc(casted_key)
  File "pandas/_libs/index.pyx", line 70, in pandas._libs.index.IndexEngine.get_loc
  File "pandas/_libs/index.pyx", line 101, in pandas._libs.index.IndexEngine.get_loc
  File "pandas/_libs/hashtable_class_helper.pxi", line 1675, in pandas._libs.hashtable.PyObjectHashTable.get_item
  File "pandas/_libs/hashtable_class_helper.pxi", line 1683, in pandas._libs.hashtable.PyObjectHashTable.get_item
KeyError: 'email'

The above exception was the direct cause of the following exception:

Traceback (most recent call last):
  File "/usr/local/lib/python3.6/site-packages/apscheduler/executors/base_py3.py", line 30, in run_coroutine_job
    retval = await job.func(*job.args, **job.kwargs)
  File "/home/TendersPlus/matcher/scheduler/__init__.py", line 25, in update_researchers_pool
    ru.update()
  File "/home/TendersPlus/matcher/researcher/update/researcher_updater.py", line 81, in update
    self.__new_tag_df, self.__new_div_df, self.__new_tag_div_map_df = get_user_profile(self.__new_reg_info)
  File "/home/TendersPlus/matcher/utils/feature_utils.py", line 53, in get_user_profile
    input_df[pk] = 'Reg_' + input_df['email']
  File "/usr/local/lib64/python3.6/site-packages/pandas/core/frame.py", line 2906, in __getitem__
    indexer = self.columns.get_loc(key)
  File "/usr/local/lib64/python3.6/site-packages/pandas/core/indexes/base.py", line 2900, in get_loc
    raise KeyError(key) from err
KeyError: 'email'
Job "update_researchers_pool (trigger: interval[0:10:00], next run at: 2022-04-29 09:20:29 CST)" raised an exception
Traceback (most recent call last):
  File "/usr/local/lib64/python3.6/site-packages/pandas/core/indexes/base.py", line 2898, in get_loc
    return self._engine.get_loc(casted_key)
  File "pandas/_libs/index.pyx", line 70, in pandas._libs.index.IndexEngine.get_loc
  File "pandas/_libs/index.pyx", line 101, in pandas._libs.index.IndexEngine.get_loc
  File "pandas/_libs/hashtable_class_helper.pxi", line 1675, in pandas._libs.hashtable.PyObjectHashTable.get_item
  File "pandas/_libs/hashtable_class_helper.pxi", line 1683, in pandas._libs.hashtable.PyObjectHashTable.get_item
KeyError: 'email'

The above exception was the direct cause of the following exception:

Traceback (most recent call last):
  File "/usr/local/lib/python3.6/site-packages/apscheduler/executors/base_py3.py", line 30, in run_coroutine_job
    retval = await job.func(*job.args, **job.kwargs)
  File "/home/TendersPlus/matcher/scheduler/__init__.py", line 25, in update_researchers_pool
    ru.update()
  File "/home/TendersPlus/matcher/researcher/update/researcher_updater.py", line 81, in update
    self.__new_tag_df, self.__new_div_df, self.__new_tag_div_map_df = get_user_profile(self.__new_reg_info)
  File "/home/TendersPlus/matcher/utils/feature_utils.py", line 53, in get_user_profile
    input_df[pk] = 'Reg_' + input_df['email']
  File "/usr/local/lib64/python3.6/site-packages/pandas/core/frame.py", line 2906, in __getitem__
    indexer = self.columns.get_loc(key)
  File "/usr/local/lib64/python3.6/site-packages/pandas/core/indexes/base.py", line 2900, in get_loc
    raise KeyError(key) from err
KeyError: 'email'
Job "update_researchers_pool (trigger: interval[0:10:00], next run at: 2022-04-29 09:30:29 CST)" raised an exception
Traceback (most recent call last):
  File "/usr/local/lib64/python3.6/site-packages/pandas/core/indexes/base.py", line 2898, in get_loc
    return self._engine.get_loc(casted_key)
  File "pandas/_libs/index.pyx", line 70, in pandas._libs.index.IndexEngine.get_loc
  File "pandas/_libs/index.pyx", line 101, in pandas._libs.index.IndexEngine.get_loc
  File "pandas/_libs/hashtable_class_helper.pxi", line 1675, in pandas._libs.hashtable.PyObjectHashTable.get_item
  File "pandas/_libs/hashtable_class_helper.pxi", line 1683, in pandas._libs.hashtable.PyObjectHashTable.get_item
KeyError: 'email'

The above exception was the direct cause of the following exception:

Traceback (most recent call last):
  File "/usr/local/lib/python3.6/site-packages/apscheduler/executors/base_py3.py", line 30, in run_coroutine_job
    retval = await job.func(*job.args, **job.kwargs)
  File "/home/TendersPlus/matcher/scheduler/__init__.py", line 25, in update_researchers_pool
    ru.update()
  File "/home/TendersPlus/matcher/researcher/update/researcher_updater.py", line 81, in update
    self.__new_tag_df, self.__new_div_df, self.__new_tag_div_map_df = get_user_profile(self.__new_reg_info)
  File "/home/TendersPlus/matcher/utils/feature_utils.py", line 53, in get_user_profile
    input_df[pk] = 'Reg_' + input_df['email']
  File "/usr/local/lib64/python3.6/site-packages/pandas/core/frame.py", line 2906, in __getitem__
    indexer = self.columns.get_loc(key)
  File "/usr/local/lib64/python3.6/site-packages/pandas/core/indexes/base.py", line 2900, in get_loc
    raise KeyError(key) from err
KeyError: 'email'
Job "update_researchers_pool (trigger: interval[0:10:00], next run at: 2022-04-29 09:40:29 CST)" raised an exception
Traceback (most recent call last):
  File "/usr/local/lib64/python3.6/site-packages/pandas/core/indexes/base.py", line 2898, in get_loc
    return self._engine.get_loc(casted_key)
  File "pandas/_libs/index.pyx", line 70, in pandas._libs.index.IndexEngine.get_loc
  File "pandas/_libs/index.pyx", line 101, in pandas._libs.index.IndexEngine.get_loc
  File "pandas/_libs/hashtable_class_helper.pxi", line 1675, in pandas._libs.hashtable.PyObjectHashTable.get_item
  File "pandas/_libs/hashtable_class_helper.pxi", line 1683, in pandas._libs.hashtable.PyObjectHashTable.get_item
KeyError: 'email'

The above exception was the direct cause of the following exception:

Traceback (most recent call last):
  File "/usr/local/lib/python3.6/site-packages/apscheduler/executors/base_py3.py", line 30, in run_coroutine_job
    retval = await job.func(*job.args, **job.kwargs)
  File "/home/TendersPlus/matcher/scheduler/__init__.py", line 25, in update_researchers_pool
    ru.update()
  File "/home/TendersPlus/matcher/researcher/update/researcher_updater.py", line 81, in update
    self.__new_tag_df, self.__new_div_df, self.__new_tag_div_map_df = get_user_profile(self.__new_reg_info)
  File "/home/TendersPlus/matcher/utils/feature_utils.py", line 53, in get_user_profile
    input_df[pk] = 'Reg_' + input_df['email']
  File "/usr/local/lib64/python3.6/site-packages/pandas/core/frame.py", line 2906, in __getitem__
    indexer = self.columns.get_loc(key)
  File "/usr/local/lib64/python3.6/site-packages/pandas/core/indexes/base.py", line 2900, in get_loc
    raise KeyError(key) from err
KeyError: 'email'
Job "update_researchers_pool (trigger: interval[0:10:00], next run at: 2022-04-29 09:50:29 CST)" raised an exception
Traceback (most recent call last):
  File "/usr/local/lib64/python3.6/site-packages/pandas/core/indexes/base.py", line 2898, in get_loc
    return self._engine.get_loc(casted_key)
  File "pandas/_libs/index.pyx", line 70, in pandas._libs.index.IndexEngine.get_loc
  File "pandas/_libs/index.pyx", line 101, in pandas._libs.index.IndexEngine.get_loc
  File "pandas/_libs/hashtable_class_helper.pxi", line 1675, in pandas._libs.hashtable.PyObjectHashTable.get_item
  File "pandas/_libs/hashtable_class_helper.pxi", line 1683, in pandas._libs.hashtable.PyObjectHashTable.get_item
KeyError: 'email'

The above exception was the direct cause of the following exception:

Traceback (most recent call last):
  File "/usr/local/lib/python3.6/site-packages/apscheduler/executors/base_py3.py", line 30, in run_coroutine_job
    retval = await job.func(*job.args, **job.kwargs)
  File "/home/TendersPlus/matcher/scheduler/__init__.py", line 25, in update_researchers_pool
    ru.update()
  File "/home/TendersPlus/matcher/researcher/update/researcher_updater.py", line 81, in update
    self.__new_tag_df, self.__new_div_df, self.__new_tag_div_map_df = get_user_profile(self.__new_reg_info)
  File "/home/TendersPlus/matcher/utils/feature_utils.py", line 53, in get_user_profile
    input_df[pk] = 'Reg_' + input_df['email']
  File "/usr/local/lib64/python3.6/site-packages/pandas/core/frame.py", line 2906, in __getitem__
    indexer = self.columns.get_loc(key)
  File "/usr/local/lib64/python3.6/site-packages/pandas/core/indexes/base.py", line 2900, in get_loc
    raise KeyError(key) from err
KeyError: 'email'
From github.com:PipelineBot01/TendersPlus
   0ff7d58..9ef42b6  master     -> origin/master
To git@github.com:PipelineBot01/TendersPlus.git
   9ef42b6..b8b5e8f  master -> master
2022-04-29 09:44:53,337    INFO:     Started server process [26045]
2022-04-29 09:44:53,338    INFO:     Waiting for application startup.
2022-04-29 09:44:53,368    ERROR:    Traceback (most recent call last):
  File "/usr/local/lib64/python3.6/site-packages/pandas/core/indexes/base.py", line 2898, in get_loc
    return self._engine.get_loc(casted_key)
  File "pandas/_libs/index.pyx", line 70, in pandas._libs.index.IndexEngine.get_loc
  File "pandas/_libs/index.pyx", line 101, in pandas._libs.index.IndexEngine.get_loc
  File "pandas/_libs/hashtable_class_helper.pxi", line 1675, in pandas._libs.hashtable.PyObjectHashTable.get_item
  File "pandas/_libs/hashtable_class_helper.pxi", line 1683, in pandas._libs.hashtable.PyObjectHashTable.get_item
KeyError: 'email'

The above exception was the direct cause of the following exception:

Traceback (most recent call last):
  File "/usr/local/lib/python3.6/site-packages/starlette/routing.py", line 621, in lifespan
    async with self.lifespan_context(app):
  File "/usr/local/lib/python3.6/site-packages/starlette/routing.py", line 518, in __aenter__
    await self._router.startup()
  File "/usr/local/lib/python3.6/site-packages/starlette/routing.py", line 598, in startup
    await handler()
  File "main.py", line 57, in init
    await job_2.func()
  File "/home/TendersPlus/matcher/scheduler/__init__.py", line 25, in update_researchers_pool
    ru.update()
  File "/home/TendersPlus/matcher/researcher/update/researcher_updater.py", line 81, in update
    self.__new_tag_df, self.__new_div_df, self.__new_tag_div_map_df = get_user_profile(self.__new_reg_info)
  File "/home/TendersPlus/matcher/utils/feature_utils.py", line 53, in get_user_profile
    input_df[pk] = 'Reg_' + input_df['email']
  File "/usr/local/lib64/python3.6/site-packages/pandas/core/frame.py", line 2906, in __getitem__
    indexer = self.columns.get_loc(key)
  File "/usr/local/lib64/python3.6/site-packages/pandas/core/indexes/base.py", line 2900, in get_loc
    raise KeyError(key) from err
KeyError: 'email'

2022-04-29 09:44:53,368    ERROR:    Application startup failed. Exiting.
To git@github.com:PipelineBot01/TendersPlus.git
   b8b5e8f..577d274  master -> master
2022-04-29 09:46:53,657    INFO:     Started server process [26580]
2022-04-29 09:46:53,657    INFO:     Waiting for application startup.
2022-04-29 09:46:53,673    ERROR:    Traceback (most recent call last):
  File "/usr/local/lib64/python3.6/site-packages/pandas/core/indexes/base.py", line 2898, in get_loc
    return self._engine.get_loc(casted_key)
  File "pandas/_libs/index.pyx", line 70, in pandas._libs.index.IndexEngine.get_loc
  File "pandas/_libs/index.pyx", line 101, in pandas._libs.index.IndexEngine.get_loc
  File "pandas/_libs/hashtable_class_helper.pxi", line 1675, in pandas._libs.hashtable.PyObjectHashTable.get_item
  File "pandas/_libs/hashtable_class_helper.pxi", line 1683, in pandas._libs.hashtable.PyObjectHashTable.get_item
KeyError: 'email'

The above exception was the direct cause of the following exception:

Traceback (most recent call last):
  File "/usr/local/lib/python3.6/site-packages/starlette/routing.py", line 621, in lifespan
    async with self.lifespan_context(app):
  File "/usr/local/lib/python3.6/site-packages/starlette/routing.py", line 518, in __aenter__
    await self._router.startup()
  File "/usr/local/lib/python3.6/site-packages/starlette/routing.py", line 598, in startup
    await handler()
  File "main.py", line 57, in init
    await job_2.func()
  File "/home/TendersPlus/matcher/scheduler/__init__.py", line 25, in update_researchers_pool
    ru.update()
  File "/home/TendersPlus/matcher/researcher/update/researcher_updater.py", line 81, in update
    self.__new_tag_df, self.__new_div_df, self.__new_tag_div_map_df = get_user_profile(self.__new_reg_info)
  File "/home/TendersPlus/matcher/utils/feature_utils.py", line 53, in get_user_profile
    input_df[pk] = 'Reg_' + input_df['email']
  File "/usr/local/lib64/python3.6/site-packages/pandas/core/frame.py", line 2906, in __getitem__
    indexer = self.columns.get_loc(key)
  File "/usr/local/lib64/python3.6/site-packages/pandas/core/indexes/base.py", line 2900, in get_loc
    raise KeyError(key) from err
KeyError: 'email'

2022-04-29 09:46:53,673    ERROR:    Application startup failed. Exiting.
From github.com:PipelineBot01/TendersPlus
   577d274..2c1a0e0  master     -> origin/master
To git@github.com:PipelineBot01/TendersPlus.git
   2c1a0e0..00fa5ca  master -> master
Traceback (most recent call last):
  File "main.py", line 5, in <module>
    from scheduler import scheduler
  File "/home/TendersPlus/matcher/scheduler/__init__.py", line 7, in <module>
    from auto_reco import reco_filter, reco_process
  File "/home/TendersPlus/matcher/auto_reco/__init__.py", line 1, in <module>
    from .clb_filter import Filter
  File "/home/TendersPlus/matcher/auto_reco/clb_filter.py", line 7, in <module>
    from researcher.matching.researcher_relation import ResearcherMatcher
  File "/home/TendersPlus/matcher/researcher/matching/__init__.py", line 3, in <module>
    researcher_matcher = ResearcherMatcher()
  File "/home/TendersPlus/matcher/researcher/matching/researcher_relation.py", line 22, in __init__
    self.__INFO_DF = pd.read_csv(self.__info_path)
  File "/usr/local/lib64/python3.6/site-packages/pandas/io/parsers.py", line 688, in read_csv
    return _read(filepath_or_buffer, kwds)
  File "/usr/local/lib64/python3.6/site-packages/pandas/io/parsers.py", line 454, in _read
    parser = TextFileReader(fp_or_buf, **kwds)
  File "/usr/local/lib64/python3.6/site-packages/pandas/io/parsers.py", line 948, in __init__
    self._make_engine(self.engine)
  File "/usr/local/lib64/python3.6/site-packages/pandas/io/parsers.py", line 1180, in _make_engine
    self._engine = CParserWrapper(self.f, **self.options)
  File "/usr/local/lib64/python3.6/site-packages/pandas/io/parsers.py", line 2010, in __init__
    self._reader = parsers.TextReader(src, **kwds)
  File "pandas/_libs/parsers.pyx", line 382, in pandas._libs.parsers.TextReader.__cinit__
  File "pandas/_libs/parsers.pyx", line 674, in pandas._libs.parsers.TextReader._setup_parser_source
FileNotFoundError: [Errno 2] No such file or directory: './researcher/assets/researcher_info.csv'
To git@github.com:PipelineBot01/TendersPlus.git
   00fa5ca..0090767  master -> master
Traceback (most recent call last):
  File "main.py", line 5, in <module>
    from scheduler import scheduler
  File "/home/TendersPlus/matcher/scheduler/__init__.py", line 7, in <module>
    from auto_reco import reco_filter, reco_process
  File "/home/TendersPlus/matcher/auto_reco/__init__.py", line 1, in <module>
    from .clb_filter import Filter
  File "/home/TendersPlus/matcher/auto_reco/clb_filter.py", line 7, in <module>
    from researcher.matching.researcher_relation import ResearcherMatcher
  File "/home/TendersPlus/matcher/researcher/matching/__init__.py", line 3, in <module>
    researcher_matcher = ResearcherMatcher()
  File "/home/TendersPlus/matcher/researcher/matching/researcher_relation.py", line 22, in __init__
    self.__INFO_DF = pd.read_csv(self.__info_path)
  File "/usr/local/lib64/python3.6/site-packages/pandas/io/parsers.py", line 688, in read_csv
    return _read(filepath_or_buffer, kwds)
  File "/usr/local/lib64/python3.6/site-packages/pandas/io/parsers.py", line 454, in _read
    parser = TextFileReader(fp_or_buf, **kwds)
  File "/usr/local/lib64/python3.6/site-packages/pandas/io/parsers.py", line 948, in __init__
    self._make_engine(self.engine)
  File "/usr/local/lib64/python3.6/site-packages/pandas/io/parsers.py", line 1180, in _make_engine
    self._engine = CParserWrapper(self.f, **self.options)
  File "/usr/local/lib64/python3.6/site-packages/pandas/io/parsers.py", line 2010, in __init__
    self._reader = parsers.TextReader(src, **kwds)
  File "pandas/_libs/parsers.pyx", line 382, in pandas._libs.parsers.TextReader.__cinit__
  File "pandas/_libs/parsers.pyx", line 674, in pandas._libs.parsers.TextReader._setup_parser_source
FileNotFoundError: [Errno 2] No such file or directory: './researcher/assets/researcher_info.csv'
To git@github.com:PipelineBot01/TendersPlus.git
   0090767..114397d  master -> master
Traceback (most recent call last):
  File "main.py", line 5, in <module>
    from scheduler import scheduler
  File "/home/TendersPlus/matcher/scheduler/__init__.py", line 7, in <module>
    from auto_reco import reco_filter, reco_process
  File "/home/TendersPlus/matcher/auto_reco/__init__.py", line 1, in <module>
    from .clb_filter import Filter
  File "/home/TendersPlus/matcher/auto_reco/clb_filter.py", line 7, in <module>
    from researcher.matching.researcher_relation import ResearcherMatcher
  File "/home/TendersPlus/matcher/researcher/matching/__init__.py", line 3, in <module>
    researcher_matcher = ResearcherMatcher()
  File "/home/TendersPlus/matcher/researcher/matching/researcher_relation.py", line 22, in __init__
    self.__INFO_DF = pd.read_csv(self.__info_path)
  File "/usr/local/lib64/python3.6/site-packages/pandas/io/parsers.py", line 688, in read_csv
    return _read(filepath_or_buffer, kwds)
  File "/usr/local/lib64/python3.6/site-packages/pandas/io/parsers.py", line 454, in _read
    parser = TextFileReader(fp_or_buf, **kwds)
  File "/usr/local/lib64/python3.6/site-packages/pandas/io/parsers.py", line 948, in __init__
    self._make_engine(self.engine)
  File "/usr/local/lib64/python3.6/site-packages/pandas/io/parsers.py", line 1180, in _make_engine
    self._engine = CParserWrapper(self.f, **self.options)
  File "/usr/local/lib64/python3.6/site-packages/pandas/io/parsers.py", line 2010, in __init__
    self._reader = parsers.TextReader(src, **kwds)
  File "pandas/_libs/parsers.pyx", line 382, in pandas._libs.parsers.TextReader.__cinit__
  File "pandas/_libs/parsers.pyx", line 674, in pandas._libs.parsers.TextReader._setup_parser_source
FileNotFoundError: [Errno 2] No such file or directory: './researcher/assets/researcher_info.csv'
To git@github.com:PipelineBot01/TendersPlus.git
   114397d..6be903c  master -> master
Traceback (most recent call last):
  File "main.py", line 5, in <module>
    from scheduler import scheduler
  File "/home/TendersPlus/matcher/scheduler/__init__.py", line 7, in <module>
    from auto_reco import reco_filter, reco_process
  File "/home/TendersPlus/matcher/auto_reco/__init__.py", line 1, in <module>
    from .clb_filter import Filter
  File "/home/TendersPlus/matcher/auto_reco/clb_filter.py", line 7, in <module>
    from researcher.matching.researcher_relation import ResearcherMatcher
  File "/home/TendersPlus/matcher/researcher/matching/__init__.py", line 3, in <module>
    researcher_matcher = ResearcherMatcher()
  File "/home/TendersPlus/matcher/researcher/matching/researcher_relation.py", line 22, in __init__
    self.__INFO_DF = pd.read_csv(self.__info_path)
  File "/usr/local/lib64/python3.6/site-packages/pandas/io/parsers.py", line 688, in read_csv
    return _read(filepath_or_buffer, kwds)
  File "/usr/local/lib64/python3.6/site-packages/pandas/io/parsers.py", line 454, in _read
    parser = TextFileReader(fp_or_buf, **kwds)
  File "/usr/local/lib64/python3.6/site-packages/pandas/io/parsers.py", line 948, in __init__
    self._make_engine(self.engine)
  File "/usr/local/lib64/python3.6/site-packages/pandas/io/parsers.py", line 1180, in _make_engine
    self._engine = CParserWrapper(self.f, **self.options)
  File "/usr/local/lib64/python3.6/site-packages/pandas/io/parsers.py", line 2010, in __init__
    self._reader = parsers.TextReader(src, **kwds)
  File "pandas/_libs/parsers.pyx", line 382, in pandas._libs.parsers.TextReader.__cinit__
  File "pandas/_libs/parsers.pyx", line 674, in pandas._libs.parsers.TextReader._setup_parser_source
FileNotFoundError: [Errno 2] No such file or directory: './researcher/assets/researcher_info.csv'
To git@github.com:PipelineBot01/TendersPlus.git
   6be903c..e4c4eb7  master -> master
Traceback (most recent call last):
  File "main.py", line 5, in <module>
    from scheduler import scheduler
  File "/home/TendersPlus/matcher/scheduler/__init__.py", line 7, in <module>
    from auto_reco import reco_filter, reco_process
  File "/home/TendersPlus/matcher/auto_reco/__init__.py", line 1, in <module>
    from .clb_filter import Filter
  File "/home/TendersPlus/matcher/auto_reco/clb_filter.py", line 7, in <module>
    from researcher.matching.researcher_relation import ResearcherMatcher
  File "/home/TendersPlus/matcher/researcher/matching/__init__.py", line 3, in <module>
    researcher_matcher = ResearcherMatcher()
  File "/home/TendersPlus/matcher/researcher/matching/researcher_relation.py", line 22, in __init__
    self.__INFO_DF = pd.read_csv(self.__info_path)
  File "/usr/local/lib64/python3.6/site-packages/pandas/io/parsers.py", line 688, in read_csv
    return _read(filepath_or_buffer, kwds)
  File "/usr/local/lib64/python3.6/site-packages/pandas/io/parsers.py", line 454, in _read
    parser = TextFileReader(fp_or_buf, **kwds)
  File "/usr/local/lib64/python3.6/site-packages/pandas/io/parsers.py", line 948, in __init__
    self._make_engine(self.engine)
  File "/usr/local/lib64/python3.6/site-packages/pandas/io/parsers.py", line 1180, in _make_engine
    self._engine = CParserWrapper(self.f, **self.options)
  File "/usr/local/lib64/python3.6/site-packages/pandas/io/parsers.py", line 2010, in __init__
    self._reader = parsers.TextReader(src, **kwds)
  File "pandas/_libs/parsers.pyx", line 382, in pandas._libs.parsers.TextReader.__cinit__
  File "pandas/_libs/parsers.pyx", line 674, in pandas._libs.parsers.TextReader._setup_parser_source
FileNotFoundError: [Errno 2] No such file or directory: './researcher/assets/researcher_info.csv'
To git@github.com:PipelineBot01/TendersPlus.git
   e4c4eb7..7c280b6  master -> master
Traceback (most recent call last):
  File "main.py", line 5, in <module>
    from scheduler import scheduler
  File "/home/TendersPlus/matcher/scheduler/__init__.py", line 7, in <module>
    from auto_reco import reco_filter, reco_process
  File "/home/TendersPlus/matcher/auto_reco/__init__.py", line 1, in <module>
    from .clb_filter import Filter
  File "/home/TendersPlus/matcher/auto_reco/clb_filter.py", line 7, in <module>
    from researcher.matching.researcher_relation import ResearcherMatcher
  File "/home/TendersPlus/matcher/researcher/matching/__init__.py", line 3, in <module>
    researcher_matcher = ResearcherMatcher()
  File "/home/TendersPlus/matcher/researcher/matching/researcher_relation.py", line 22, in __init__
    self.__INFO_DF = pd.read_csv(self.__info_path)
  File "/usr/local/lib64/python3.6/site-packages/pandas/io/parsers.py", line 688, in read_csv
    return _read(filepath_or_buffer, kwds)
  File "/usr/local/lib64/python3.6/site-packages/pandas/io/parsers.py", line 454, in _read
    parser = TextFileReader(fp_or_buf, **kwds)
  File "/usr/local/lib64/python3.6/site-packages/pandas/io/parsers.py", line 948, in __init__
    self._make_engine(self.engine)
  File "/usr/local/lib64/python3.6/site-packages/pandas/io/parsers.py", line 1180, in _make_engine
    self._engine = CParserWrapper(self.f, **self.options)
  File "/usr/local/lib64/python3.6/site-packages/pandas/io/parsers.py", line 2010, in __init__
    self._reader = parsers.TextReader(src, **kwds)
  File "pandas/_libs/parsers.pyx", line 382, in pandas._libs.parsers.TextReader.__cinit__
  File "pandas/_libs/parsers.pyx", line 674, in pandas._libs.parsers.TextReader._setup_parser_source
FileNotFoundError: [Errno 2] No such file or directory: './researcher/assets/researcher_info.csv'
To git@github.com:PipelineBot01/TendersPlus.git
   7c280b6..6a733d9  master -> master
Traceback (most recent call last):
  File "main.py", line 5, in <module>
    from scheduler import scheduler
  File "/home/TendersPlus/matcher/scheduler/__init__.py", line 7, in <module>
    from auto_reco import reco_filter, reco_process
  File "/home/TendersPlus/matcher/auto_reco/__init__.py", line 1, in <module>
    from .clb_filter import Filter
  File "/home/TendersPlus/matcher/auto_reco/clb_filter.py", line 7, in <module>
    from researcher.matching.researcher_relation import ResearcherMatcher
  File "/home/TendersPlus/matcher/researcher/matching/__init__.py", line 3, in <module>
    researcher_matcher = ResearcherMatcher()
  File "/home/TendersPlus/matcher/researcher/matching/researcher_relation.py", line 22, in __init__
    self.__INFO_DF = pd.read_csv(self.__info_path)
  File "/usr/local/lib64/python3.6/site-packages/pandas/io/parsers.py", line 688, in read_csv
    return _read(filepath_or_buffer, kwds)
  File "/usr/local/lib64/python3.6/site-packages/pandas/io/parsers.py", line 454, in _read
    parser = TextFileReader(fp_or_buf, **kwds)
  File "/usr/local/lib64/python3.6/site-packages/pandas/io/parsers.py", line 948, in __init__
    self._make_engine(self.engine)
  File "/usr/local/lib64/python3.6/site-packages/pandas/io/parsers.py", line 1180, in _make_engine
    self._engine = CParserWrapper(self.f, **self.options)
  File "/usr/local/lib64/python3.6/site-packages/pandas/io/parsers.py", line 2010, in __init__
    self._reader = parsers.TextReader(src, **kwds)
  File "pandas/_libs/parsers.pyx", line 382, in pandas._libs.parsers.TextReader.__cinit__
  File "pandas/_libs/parsers.pyx", line 674, in pandas._libs.parsers.TextReader._setup_parser_source
FileNotFoundError: [Errno 2] No such file or directory: './researcher/assets/researcher_info.csv'
To git@github.com:PipelineBot01/TendersPlus.git
   6a733d9..6787c45  master -> master
Traceback (most recent call last):
  File "main.py", line 5, in <module>
    from scheduler import scheduler
  File "/home/TendersPlus/matcher/scheduler/__init__.py", line 7, in <module>
    from auto_reco import reco_filter, reco_process
  File "/home/TendersPlus/matcher/auto_reco/__init__.py", line 1, in <module>
    from .clb_filter import Filter
  File "/home/TendersPlus/matcher/auto_reco/clb_filter.py", line 7, in <module>
    from researcher.matching.researcher_relation import ResearcherMatcher
  File "/home/TendersPlus/matcher/researcher/matching/__init__.py", line 3, in <module>
    researcher_matcher = ResearcherMatcher()
  File "/home/TendersPlus/matcher/researcher/matching/researcher_relation.py", line 22, in __init__
    self.__INFO_DF = pd.read_csv(self.__info_path)
  File "/usr/local/lib64/python3.6/site-packages/pandas/io/parsers.py", line 688, in read_csv
    return _read(filepath_or_buffer, kwds)
  File "/usr/local/lib64/python3.6/site-packages/pandas/io/parsers.py", line 454, in _read
    parser = TextFileReader(fp_or_buf, **kwds)
  File "/usr/local/lib64/python3.6/site-packages/pandas/io/parsers.py", line 948, in __init__
    self._make_engine(self.engine)
  File "/usr/local/lib64/python3.6/site-packages/pandas/io/parsers.py", line 1180, in _make_engine
    self._engine = CParserWrapper(self.f, **self.options)
  File "/usr/local/lib64/python3.6/site-packages/pandas/io/parsers.py", line 2010, in __init__
    self._reader = parsers.TextReader(src, **kwds)
  File "pandas/_libs/parsers.pyx", line 382, in pandas._libs.parsers.TextReader.__cinit__
  File "pandas/_libs/parsers.pyx", line 674, in pandas._libs.parsers.TextReader._setup_parser_source
FileNotFoundError: [Errno 2] No such file or directory: './researcher/assets/researcher_info.csv'
To git@github.com:PipelineBot01/TendersPlus.git
   6787c45..0aabc39  master -> master
Traceback (most recent call last):
  File "main.py", line 5, in <module>
    from scheduler import scheduler
  File "/home/TendersPlus/matcher/scheduler/__init__.py", line 7, in <module>
    from auto_reco import reco_filter, reco_process
  File "/home/TendersPlus/matcher/auto_reco/__init__.py", line 1, in <module>
    from .clb_filter import Filter
  File "/home/TendersPlus/matcher/auto_reco/clb_filter.py", line 7, in <module>
    from researcher.matching.researcher_relation import ResearcherMatcher
  File "/home/TendersPlus/matcher/researcher/matching/__init__.py", line 3, in <module>
    researcher_matcher = ResearcherMatcher()
  File "/home/TendersPlus/matcher/researcher/matching/researcher_relation.py", line 22, in __init__
    self.__INFO_DF = pd.read_csv(self.__info_path)
  File "/usr/local/lib64/python3.6/site-packages/pandas/io/parsers.py", line 688, in read_csv
    return _read(filepath_or_buffer, kwds)
  File "/usr/local/lib64/python3.6/site-packages/pandas/io/parsers.py", line 454, in _read
    parser = TextFileReader(fp_or_buf, **kwds)
  File "/usr/local/lib64/python3.6/site-packages/pandas/io/parsers.py", line 948, in __init__
    self._make_engine(self.engine)
  File "/usr/local/lib64/python3.6/site-packages/pandas/io/parsers.py", line 1180, in _make_engine
    self._engine = CParserWrapper(self.f, **self.options)
  File "/usr/local/lib64/python3.6/site-packages/pandas/io/parsers.py", line 2010, in __init__
    self._reader = parsers.TextReader(src, **kwds)
  File "pandas/_libs/parsers.pyx", line 382, in pandas._libs.parsers.TextReader.__cinit__
  File "pandas/_libs/parsers.pyx", line 674, in pandas._libs.parsers.TextReader._setup_parser_source
FileNotFoundError: [Errno 2] No such file or directory: './researcher/assets/researcher_info.csv'
To git@github.com:PipelineBot01/TendersPlus.git
   0aabc39..8815646  master -> master
Traceback (most recent call last):
  File "main.py", line 5, in <module>
    from scheduler import scheduler
  File "/home/TendersPlus/matcher/scheduler/__init__.py", line 7, in <module>
    from auto_reco import reco_filter, reco_process
  File "/home/TendersPlus/matcher/auto_reco/__init__.py", line 1, in <module>
    from .clb_filter import Filter
  File "/home/TendersPlus/matcher/auto_reco/clb_filter.py", line 7, in <module>
    from researcher.matching.researcher_relation import ResearcherMatcher
  File "/home/TendersPlus/matcher/researcher/matching/__init__.py", line 3, in <module>
    researcher_matcher = ResearcherMatcher()
  File "/home/TendersPlus/matcher/researcher/matching/researcher_relation.py", line 22, in __init__
    self.__INFO_DF = pd.read_csv(self.__info_path)
  File "/usr/local/lib64/python3.6/site-packages/pandas/io/parsers.py", line 688, in read_csv
    return _read(filepath_or_buffer, kwds)
  File "/usr/local/lib64/python3.6/site-packages/pandas/io/parsers.py", line 454, in _read
    parser = TextFileReader(fp_or_buf, **kwds)
  File "/usr/local/lib64/python3.6/site-packages/pandas/io/parsers.py", line 948, in __init__
    self._make_engine(self.engine)
  File "/usr/local/lib64/python3.6/site-packages/pandas/io/parsers.py", line 1180, in _make_engine
    self._engine = CParserWrapper(self.f, **self.options)
  File "/usr/local/lib64/python3.6/site-packages/pandas/io/parsers.py", line 2010, in __init__
    self._reader = parsers.TextReader(src, **kwds)
  File "pandas/_libs/parsers.pyx", line 382, in pandas._libs.parsers.TextReader.__cinit__
  File "pandas/_libs/parsers.pyx", line 674, in pandas._libs.parsers.TextReader._setup_parser_source
FileNotFoundError: [Errno 2] No such file or directory: './researcher/assets/researcher_info.csv'
