2022-04-25 13:27:21,419    ERROR:    Exception in ASGI application
Traceback (most recent call last):
  File "/usr/local/lib/python3.6/site-packages/uvicorn/protocols/http/h11_impl.py", line 373, in run_asgi
    result = await app(self.scope, self.receive, self.send)
  File "/usr/local/lib/python3.6/site-packages/uvicorn/middleware/proxy_headers.py", line 75, in __call__
    return await self.app(scope, receive, send)
  File "/usr/local/lib/python3.6/site-packages/fastapi/applications.py", line 261, in __call__
    await super().__call__(scope, receive, send)
  File "/usr/local/lib/python3.6/site-packages/starlette/applications.py", line 112, in __call__
    await self.middleware_stack(scope, receive, send)
  File "/usr/local/lib/python3.6/site-packages/starlette/middleware/errors.py", line 181, in __call__
    raise exc
  File "/usr/local/lib/python3.6/site-packages/starlette/middleware/errors.py", line 159, in __call__
    await self.app(scope, receive, _send)
  File "/usr/local/lib/python3.6/site-packages/starlette/exceptions.py", line 82, in __call__
    raise exc
  File "/usr/local/lib/python3.6/site-packages/starlette/exceptions.py", line 71, in __call__
    await self.app(scope, receive, sender)
  File "/usr/local/lib/python3.6/site-packages/fastapi/middleware/asyncexitstack.py", line 21, in __call__
    raise e
  File "/usr/local/lib/python3.6/site-packages/fastapi/middleware/asyncexitstack.py", line 18, in __call__
    await self.app(scope, receive, send)
  File "/usr/local/lib/python3.6/site-packages/starlette/routing.py", line 656, in __call__
    await route.handle(scope, receive, send)
  File "/usr/local/lib/python3.6/site-packages/starlette/routing.py", line 259, in handle
    await self.app(scope, receive, send)
  File "/usr/local/lib/python3.6/site-packages/starlette/routing.py", line 61, in app
    response = await func(request)
  File "/usr/local/lib/python3.6/site-packages/fastapi/routing.py", line 251, in app
    response = actual_response_class(response_data, **response_args)
  File "/usr/local/lib/python3.6/site-packages/starlette/responses.py", line 49, in __init__
    self.body = self.render(content)
  File "/usr/local/lib/python3.6/site-packages/starlette/responses.py", line 179, in render
    separators=(",", ":"),
  File "/usr/lib64/python3.6/json/__init__.py", line 238, in dumps
    **kw).encode(obj)
  File "/usr/lib64/python3.6/json/encoder.py", line 199, in encode
    chunks = self.iterencode(o, _one_shot=True)
  File "/usr/lib64/python3.6/json/encoder.py", line 257, in iterencode
    return _iterencode(o, 0)
ValueError: Out of range float values are not JSON compliant
2022-04-25 13:29:25,622    ERROR:    Exception in ASGI application
Traceback (most recent call last):
  File "/usr/local/lib/python3.6/site-packages/uvicorn/protocols/http/h11_impl.py", line 373, in run_asgi
    result = await app(self.scope, self.receive, self.send)
  File "/usr/local/lib/python3.6/site-packages/uvicorn/middleware/proxy_headers.py", line 75, in __call__
    return await self.app(scope, receive, send)
  File "/usr/local/lib/python3.6/site-packages/fastapi/applications.py", line 261, in __call__
    await super().__call__(scope, receive, send)
  File "/usr/local/lib/python3.6/site-packages/starlette/applications.py", line 112, in __call__
    await self.middleware_stack(scope, receive, send)
  File "/usr/local/lib/python3.6/site-packages/starlette/middleware/errors.py", line 181, in __call__
    raise exc
  File "/usr/local/lib/python3.6/site-packages/starlette/middleware/errors.py", line 159, in __call__
    await self.app(scope, receive, _send)
  File "/usr/local/lib/python3.6/site-packages/starlette/exceptions.py", line 82, in __call__
    raise exc
  File "/usr/local/lib/python3.6/site-packages/starlette/exceptions.py", line 71, in __call__
    await self.app(scope, receive, sender)
  File "/usr/local/lib/python3.6/site-packages/fastapi/middleware/asyncexitstack.py", line 21, in __call__
    raise e
  File "/usr/local/lib/python3.6/site-packages/fastapi/middleware/asyncexitstack.py", line 18, in __call__
    await self.app(scope, receive, send)
  File "/usr/local/lib/python3.6/site-packages/starlette/routing.py", line 656, in __call__
    await route.handle(scope, receive, send)
  File "/usr/local/lib/python3.6/site-packages/starlette/routing.py", line 259, in handle
    await self.app(scope, receive, send)
  File "/usr/local/lib/python3.6/site-packages/starlette/routing.py", line 61, in app
    response = await func(request)
  File "/usr/local/lib/python3.6/site-packages/fastapi/routing.py", line 251, in app
    response = actual_response_class(response_data, **response_args)
  File "/usr/local/lib/python3.6/site-packages/starlette/responses.py", line 49, in __init__
    self.body = self.render(content)
  File "/usr/local/lib/python3.6/site-packages/starlette/responses.py", line 179, in render
    separators=(",", ":"),
  File "/usr/lib64/python3.6/json/__init__.py", line 238, in dumps
    **kw).encode(obj)
  File "/usr/lib64/python3.6/json/encoder.py", line 199, in encode
    chunks = self.iterencode(o, _one_shot=True)
  File "/usr/lib64/python3.6/json/encoder.py", line 257, in iterencode
    return _iterencode(o, 0)
ValueError: Out of range float values are not JSON compliant
2022-04-25 14:23:33,372    INFO:     Shutting down
From github.com:PipelineBot01/TendersPlus
   2eea0b1..46a8404  master     -> origin/master
To git@github.com:PipelineBot01/TendersPlus.git
   46a8404..ee353dd  master -> master
2022-04-25 14:24:04,095    INFO:     Started server process [30557]
2022-04-25 14:24:04,096    INFO:     Waiting for application startup.
2022-04-25 14:24:04,097    INFO:     Application startup complete.
2022-04-25 14:24:04,098    INFO:     Uvicorn running on http://localhost:20222 (Press CTRL+C to quit)
2022-04-25 14:28:28,230    ERROR:    Exception in ASGI application
Traceback (most recent call last):
  File "/usr/local/lib/python3.6/site-packages/uvicorn/protocols/http/h11_impl.py", line 373, in run_asgi
    result = await app(self.scope, self.receive, self.send)
  File "/usr/local/lib/python3.6/site-packages/uvicorn/middleware/proxy_headers.py", line 75, in __call__
    return await self.app(scope, receive, send)
  File "/usr/local/lib/python3.6/site-packages/fastapi/applications.py", line 261, in __call__
    await super().__call__(scope, receive, send)
  File "/usr/local/lib/python3.6/site-packages/starlette/applications.py", line 112, in __call__
    await self.middleware_stack(scope, receive, send)
  File "/usr/local/lib/python3.6/site-packages/starlette/middleware/errors.py", line 181, in __call__
    raise exc
  File "/usr/local/lib/python3.6/site-packages/starlette/middleware/errors.py", line 159, in __call__
    await self.app(scope, receive, _send)
  File "/usr/local/lib/python3.6/site-packages/starlette/exceptions.py", line 82, in __call__
    raise exc
  File "/usr/local/lib/python3.6/site-packages/starlette/exceptions.py", line 71, in __call__
    await self.app(scope, receive, sender)
  File "/usr/local/lib/python3.6/site-packages/fastapi/middleware/asyncexitstack.py", line 21, in __call__
    raise e
  File "/usr/local/lib/python3.6/site-packages/fastapi/middleware/asyncexitstack.py", line 18, in __call__
    await self.app(scope, receive, send)
  File "/usr/local/lib/python3.6/site-packages/starlette/routing.py", line 656, in __call__
    await route.handle(scope, receive, send)
  File "/usr/local/lib/python3.6/site-packages/starlette/routing.py", line 259, in handle
    await self.app(scope, receive, send)
  File "/usr/local/lib/python3.6/site-packages/starlette/routing.py", line 61, in app
    response = await func(request)
  File "/usr/local/lib/python3.6/site-packages/fastapi/routing.py", line 251, in app
    response = actual_response_class(response_data, **response_args)
  File "/usr/local/lib/python3.6/site-packages/starlette/responses.py", line 49, in __init__
    self.body = self.render(content)
  File "/usr/local/lib/python3.6/site-packages/starlette/responses.py", line 179, in render
    separators=(",", ":"),
  File "/usr/lib64/python3.6/json/__init__.py", line 238, in dumps
    **kw).encode(obj)
  File "/usr/lib64/python3.6/json/encoder.py", line 199, in encode
    chunks = self.iterencode(o, _one_shot=True)
  File "/usr/lib64/python3.6/json/encoder.py", line 257, in iterencode
    return _iterencode(o, 0)
ValueError: Out of range float values are not JSON compliant
2022-04-25 15:46:16,844    INFO:     Shutting down
From github.com:PipelineBot01/TendersPlus
   ee353dd..3a06111  master     -> origin/master
To git@github.com:PipelineBot01/TendersPlus.git
   3a06111..ca7e43b  master -> master
2022-04-25 15:46:42,959    INFO:     Started server process [18433]
2022-04-25 15:46:42,960    INFO:     Waiting for application startup.
2022-04-25 15:46:42,961    INFO:     Application startup complete.
2022-04-25 15:46:42,962    INFO:     Uvicorn running on http://localhost:20222 (Press CTRL+C to quit)
To git@github.com:PipelineBot01/TendersPlus.git
   674f4e6..0896a88  master -> master
2022-04-25 20:54:52,584    INFO:     Started server process [29800]
2022-04-25 20:54:52,586    INFO:     Waiting for application startup.
2022-04-25 20:54:52,859    INFO:     Application startup complete.
2022-04-25 20:54:52,917    INFO:     Uvicorn running on http://localhost:20222 (Press CTRL+C to quit)
Job "update_tenders_pool (trigger: interval[2:00:00], next run at: 2022-04-26 06:54:50 CST)" raised an exception
Traceback (most recent call last):
  File "/usr/local/lib/python3.6/site-packages/apscheduler/executors/base_py3.py", line 30, in run_coroutine_job
    retval = await job.func(*job.args, **job.kwargs)
  File "/home/TendersPlus/matcher/scheduler/__init__.py", line 16, in update_tenders_pool
    print(datetime.now().strftime(fmt='%Y-%m-%d %H:%M:%S') + ' ------ start update tenders pool')
TypeError: Required argument 'format' (pos 1) not found
2022-04-26 11:32:49,692    INFO:     Shutting down
From github.com:PipelineBot01/TendersPlus
   c2238b9..d11dcfe  master     -> origin/master
